Workbook

Sheet Ввод
A1: Калькулятор Adaptive EV
A3: Брокер | B3: DemoBroker
A4: Символ | B4: EURUSD
A5: Знаков после запятой | B5: 5
A6: Размер контракта | B6: 100000
A7: Кредитное плечо | B7: 100
A8: Валюта счета | B8: USD
A9: Баланс | B9: 100000
A10: Эквити | B10: 99998.7
A11: Свободная маржа | B11: 99875.5
A12: Текущая цена (mid) | B12: 1.23184
A13: Bid | B13: =B12-B15/2
A14: Ask | B14: =B12+B15/2
A15: Спред (цена) | B15: 8e-05
A16: ATR | B16: 0.0008
A17: Alpha (α) | B17: 0.3
A18: Шаг Δ | B18: 0.00028
A19: Gamma (γ) | B19: 0.08
A20: Минимум SELL Ls,min | B20: 0.25
A21: Предел просадки Dmax, % | B21: 2
A22: Лимит нагрузки маржи, % | B22: 60
A23: Коэффициент режима (0.5..2.0) | B23: 1
A25: Уровень маржи, % | B25: =IF(Расчеты!B13=0,0,B10/Расчеты!B13*100)
A26: Статус риска | B26: =IF(OR(Расчеты!B9="FAIL",Расчеты!B14>B22,Расчеты!B16<-B21),"СТРЕСС/СОКРАЩЕНИЕ","НОРМА")

Sheet Позиции
A1: ID | B1: Активна (Y/N) | C1: Направление (BUY/SELL) | D1: Лот | E1: Цена открытия | F1: SL | G1: TP | H1: Комиссия | I1: Своп | J1: Текущая цена | K1: Разница цены | L1: P/L, USD | M1: Маржа, USD | N1: Лот частичного закрытия | O1: Действие | P1: Расчет ΔL_s/ΔL_b | Q1: Ключ актив+направление
A2: 1 | B2: Y | C2: SELL | D2: 0.1 | E2: 1.23125 | F2: 0 | G2: 0 | H2: 0 | I2: 0 | J2: =IF(C2="BUY",Ввод!B13,Ввод!B14) | K2: =IF(C2="BUY",J2-E2,E2-J2) | L2: =IF(B2="Y",K2*D2*Ввод!B6+H2+I2,0) | M2: =IF(B2="Y",D2*Ввод!B6*J2/Ввод!B7,0) | N2: =IF(B2="Y",ROUND(MIN(D2*Ввод!B19,D2*0.5),2),0) | O2: =IF(B2<>"Y","НЕТ",IF(AND(Расчеты!B11="ДА",ABS(K2)>=Ввод!B18),"ЧАСТИЧНО ЗАКРЫТЬ","ДЕРЖАТЬ")) | P2: =IF(B2<>"Y",0,IFERROR((Ввод!B12-Расчеты!B3-Ввод!B15/2+Расчеты!B6)/(Расчеты!B4-Ввод!B12-Ввод!B15/2-Расчеты!B6),0)) | Q2: =IF(B2="Y",B2&C2,"")
A3: 2 | B3: Y | C3: BUY | D3: 0.1 | E3: 1.23267 | F3: 0 | G3: 0 | H3: 0 | I3: 0 | J3: =IF(C3="BUY",Ввод!B13,Ввод!B14) | K3: =IF(C3="BUY",J3-E3,E3-J3) | L3: =IF(B3="Y",K3*D3*Ввод!B6+H3+I3,0) | M3: =IF(B3="Y",D3*Ввод!B6*J3/Ввод!B7,0) | N3: =IF(B3="Y",ROUND(MIN(D3*Ввод!B19,D3*0.5),2),0) | O3: =IF(B3<>"Y","НЕТ",IF(AND(Расчеты!B11="ДА",ABS(K3)>=Ввод!B18),"ЧАСТИЧНО ЗАКРЫТЬ","ДЕРЖАТЬ")) | P3: =IF(B3<>"Y",0,IFERROR((Ввод!B12-Расчеты!B3-Ввод!B15/2+Расчеты!B6)/(Расчеты!B4-Ввод!B12-Ввод!B15/2-Расчеты!B6),0)) | Q3: =IF(B3="Y",B3&C3,"")
J4: =IF(C4="BUY",Ввод!B13,Ввод!B14) | K4: =IF(C4="BUY",J4-E4,E4-J4) | L4: =IF(B4="Y",K4*D4*Ввод!B6+H4+I4,0) | M4: =IF(B4="Y",D4*Ввод!B6*J4/Ввод!B7,0) | N4: =IF(B4="Y",ROUND(MIN(D4*Ввод!B19,D4*0.5),2),0) | O4: =IF(B4<>"Y","НЕТ",IF(AND(Расчеты!B11="ДА",ABS(K4)>=Ввод!B18),"ЧАСТИЧНО ЗАКРЫТЬ","ДЕРЖАТЬ")) | P4: =IF(B4<>"Y",0,IFERROR((Ввод!B12-Расчеты!B3-Ввод!B15/2+Расчеты!B6)/(Расчеты!B4-Ввод!B12-Ввод!B15/2-Расчеты!B6),0)) | Q4: =IF(B4="Y",B4&C4,"")
J5: =IF(C5="BUY",Ввод!B13,Ввод!B14) | K5: =IF(C5="BUY",J5-E5,E5-J5) | L5: =IF(B5="Y",K5*D5*Ввод!B6+H5+I5,0) | M5: =IF(B5="Y",D5*Ввод!B6*J5/Ввод!B7,0) | N5: =IF(B5="Y",ROUND(MIN(D5*Ввод!B19,D5*0.5),2),0) | O5: =IF(B5<>"Y","НЕТ",IF(AND(Расчеты!B11="ДА",ABS(K5)>=Ввод!B18),"ЧАСТИЧНО ЗАКРЫТЬ","ДЕРЖАТЬ")) | P5: =IF(B5<>"Y",0,IFERROR((Ввод!B12-Расчеты!B3-Ввод!B15/2+Расчеты!B6)/(Расчеты!B4-Ввод!B12-Ввод!B15/2-Расчеты!B6),0)) | Q5: =IF(B5="Y",B5&C5,"")
J6: =IF(C6="BUY",Ввод!B13,Ввод!B14) | K6: =IF(C6="BUY",J6-E6,E6-J6) | L6: =IF(B6="Y",K6*D6*Ввод!B6+H6+I6,0) | M6: =IF(B6="Y",D6*Ввод!B6*J6/Ввод!B7,0) | N6: =IF(B6="Y",ROUND(MIN(D6*Ввод!B19,D6*0.5),2),0) | O6: =IF(B6<>"Y","НЕТ",IF(AND(Расчеты!B11="ДА",ABS(K6)>=Ввод!B18),"ЧАСТИЧНО ЗАКРЫТЬ","ДЕРЖАТЬ")) | P6: =IF(B6<>"Y",0,IFERROR((Ввод!B12-Расчеты!B3-Ввод!B15/2+Расчеты!B6)/(Расчеты!B4-Ввод!B12-Ввод!B15/2-Расчеты!B6),0)) | Q6: =IF(B6="Y",B6&C6,"")
J7: =IF(C7="BUY",Ввод!B13,Ввод!B14) | K7: =IF(C7="BUY",J7-E7,E7-J7) | L7: =IF(B7="Y",K7*D7*Ввод!B6+H7+I7,0) | M7: =IF(B7="Y",D7*Ввод!B6*J7/Ввод!B7,0) | N7: =IF(B7="Y",ROUND(MIN(D7*Ввод!B19,D7*0.5),2),0) | O7: =IF(B7<>"Y","НЕТ",IF(AND(Расчеты!B11="ДА",ABS(K7)>=Ввод!B18),"ЧАСТИЧНО ЗАКРЫТЬ","ДЕРЖАТЬ")) | P7: =IF(B7<>"Y",0,IFERROR((Ввод!B12-Расчеты!B3-Ввод!B15/2+Расчеты!B6)/(Расчеты!B4-Ввод!B12-Ввод!B15/2-Расчеты!B6),0)) | Q7: =IF(B7="Y",B7&C7,"")
J8: =IF(C8="BUY",Ввод!B13,Ввод!B14) | K8: =IF(C8="BUY",J8-E8,E8-J8) | L8: =IF(B8="Y",K8*D8*Ввод!B6+H8+I8,0) | M8: =IF(B8="Y",D8*Ввод!B6*J8/Ввод!B7,0) | N8: =IF(B8="Y",ROUND(MIN(D8*Ввод!B19,D8*0.5),2),0) | O8: =IF(B8<>"Y","НЕТ",IF(AND(Расчеты!B11="ДА",ABS(K8)>=Ввод!B18),"ЧАСТИЧНО ЗАКРЫТЬ","ДЕРЖАТЬ")) | P8: =IF(B8<>"Y",0,IFERROR((Ввод!B12-Расчеты!B3-Ввод!B15/2+Расчеты!B6)/(Расчеты!B4-Ввод!B12-Ввод!B15/2-Расчеты!B6),0)) | Q8: =IF(B8="Y",B8&C8,"")
J9: =IF(C9="BUY",Ввод!B13,Ввод!B14) | K9: =IF(C9="BUY",J9-E9,E9-J9) | L9: =IF(B9="Y",K9*D9*Ввод!B6+H9+I9,0) | M9: =IF(B9="Y",D9*Ввод!B6*J9/Ввод!B7,0) | N9: =IF(B9="Y",ROUND(MIN(D9*Ввод!B19,D9*0.5),2),0) | O9: =IF(B9<>"Y","НЕТ",IF(AND(Расчеты!B11="ДА",ABS(K9)>=Ввод!B18),"ЧАСТИЧНО ЗАКРЫТЬ","ДЕРЖАТЬ")) | P9: =IF(B9<>"Y",0,IFERROR((Ввод!B12-Расчеты!B3-Ввод!B15/2+Расчеты!B6)/(Расчеты!B4-Ввод!B12-Ввод!B15/2-Расчеты!B6),0)) | Q9: =IF(B9="Y",B9&C9,"")
J10: =IF(C10="BUY",Ввод!B13,Ввод!B14) | K10: =IF(C10="BUY",J10-E10,E10-J10) | L10: =IF(B10="Y",K10*D10*Ввод!B6+H10+I10,0) | M10: =IF(B10="Y",D10*Ввод!B6*J10/Ввод!B7,0) | N10: =IF(B10="Y",ROUND(MIN(D10*Ввод!B19,D10*0.5),2),0) | O10: =IF(B10<>"Y","НЕТ",IF(AND(Расчеты!B11="ДА",ABS(K10)>=Ввод!B18),"ЧАСТИЧНО ЗАКРЫТЬ","ДЕРЖАТЬ")) | P10: =IF(B10<>"Y",0,IFERROR((Ввод!B12-Расчеты!B3-Ввод!B15/2+Расчеты!B6)/(Расчеты!B4-Ввод!B12-Ввод!B15/2-Расчеты!B6),0)) | Q10: =IF(B10="Y",B10&C10,"")
J11: =IF(C11="BUY",Ввод!B13,Ввод!B14) | K11: =IF(C11="BUY",J11-E11,E11-J11) | L11: =IF(B11="Y",K11*D11*Ввод!B6+H11+I11,0) | M11: =IF(B11="Y",D11*Ввод!B6*J11/Ввод!B7,0) | N11: =IF(B11="Y",ROUND(MIN(D11*Ввод!B19,D11*0.5),2),0) | O11: =IF(B11<>"Y","НЕТ",IF(AND(Расчеты!B11="ДА",ABS(K11)>=Ввод!B18),"ЧАСТИЧНО ЗАКРЫТЬ","ДЕРЖАТЬ")) | P11: =IF(B11<>"Y",0,IFERROR((Ввод!B12-Расчеты!B3-Ввод!B15/2+Расчеты!B6)/(Расчеты!B4-Ввод!B12-Ввод!B15/2-Расчеты!B6),0)) | Q11: =IF(B11="Y",B11&C11,"")
J12: =IF(C12="BUY",Ввод!B13,Ввод!B14) | K12: =IF(C12="BUY",J12-E12,E12-J12) | L12: =IF(B12="Y",K12*D12*Ввод!B6+H12+I12,0) | M12: =IF(B12="Y",D12*Ввод!B6*J12/Ввод!B7,0) | N12: =IF(B12="Y",ROUND(MIN(D12*Ввод!B19,D12*0.5),2),0) | O12: =IF(B12<>"Y","НЕТ",IF(AND(Расчеты!B11="ДА",ABS(K12)>=Ввод!B18),"ЧАСТИЧНО ЗАКРЫТЬ","ДЕРЖАТЬ")) | P12: =IF(B12<>"Y",0,IFERROR((Ввод!B12-Расчеты!B3-Ввод!B15/2+Расчеты!B6)/(Расчеты!B4-Ввод!B12-Ввод!B15/2-Расчеты!B6),0)) | Q12: =IF(B12="Y",B12&C12,"")
J13: =IF(C13="BUY",Ввод!B13,Ввод!B14) | K13: =IF(C13="BUY",J13-E13,E13-J13) | L13: =IF(B13="Y",K13*D13*Ввод!B6+H13+I13,0) | M13: =IF(B13="Y",D13*Ввод!B6*J13/Ввод!B7,0) | N13: =IF(B13="Y",ROUND(MIN(D13*Ввод!B19,D13*0.5),2),0) | O13: =IF(B13<>"Y","НЕТ",IF(AND(Расчеты!B11="ДА",ABS(K13)>=Ввод!B18),"ЧАСТИЧНО ЗАКРЫТЬ","ДЕРЖАТЬ")) | P13: =IF(B13<>"Y",0,IFERROR((Ввод!B12-Расчеты!B3-Ввод!B15/2+Расчеты!B6)/(Расчеты!B4-Ввод!B12-Ввод!B15/2-Расчеты!B6),0)) | Q13: =IF(B13="Y",B13&C13,"")
J14: =IF(C14="BUY",Ввод!B13,Ввод!B14) | K14: =IF(C14="BUY",J14-E14,E14-J14) | L14: =IF(B14="Y",K14*D14*Ввод!B6+H14+I14,0) | M14: =IF(B14="Y",D14*Ввод!B6*J14/Ввод!B7,0) | N14: =IF(B14="Y",ROUND(MIN(D14*Ввод!B19,D14*0.5),2),0) | O14: =IF(B14<>"Y","НЕТ",IF(AND(Расчеты!B11="ДА",ABS(K14)>=Ввод!B18),"ЧАСТИЧНО ЗАКРЫТЬ","ДЕРЖАТЬ")) | P14: =IF(B14<>"Y",0,IFERROR((Ввод!B12-Расчеты!B3-Ввод!B15/2+Расчеты!B6)/(Расчеты!B4-Ввод!B12-Ввод!B15/2-Расчеты!B6),0)) | Q14: =IF(B14="Y",B14&C14,"")
J15: =IF(C15="BUY",Ввод!B13,Ввод!B14) | K15: =IF(C15="BUY",J15-E15,E15-J15) | L15: =IF(B15="Y",K15*D15*Ввод!B6+H15+I15,0) | M15: =IF(B15="Y",D15*Ввод!B6*J15/Ввод!B7,0) | N15: =IF(B15="Y",ROUND(MIN(D15*Ввод!B19,D15*0.5),2),0) | O15: =IF(B15<>"Y","НЕТ",IF(AND(Расчеты!B11="ДА",ABS(K15)>=Ввод!B18),"ЧАСТИЧНО ЗАКРЫТЬ","ДЕРЖАТЬ")) | P15: =IF(B15<>"Y",0,IFERROR((Ввод!B12-Расчеты!B3-Ввод!B15/2+Расчеты!B6)/(Расчеты!B4-Ввод!B12-Ввод!B15/2-Расчеты!B6),0)) | Q15: =IF(B15="Y",B15&C15,"")
J16: =IF(C16="BUY",Ввод!B13,Ввод!B14) | K16: =IF(C16="BUY",J16-E16,E16-J16) | L16: =IF(B16="Y",K16*D16*Ввод!B6+H16+I16,0) | M16: =IF(B16="Y",D16*Ввод!B6*J16/Ввод!B7,0) | N16: =IF(B16="Y",ROUND(MIN(D16*Ввод!B19,D16*0.5),2),0) | O16: =IF(B16<>"Y","НЕТ",IF(AND(Расчеты!B11="ДА",ABS(K16)>=Ввод!B18),"ЧАСТИЧНО ЗАКРЫТЬ","ДЕРЖАТЬ")) | P16: =IF(B16<>"Y",0,IFERROR((Ввод!B12-Расчеты!B3-Ввод!B15/2+Расчеты!B6)/(Расчеты!B4-Ввод!B12-Ввод!B15/2-Расчеты!B6),0)) | Q16: =IF(B16="Y",B16&C16,"")
J17: =IF(C17="BUY",Ввод!B13,Ввод!B14) | K17: =IF(C17="BUY",J17-E17,E17-J17) | L17: =IF(B17="Y",K17*D17*Ввод!B6+H17+I17,0) | M17: =IF(B17="Y",D17*Ввод!B6*J17/Ввод!B7,0) | N17: =IF(B17="Y",ROUND(MIN(D17*Ввод!B19,D17*0.5),2),0) | O17: =IF(B17<>"Y","НЕТ",IF(AND(Расчеты!B11="ДА",ABS(K17)>=Ввод!B18),"ЧАСТИЧНО ЗАКРЫТЬ","ДЕРЖАТЬ")) | P17: =IF(B17<>"Y",0,IFERROR((Ввод!B12-Расчеты!B3-Ввод!B15/2+Расчеты!B6)/(Расчеты!B4-Ввод!B12-Ввод!B15/2-Расчеты!B6),0)) | Q17: =IF(B17="Y",B17&C17,"")
J18: =IF(C18="BUY",Ввод!B13,Ввод!B14) | K18: =IF(C18="BUY",J18-E18,E18-J18) | L18: =IF(B18="Y",K18*D18*Ввод!B6+H18+I18,0) | M18: =IF(B18="Y",D18*Ввод!B6*J18/Ввод!B7,0) | N18: =IF(B18="Y",ROUND(MIN(D18*Ввод!B19,D18*0.5),2),0) | O18: =IF(B18<>"Y","НЕТ",IF(AND(Расчеты!B11="ДА",ABS(K18)>=Ввод!B18),"ЧАСТИЧНО ЗАКРЫТЬ","ДЕРЖАТЬ")) | P18: =IF(B18<>"Y",0,IFERROR((Ввод!B12-Расчеты!B3-Ввод!B15/2+Расчеты!B6)/(Расчеты!B4-Ввод!B12-Ввод!B15/2-Расчеты!B6),0)) | Q18: =IF(B18="Y",B18&C18,"")
J19: =IF(C19="BUY",Ввод!B13,Ввод!B14) | K19: =IF(C19="BUY",J19-E19,E19-J19) | L19: =IF(B19="Y",K19*D19*Ввод!B6+H19+I19,0) | M19: =IF(B19="Y",D19*Ввод!B6*J19/Ввод!B7,0) | N19: =IF(B19="Y",ROUND(MIN(D19*Ввод!B19,D19*0.5),2),0) | O19: =IF(B19<>"Y","НЕТ",IF(AND(Расчеты!B11="ДА",ABS(K19)>=Ввод!B18),"ЧАСТИЧНО ЗАКРЫТЬ","ДЕРЖАТЬ")) | P19: =IF(B19<>"Y",0,IFERROR((Ввод!B12-Расчеты!B3-Ввод!B15/2+Расчеты!B6)/(Расчеты!B4-Ввод!B12-Ввод!B15/2-Расчеты!B6),0)) | Q19: =IF(B19="Y",B19&C19,"")
J20: =IF(C20="BUY",Ввод!B13,Ввод!B14) | K20: =IF(C20="BUY",J20-E20,E20-J20) | L20: =IF(B20="Y",K20*D20*Ввод!B6+H20+I20,0) | M20: =IF(B20="Y",D20*Ввод!B6*J20/Ввод!B7,0) | N20: =IF(B20="Y",ROUND(MIN(D20*Ввод!B19,D20*0.5),2),0) | O20: =IF(B20<>"Y","НЕТ",IF(AND(Расчеты!B11="ДА",ABS(K20)>=Ввод!B18),"ЧАСТИЧНО ЗАКРЫТЬ","ДЕРЖАТЬ")) | P20: =IF(B20<>"Y",0,IFERROR((Ввод!B12-Расчеты!B3-Ввод!B15/2+Расчеты!B6)/(Расчеты!B4-Ввод!B12-Ввод!B15/2-Расчеты!B6),0)) | Q20: =IF(B20="Y",B20&C20,"")
J21: =IF(C21="BUY",Ввод!B13,Ввод!B14) | K21: =IF(C21="BUY",J21-E21,E21-J21) | L21: =IF(B21="Y",K21*D21*Ввод!B6+H21+I21,0) | M21: =IF(B21="Y",D21*Ввод!B6*J21/Ввод!B7,0) | N21: =IF(B21="Y",ROUND(MIN(D21*Ввод!B19,D21*0.5),2),0) | O21: =IF(B21<>"Y","НЕТ",IF(AND(Расчеты!B11="ДА",ABS(K21)>=Ввод!B18),"ЧАСТИЧНО ЗАКРЫТЬ","ДЕРЖАТЬ")) | P21: =IF(B21<>"Y",0,IFERROR((Ввод!B12-Расчеты!B3-Ввод!B15/2+Расчеты!B6)/(Расчеты!B4-Ввод!B12-Ввод!B15/2-Расчеты!B6),0)) | Q21: =IF(B21="Y",B21&C21,"")
J22: =IF(C22="BUY",Ввод!B13,Ввод!B14) | K22: =IF(C22="BUY",J22-E22,E22-J22) | L22: =IF(B22="Y",K22*D22*Ввод!B6+H22+I22,0) | M22: =IF(B22="Y",D22*Ввод!B6*J22/Ввод!B7,0) | N22: =IF(B22="Y",ROUND(MIN(D22*Ввод!B19,D22*0.5),2),0) | O22: =IF(B22<>"Y","НЕТ",IF(AND(Расчеты!B11="ДА",ABS(K22)>=Ввод!B18),"ЧАСТИЧНО ЗАКРЫТЬ","ДЕРЖАТЬ")) | P22: =IF(B22<>"Y",0,IFERROR((Ввод!B12-Расчеты!B3-Ввод!B15/2+Расчеты!B6)/(Расчеты!B4-Ввод!B12-Ввод!B15/2-Расчеты!B6),0)) | Q22: =IF(B22="Y",B22&C22,"")
J23: =IF(C23="BUY",Ввод!B13,Ввод!B14) | K23: =IF(C23="BUY",J23-E23,E23-J23) | L23: =IF(B23="Y",K23*D23*Ввод!B6+H23+I23,0) | M23: =IF(B23="Y",D23*Ввод!B6*J23/Ввод!B7,0) | N23: =IF(B23="Y",ROUND(MIN(D23*Ввод!B19,D23*0.5),2),0) | O23: =IF(B23<>"Y","НЕТ",IF(AND(Расчеты!B11="ДА",ABS(K23)>=Ввод!B18),"ЧАСТИЧНО ЗАКРЫТЬ","ДЕРЖАТЬ")) | P23: =IF(B23<>"Y",0,IFERROR((Ввод!B12-Расчеты!B3-Ввод!B15/2+Расчеты!B6)/(Расчеты!B4-Ввод!B12-Ввод!B15/2-Расчеты!B6),0)) | Q23: =IF(B23="Y",B23&C23,"")
J24: =IF(C24="BUY",Ввод!B13,Ввод!B14) | K24: =IF(C24="BUY",J24-E24,E24-J24) | L24: =IF(B24="Y",K24*D24*Ввод!B6+H24+I24,0) | M24: =IF(B24="Y",D24*Ввод!B6*J24/Ввод!B7,0) | N24: =IF(B24="Y",ROUND(MIN(D24*Ввод!B19,D24*0.5),2),0) | O24: =IF(B24<>"Y","НЕТ",IF(AND(Расчеты!B11="ДА",ABS(K24)>=Ввод!B18),"ЧАСТИЧНО ЗАКРЫТЬ","ДЕРЖАТЬ")) | P24: =IF(B24<>"Y",0,IFERROR((Ввод!B12-Расчеты!B3-Ввод!B15/2+Расчеты!B6)/(Расчеты!B4-Ввод!B12-Ввод!B15/2-Расчеты!B6),0)) | Q24: =IF(B24="Y",B24&C24,"")
J25: =IF(C25="BUY",Ввод!B13,Ввод!B14) | K25: =IF(C25="BUY",J25-E25,E25-J25) | L25: =IF(B25="Y",K25*D25*Ввод!B6+H25+I25,0) | M25: =IF(B25="Y",D25*Ввод!B6*J25/Ввод!B7,0) | N25: =IF(B25="Y",ROUND(MIN(D25*Ввод!B19,D25*0.5),2),0) | O25: =IF(B25<>"Y","НЕТ",IF(AND(Расчеты!B11="ДА",ABS(K25)>=Ввод!B18),"ЧАСТИЧНО ЗАКРЫТЬ","ДЕРЖАТЬ")) | P25: =IF(B25<>"Y",0,IFERROR((Ввод!B12-Расчеты!B3-Ввод!B15/2+Расчеты!B6)/(Расчеты!B4-Ввод!B12-Ввод!B15/2-Расчеты!B6),0)) | Q25: =IF(B25="Y",B25&C25,"")
J26: =IF(C26="BUY",Ввод!B13,Ввод!B14) | K26: =IF(C26="BUY",J26-E26,E26-J26) | L26: =IF(B26="Y",K26*D26*Ввод!B6+H26+I26,0) | M26: =IF(B26="Y",D26*Ввод!B6*J26/Ввод!B7,0) | N26: =IF(B26="Y",ROUND(MIN(D26*Ввод!B19,D26*0.5),2),0) | O26: =IF(B26<>"Y","НЕТ",IF(AND(Расчеты!B11="ДА",ABS(K26)>=Ввод!B18),"ЧАСТИЧНО ЗАКРЫТЬ","ДЕРЖАТЬ")) | P26: =IF(B26<>"Y",0,IFERROR((Ввод!B12-Расчеты!B3-Ввод!B15/2+Расчеты!B6)/(Расчеты!B4-Ввод!B12-Ввод!B15/2-Расчеты!B6),0)) | Q26: =IF(B26="Y",B26&C26,"")
J27: =IF(C27="BUY",Ввод!B13,Ввод!B14) | K27: =IF(C27="BUY",J27-E27,E27-J27) | L27: =IF(B27="Y",K27*D27*Ввод!B6+H27+I27,0) | M27: =IF(B27="Y",D27*Ввод!B6*J27/Ввод!B7,0) | N27: =IF(B27="Y",ROUND(MIN(D27*Ввод!B19,D27*0.5),2),0) | O27: =IF(B27<>"Y","НЕТ",IF(AND(Расчеты!B11="ДА",ABS(K27)>=Ввод!B18),"ЧАСТИЧНО ЗАКРЫТЬ","ДЕРЖАТЬ")) | P27: =IF(B27<>"Y",0,IFERROR((Ввод!B12-Расчеты!B3-Ввод!B15/2+Расчеты!B6)/(Расчеты!B4-Ввод!B12-Ввод!B15/2-Расчеты!B6),0)) | Q27: =IF(B27="Y",B27&C27,"")
J28: =IF(C28="BUY",Ввод!B13,Ввод!B14) | K28: =IF(C28="BUY",J28-E28,E28-J28) | L28: =IF(B28="Y",K28*D28*Ввод!B6+H28+I28,0) | M28: =IF(B28="Y",D28*Ввод!B6*J28/Ввод!B7,0) | N28: =IF(B28="Y",ROUND(MIN(D28*Ввод!B19,D28*0.5),2),0) | O28: =IF(B28<>"Y","НЕТ",IF(AND(Расчеты!B11="ДА",ABS(K28)>=Ввод!B18),"ЧАСТИЧНО ЗАКРЫТЬ","ДЕРЖАТЬ")) | P28: =IF(B28<>"Y",0,IFERROR((Ввод!B12-Расчеты!B3-Ввод!B15/2+Расчеты!B6)/(Расчеты!B4-Ввод!B12-Ввод!B15/2-Расчеты!B6),0)) | Q28: =IF(B28="Y",B28&C28,"")
J29: =IF(C29="BUY",Ввод!B13,Ввод!B14) | K29: =IF(C29="BUY",J29-E29,E29-J29) | L29: =IF(B29="Y",K29*D29*Ввод!B6+H29+I29,0) | M29: =IF(B29="Y",D29*Ввод!B6*J29/Ввод!B7,0) | N29: =IF(B29="Y",ROUND(MIN(D29*Ввод!B19,D29*0.5),2),0) | O29: =IF(B29<>"Y","НЕТ",IF(AND(Расчеты!B11="ДА",ABS(K29)>=Ввод!B18),"ЧАСТИЧНО ЗАКРЫТЬ","ДЕРЖАТЬ")) | P29: =IF(B29<>"Y",0,IFERROR((Ввод!B12-Расчеты!B3-Ввод!B15/2+Расчеты!B6)/(Расчеты!B4-Ввод!B12-Ввод!B15/2-Расчеты!B6),0)) | Q29: =IF(B29="Y",B29&C29,"")
J30: =IF(C30="BUY",Ввод!B13,Ввод!B14) | K30: =IF(C30="BUY",J30-E30,E30-J30) | L30: =IF(B30="Y",K30*D30*Ввод!B6+H30+I30,0) | M30: =IF(B30="Y",D30*Ввод!B6*J30/Ввод!B7,0) | N30: =IF(B30="Y",ROUND(MIN(D30*Ввод!B19,D30*0.5),2),0) | O30: =IF(B30<>"Y","НЕТ",IF(AND(Расчеты!B11="ДА",ABS(K30)>=Ввод!B18),"ЧАСТИЧНО ЗАКРЫТЬ","ДЕРЖАТЬ")) | P30: =IF(B30<>"Y",0,IFERROR((Ввод!B12-Расчеты!B3-Ввод!B15/2+Расчеты!B6)/(Расчеты!B4-Ввод!B12-Ввод!B15/2-Расчеты!B6),0)) | Q30: =IF(B30="Y",B30&C30,"")
J31: =IF(C31="BUY",Ввод!B13,Ввод!B14) | K31: =IF(C31="BUY",J31-E31,E31-J31) | L31: =IF(B31="Y",K31*D31*Ввод!B6+H31+I31,0) | M31: =IF(B31="Y",D31*Ввод!B6*J31/Ввод!B7,0) | N31: =IF(B31="Y",ROUND(MIN(D31*Ввод!B19,D31*0.5),2),0) | O31: =IF(B31<>"Y","НЕТ",IF(AND(Расчеты!B11="ДА",ABS(K31)>=Ввод!B18),"ЧАСТИЧНО ЗАКРЫТЬ","ДЕРЖАТЬ")) | P31: =IF(B31<>"Y",0,IFERROR((Ввод!B12-Расчеты!B3-Ввод!B15/2+Расчеты!B6)/(Расчеты!B4-Ввод!B12-Ввод!B15/2-Расчеты!B6),0)) | Q31: =IF(B31="Y",B31&C31,"")
J32: =IF(C32="BUY",Ввод!B13,Ввод!B14) | K32: =IF(C32="BUY",J32-E32,E32-J32) | L32: =IF(B32="Y",K32*D32*Ввод!B6+H32+I32,0) | M32: =IF(B32="Y",D32*Ввод!B6*J32/Ввод!B7,0) | N32: =IF(B32="Y",ROUND(MIN(D32*Ввод!B19,D32*0.5),2),0) | O32: =IF(B32<>"Y","НЕТ",IF(AND(Расчеты!B11="ДА",ABS(K32)>=Ввод!B18),"ЧАСТИЧНО ЗАКРЫТЬ","ДЕРЖАТЬ")) | P32: =IF(B32<>"Y",0,IFERROR((Ввод!B12-Расчеты!B3-Ввод!B15/2+Расчеты!B6)/(Расчеты!B4-Ввод!B12-Ввод!B15/2-Расчеты!B6),0)) | Q32: =IF(B32="Y",B32&C32,"")
J33: =IF(C33="BUY",Ввод!B13,Ввод!B14) | K33: =IF(C33="BUY",J33-E33,E33-J33) | L33: =IF(B33="Y",K33*D33*Ввод!B6+H33+I33,0) | M33: =IF(B33="Y",D33*Ввод!B6*J33/Ввод!B7,0) | N33: =IF(B33="Y",ROUND(MIN(D33*Ввод!B19,D33*0.5),2),0) | O33: =IF(B33<>"Y","НЕТ",IF(AND(Расчеты!B11="ДА",ABS(K33)>=Ввод!B18),"ЧАСТИЧНО ЗАКРЫТЬ","ДЕРЖАТЬ")) | P33: =IF(B33<>"Y",0,IFERROR((Ввод!B12-Расчеты!B3-Ввод!B15/2+Расчеты!B6)/(Расчеты!B4-Ввод!B12-Ввод!B15/2-Расчеты!B6),0)) | Q33: =IF(B33="Y",B33&C33,"")
J34: =IF(C34="BUY",Ввод!B13,Ввод!B14) | K34: =IF(C34="BUY",J34-E34,E34-J34) | L34: =IF(B34="Y",K34*D34*Ввод!B6+H34+I34,0) | M34: =IF(B34="Y",D34*Ввод!B6*J34/Ввод!B7,0) | N34: =IF(B34="Y",ROUND(MIN(D34*Ввод!B19,D34*0.5),2),0) | O34: =IF(B34<>"Y","НЕТ",IF(AND(Расчеты!B11="ДА",ABS(K34)>=Ввод!B18),"ЧАСТИЧНО ЗАКРЫТЬ","ДЕРЖАТЬ")) | P34: =IF(B34<>"Y",0,IFERROR((Ввод!B12-Расчеты!B3-Ввод!B15/2+Расчеты!B6)/(Расчеты!B4-Ввод!B12-Ввод!B15/2-Расчеты!B6),0)) | Q34: =IF(B34="Y",B34&C34,"")
J35: =IF(C35="BUY",Ввод!B13,Ввод!B14) | K35: =IF(C35="BUY",J35-E35,E35-J35) | L35: =IF(B35="Y",K35*D35*Ввод!B6+H35+I35,0) | M35: =IF(B35="Y",D35*Ввод!B6*J35/Ввод!B7,0) | N35: =IF(B35="Y",ROUND(MIN(D35*Ввод!B19,D35*0.5),2),0) | O35: =IF(B35<>"Y","НЕТ",IF(AND(Расчеты!B11="ДА",ABS(K35)>=Ввод!B18),"ЧАСТИЧНО ЗАКРЫТЬ","ДЕРЖАТЬ")) | P35: =IF(B35<>"Y",0,IFERROR((Ввод!B12-Расчеты!B3-Ввод!B15/2+Расчеты!B6)/(Расчеты!B4-Ввод!B12-Ввод!B15/2-Расчеты!B6),0)) | Q35: =IF(B35="Y",B35&C35,"")
J36: =IF(C36="BUY",Ввод!B13,Ввод!B14) | K36: =IF(C36="BUY",J36-E36,E36-J36) | L36: =IF(B36="Y",K36*D36*Ввод!B6+H36+I36,0) | M36: =IF(B36="Y",D36*Ввод!B6*J36/Ввод!B7,0) | N36: =IF(B36="Y",ROUND(MIN(D36*Ввод!B19,D36*0.5),2),0) | O36: =IF(B36<>"Y","НЕТ",IF(AND(Расчеты!B11="ДА",ABS(K36)>=Ввод!B18),"ЧАСТИЧНО ЗАКРЫТЬ","ДЕРЖАТЬ")) | P36: =IF(B36<>"Y",0,IFERROR((Ввод!B12-Расчеты!B3-Ввод!B15/2+Расчеты!B6)/(Расчеты!B4-Ввод!B12-Ввод!B15/2-Расчеты!B6),0)) | Q36: =IF(B36="Y",B36&C36,"")
J37: =IF(C37="BUY",Ввод!B13,Ввод!B14) | K37: =IF(C37="BUY",J37-E37,E37-J37) | L37: =IF(B37="Y",K37*D37*Ввод!B6+H37+I37,0) | M37: =IF(B37="Y",D37*Ввод!B6*J37/Ввод!B7,0) | N37: =IF(B37="Y",ROUND(MIN(D37*Ввод!B19,D37*0.5),2),0) | O37: =IF(B37<>"Y","НЕТ",IF(AND(Расчеты!B11="ДА",ABS(K37)>=Ввод!B18),"ЧАСТИЧНО ЗАКРЫТЬ","ДЕРЖАТЬ")) | P37: =IF(B37<>"Y",0,IFERROR((Ввод!B12-Расчеты!B3-Ввод!B15/2+Расчеты!B6)/(Расчеты!B4-Ввод!B12-Ввод!B15/2-Расчеты!B6),0)) | Q37: =IF(B37="Y",B37&C37,"")
J38: =IF(C38="BUY",Ввод!B13,Ввод!B14) | K38: =IF(C38="BUY",J38-E38,E38-J38) | L38: =IF(B38="Y",K38*D38*Ввод!B6+H38+I38,0) | M38: =IF(B38="Y",D38*Ввод!B6*J38/Ввод!B7,0) | N38: =IF(B38="Y",ROUND(MIN(D38*Ввод!B19,D38*0.5),2),0) | O38: =IF(B38<>"Y","НЕТ",IF(AND(Расчеты!B11="ДА",ABS(K38)>=Ввод!B18),"ЧАСТИЧНО ЗАКРЫТЬ","ДЕРЖАТЬ")) | P38: =IF(B38<>"Y",0,IFERROR((Ввод!B12-Расчеты!B3-Ввод!B15/2+Расчеты!B6)/(Расчеты!B4-Ввод!B12-Ввод!B15/2-Расчеты!B6),0)) | Q38: =IF(B38="Y",B38&C38,"")
J39: =IF(C39="BUY",Ввод!B13,Ввод!B14) | K39: =IF(C39="BUY",J39-E39,E39-J39) | L39: =IF(B39="Y",K39*D39*Ввод!B6+H39+I39,0) | M39: =IF(B39="Y",D39*Ввод!B6*J39/Ввод!B7,0) | N39: =IF(B39="Y",ROUND(MIN(D39*Ввод!B19,D39*0.5),2),0) | O39: =IF(B39<>"Y","НЕТ",IF(AND(Расчеты!B11="ДА",ABS(K39)>=Ввод!B18),"ЧАСТИЧНО ЗАКРЫТЬ","ДЕРЖАТЬ")) | P39: =IF(B39<>"Y",0,IFERROR((Ввод!B12-Расчеты!B3-Ввод!B15/2+Расчеты!B6)/(Расчеты!B4-Ввод!B12-Ввод!B15/2-Расчеты!B6),0)) | Q39: =IF(B39="Y",B39&C39,"")
J40: =IF(C40="BUY",Ввод!B13,Ввод!B14) | K40: =IF(C40="BUY",J40-E40,E40-J40) | L40: =IF(B40="Y",K40*D40*Ввод!B6+H40+I40,0) | M40: =IF(B40="Y",D40*Ввод!B6*J40/Ввод!B7,0) | N40: =IF(B40="Y",ROUND(MIN(D40*Ввод!B19,D40*0.5),2),0) | O40: =IF(B40<>"Y","НЕТ",IF(AND(Расчеты!B11="ДА",ABS(K40)>=Ввод!B18),"ЧАСТИЧНО ЗАКРЫТЬ","ДЕРЖАТЬ")) | P40: =IF(B40<>"Y",0,IFERROR((Ввод!B12-Расчеты!B3-Ввод!B15/2+Расчеты!B6)/(Расчеты!B4-Ввод!B12-Ввод!B15/2-Расчеты!B6),0)) | Q40: =IF(B40="Y",B40&C40,"")
...

Sheet Расчеты
A1: Сумма BUY лотов | B1: =SUMIFS(Позиции!D2:D201,Позиции!C2:C201,"BUY",Позиции!B2:B201,"Y")
A2: Сумма SELL лотов | B2: =SUMIFS(Позиции!D2:D201,Позиции!C2:C201,"SELL",Позиции!B2:B201,"Y")
A3: Средняя цена BUY | B3: =IF(B1=0,0,SUMPRODUCT((Позиции!C2:C201="BUY")*(Позиции!B2:B201="Y")*Позиции!D2:D201*Позиции!E2:E201)/B1)
A4: Средняя цена SELL | B4: =IF(B2=0,0,SUMPRODUCT((Позиции!C2:C201="SELL")*(Позиции!B2:B201="Y")*Позиции!D2:D201*Позиции!E2:E201)/B2)
A5: P_avg | B5: =IF(B1+B2=0,0,(B1*B3+B2*B4)/(B1+B2))
A6: δ = S + α*ATR | B6: =Ввод!B15 + Ввод!B17*Ввод!B16
A7: Левая часть survival: δ*Ls | B7: =B6*B2
A8: Правая часть survival: Δ*Lb | B8: =Ввод!B18*B1
A9: Условие survival | B9: =IF(B7>B8,"OK","FAIL")
A10: |P-P_avg| | B10: =ABS(Ввод!B12-B5)
A11: Триггер |P-P_avg|>Δ | B11: =IF(B10>Ввод!B18,"ДА","НЕТ")
A12: Общий плавающий P/L | B12: =SUM(Позиции!L2:L201)
A13: Общая маржа | B13: =SUM(Позиции!M2:M201)
A14: Нагрузка на депозит, % | B14: =IF(Ввод!B9=0,0,B13/Ввод!B9*100)
A15: Чистая экспозиция (BUY-SELL) | B15: =B1-B2
A16: Текущая просадка от баланса, % | B16: =IF(Ввод!B9=0,0,(B12/Ввод!B9)*100)
A17: ID первой активной BUY | B17: =IFERROR(INDEX(Позиции!A$2:A$201,MATCH("YBUY",Позиции!Q$2:Q$201,0)),"НЕТ")
A18: ID первой активной SELL | B18: =IFERROR(INDEX(Позиции!A$2:A$201,MATCH("YSELL",Позиции!Q$2:Q$201,0)),"НЕТ")
A19: Лот выбранной BUY | B19: =IFERROR(INDEX(Позиции!D$2:D$201,MATCH(B17,Позиции!A$2:A$201,0)),0)
A20: Лот выбранной SELL | B20: =IFERROR(INDEX(Позиции!D$2:D$201,MATCH(B18,Позиции!A$2:A$201,0)),0)

Sheet Следующий шаг
A1: Сценарий | B1: Целевая цена | C1: ID Позиции | D1: Для BUY/SELL | E1: Направление шага | F1: Рекоменд. лот | G1: Действие | H1: Частично закрыть лот | I1: Полностью закрыть? | J1: Причина
A2: Цена вверх на Δ | B2: =Ввод!B12+Ввод!B18 | C2: =IF(D2="BUY (Рекомендации для выбранной BUY)",Расчеты!B17,Расчеты!B18) | D2: BUY (Рекомендации для выбранной BUY) | E2: BUY trim / SELL hedge | F2: =IF(Расчеты!B17="НЕТ",0,MAX(0.01,ROUND(Расчеты!B19*Ввод!B19*Ввод!B23*0.5,2))) | G2: =IF(AND(Расчеты!B11="ДА",F2>0),"ЧАСТИЧНАЯ РЕБАЛАНСИРОВКА","ОЖИДАТЬ") | H2: =IF(F2=0,0,IF(OR(E2="BUY partial",E2="SELL partial"),ROUND(F2,2),ROUND(F2*0.6,2))) | I2: =IF(OR(Расчеты!B9="FAIL",Расчеты!B14>Ввод!B22,Расчеты!B16<-Ввод!B21),"ДА","НЕТ") | J2: =IF(I2="ДА","Риск превышен: survival/маржа/просадка","Нормальный цикл")
A3: Цена вверх на Δ | B3: =Ввод!B12+Ввод!B18 | C3: =IF(D3="BUY (Рекомендации для выбранной BUY)",Расчеты!B17,Расчеты!B18) | D3: SELL (Рекомендации для выбранной SELL) | E3: SELL partial | F3: =IF(Расчеты!B18="НЕТ",0,MAX(0.01,ROUND(Расчеты!B20*Ввод!B19*Ввод!B23*2,2))) | G3: =IF(AND(Расчеты!B11="ДА",F3>0),"ЧАСТИЧНАЯ РЕБАЛАНСИРОВКА","ОЖИДАТЬ") | H3: =IF(F3=0,0,IF(OR(E3="BUY partial",E3="SELL partial"),ROUND(F3,2),ROUND(F3*0.6,2))) | I3: =IF(OR(Расчеты!B9="FAIL",Расчеты!B14>Ввод!B22,Расчеты!B16<-Ввод!B21),"ДА","НЕТ") | J3: =IF(I3="ДА","Риск превышен: survival/маржа/просадка","Нормальный цикл")
A4: Цена вниз на Δ | B4: =Ввод!B12-Ввод!B18 | C4: =IF(D4="BUY (Рекомендации для выбранной BUY)",Расчеты!B17,Расчеты!B18) | D4: BUY (Рекомендации для выбранной BUY) | E4: BUY partial | F4: =IF(Расчеты!B17="НЕТ",0,MAX(0.01,ROUND(Расчеты!B19*Ввод!B19*Ввод!B23*2,2))) | G4: =IF(AND(Расчеты!B11="ДА",F4>0),"ЧАСТИЧНАЯ РЕБАЛАНСИРОВКА","ОЖИДАТЬ") | H4: =IF(F4=0,0,IF(OR(E4="BUY partial",E4="SELL partial"),ROUND(F4,2),ROUND(F4*0.6,2))) | I4: =IF(OR(Расчеты!B9="FAIL",Расчеты!B14>Ввод!B22,Расчеты!B16<-Ввод!B21),"ДА","НЕТ") | J4: =IF(I4="ДА","Риск превышен: survival/маржа/просадка","Нормальный цикл")
A5: Цена вниз на Δ | B5: =Ввод!B12-Ввод!B18 | C5: =IF(D5="BUY (Рекомендации для выбранной BUY)",Расчеты!B17,Расчеты!B18) | D5: SELL (Рекомендации для выбранной SELL) | E5: SELL trim / BUY hedge | F5: =IF(Расчеты!B18="НЕТ",0,MAX(0.01,ROUND(Расчеты!B20*Ввод!B19*Ввод!B23*0.5,2))) | G5: =IF(AND(Расчеты!B11="ДА",F5>0),"ЧАСТИЧНАЯ РЕБАЛАНСИРОВКА","ОЖИДАТЬ") | H5: =IF(F5=0,0,IF(OR(E5="BUY partial",E5="SELL partial"),ROUND(F5,2),ROUND(F5*0.6,2))) | I5: =IF(OR(Расчеты!B9="FAIL",Расчеты!B14>Ввод!B22,Расчеты!B16<-Ввод!B21),"ДА","НЕТ") | J5: =IF(I5="ДА","Риск превышен: survival/маржа/просадка","Нормальный цикл")
