Workbook
Name LevelRange: Settings!$A$22:$A$200
Name BigPercentRange: Settings!$B$22:$B$200
Name SmallPercentRange: Settings!$C$22:$C$200
Name TargetSkewRange: Settings!$D$22:$D$200
Name ManualCloseRange: Settings!$E$22:$E$200

Sheet Settings
A2: StartLot | B2: 1
A3: PointStep | B3: 100
A4: MaxLevels | B4: 5
A5: LotStep | B5: 0.01
A6: RoundMode | B6: Nearest
A7: TargetSkewMin% | B7: 5
A8: TargetSkewMax% | B8: 25
A9: UseRounding | B9: TRUE
A10: Direction | B10: DOWN
A11: BigRoundMode_DOWN | B11: DOWN
A12: SmallRoundMode_DOWN | B12: UP
A13: CloseRoundMode_DOWN | B13: SAFE
A14: BigRoundMode_UP | B14: DOWN
A15: SmallRoundMode_UP | B15: UP
A16: CloseRoundMode_UP | B16: SAFE
A17: EnableRiskSafeRounding | B17: TRUE
A18: EnableInputValidation | B18: TRUE
A21: Level | B21: Big% | C21: Small% | D21: TargetSkew% | E21: ManualClose%
A22: 1 | B22: 90 | C22: 30 | D22: 0
A23: 2 | B23: 30 | C23: 15 | D23: 15
A24: 3 | B24: 20 | C24: 15 | D24: 10
A25: 4 | B25: 10 | C25: 10 | D25: 10
A26: 5 | B26: 5 | C26: 5 | D26: 10

Sheet DownTrend
A1: Level | B1: PriceStep | C1: Big % | D1: Big Lot | E1: Small % | F1: Small Lot | G1: Start Before % | H1: Before Close % | I1: Opposite After Add % | J1: Target Skew % | K1: Auto Close % | L1: Manual Close % | M1: Final Close % | N1: Start After % | O1: Sum Big % | P1: Sum Small % | Q1: Total Main % | R1: Total Opposite % | S1: Skew % | T1: Status | U1: Comment | V1: Big Raw Lot | W1: Big Rounded | X1: Small Raw Lot | Y1: Small Rounded | Z1: Close Raw Lot | AA1: Close Rounded | AB1: Safe Rounding Status | AC1: Rounding Comment
A2: 0 | B2: 0 | C2: 0 | D2: =W2 | E2: 0 | F2: =Y2 | G2: 100 | H2: 100 | I2: 100 | J2: 0 | K2: 0 | M2: 0 | N2: 100 | O2: 0 | P2: 0 | Q2: =N2+O2 | R2: =100+P2 | S2: =R2-Q2 | T2: =IF(Settings!$B$18=FALSE,"OK",IF(OR(NOT(ISNUMBER(Settings!$B$2)),Settings!$B$2<=0),"ERROR: Invalid StartLot",IF(OR(NOT(ISNUMBER(Settings!$B$5)),Settings!$B$5<=0),"ERROR: Invalid LotStep",IF(OR(Settings!$B$4<1,Settings!$B$4>20),"ERROR: Invalid MaxLevels",IF(AND(Settings!$B$10<>"DOWN",Settings!$B$10<>"UP"),"ERROR: Invalid Direction",IF(OR(C2<0,E2<0,J2<0,AND(LEN(L2)>0,L2<0)),"ERROR: Negative input",IF(C2<E2,"ERROR: Big BUY must be >= Small SELL",IF(AND(LEN(L2)>0,L2>G2),"ERROR: ManualClose exceeds remaining Start position",IF(OR(N2<0,Q2<0,R2<0),"ERROR: Negative totals",IF(Q2>R2,"ERROR: Rounding broke protection balance",IF(S2>Settings!$B$8,"WARNING: Skew exceeds recommended limit","OK"))))))))))) | U2: =IF(LEFT(T2,5)="ERROR","Check input/risk","") | V2: 0 | W2: 0 | X2: 0 | Y2: 0 | Z2: 0 | AA2: 0 | AB2: =IF(LEFT(T2,5)="ERROR","ERROR",IF(AND(Settings!$B$17,ABS(AA2-Z2)>1E-9),"FIXED",IF(ABS(S2)<=Settings!$B$7,"SAFE","WARNING"))) | AC2: =IF(AB2="FIXED","Close adjusted by SAFE mode",IF(AB2="SAFE","BUY/SELL balance preserved",IF(AB2="WARNING","Near protection boundary","Protection broken")))
A3: 1 | B3: =A3*Settings!$B$3 | C3: =IF(A3<=Settings!$B$4,IFERROR(XLOOKUP(A3,LevelRange,BigPercentRange),0),0) | D3: =W3 | E3: =IF(A3<=Settings!$B$4,IFERROR(XLOOKUP(A3,LevelRange,SmallPercentRange),0),0) | F3: =Y3 | G3: 100 | H3: =G3+SUM($C$3:C3) | I3: =100+SUM($E$3:E3) | J3: =IF(A3<=Settings!$B$4,IFERROR(XLOOKUP(A3,LevelRange,TargetSkewRange),0),0) | K3: =MIN(G3,MAX(0,H3-I3+J3)) | L3: =IF(A3<=Settings!$B$4,IFERROR(XLOOKUP(A3,LevelRange,ManualCloseRange),""),"") | M3: =MIN(G3,AA3/Settings!$B$2*100) | N3: =G3-M3 | O3: =SUM($C$3:C3) | P3: =SUM($E$3:E3) | Q3: =N3+O3 | R3: =100+P3 | S3: =R3-Q3 | T3: =IF(Settings!$B$18=FALSE,"OK",IF(OR(NOT(ISNUMBER(Settings!$B$2)),Settings!$B$2<=0),"ERROR: Invalid StartLot",IF(OR(NOT(ISNUMBER(Settings!$B$5)),Settings!$B$5<=0),"ERROR: Invalid LotStep",IF(OR(Settings!$B$4<1,Settings!$B$4>20),"ERROR: Invalid MaxLevels",IF(AND(Settings!$B$10<>"DOWN",Settings!$B$10<>"UP"),"ERROR: Invalid Direction",IF(OR(C3<0,E3<0,J3<0,AND(LEN(L3)>0,L3<0)),"ERROR: Negative input",IF(C3<E3,"ERROR: Big BUY must be >= Small SELL",IF(AND(LEN(L3)>0,L3>G3),"ERROR: ManualClose exceeds remaining Start position",IF(OR(N3<0,Q3<0,R3<0),"ERROR: Negative totals",IF(Q3>R3,"ERROR: Rounding broke protection balance",IF(S3>Settings!$B$8,"WARNING: Skew exceeds recommended limit","OK"))))))))))) | U3: =IF(LEFT(T3,5)="ERROR","Check input/risk","") | V3: =Settings!$B$2*C3/100 | W3: =IF(Settings!$B$9,FLOOR(V3,Settings!$B$5),V3) | X3: =Settings!$B$2*E3/100 | Y3: =IF(Settings!$B$9,CEILING(X3,Settings!$B$5),X3) | Z3: =Settings!$B$2*M3/100 | AA3: =IF(Settings!$B$17,MIN(Settings!$B$2*G3/100,IF(Settings!$B$9,CEILING(MAX(0,V3+Settings!$B$2*G3/100-X3-Settings!$B$2*J3/100),Settings!$B$5),MAX(0,V3+Settings!$B$2*G3/100-X3-Settings!$B$2*J3/100))),IF(Settings!$B$9,MROUND(Z3,Settings!$B$5),Z3)) | AB3: =IF(LEFT(T3,5)="ERROR","ERROR",IF(AND(Settings!$B$17,ABS(AA3-Z3)>1E-9),"FIXED",IF(ABS(S3)<=Settings!$B$7,"SAFE","WARNING"))) | AC3: =IF(AB3="FIXED","Close adjusted by SAFE mode",IF(AB3="SAFE","BUY/SELL balance preserved",IF(AB3="WARNING","Near protection boundary","Protection broken")))
A4: 2 | B4: =A4*Settings!$B$3 | C4: =IF(A4<=Settings!$B$4,IFERROR(XLOOKUP(A4,LevelRange,BigPercentRange),0),0) | D4: =W4 | E4: =IF(A4<=Settings!$B$4,IFERROR(XLOOKUP(A4,LevelRange,SmallPercentRange),0),0) | F4: =Y4 | G4: =N3 | H4: =G4+SUM($C$3:C4) | I4: =100+SUM($E$3:E4) | J4: =IF(A4<=Settings!$B$4,IFERROR(XLOOKUP(A4,LevelRange,TargetSkewRange),0),0) | K4: =MIN(G4,MAX(0,H4-I4+J4)) | L4: =IF(A4<=Settings!$B$4,IFERROR(XLOOKUP(A4,LevelRange,ManualCloseRange),""),"") | M4: =MIN(G4,AA4/Settings!$B$2*100) | N4: =G4-M4 | O4: =SUM($C$3:C4) | P4: =SUM($E$3:E4) | Q4: =N4+O4 | R4: =100+P4 | S4: =R4-Q4 | T4: =IF(Settings!$B$18=FALSE,"OK",IF(OR(NOT(ISNUMBER(Settings!$B$2)),Settings!$B$2<=0),"ERROR: Invalid StartLot",IF(OR(NOT(ISNUMBER(Settings!$B$5)),Settings!$B$5<=0),"ERROR: Invalid LotStep",IF(OR(Settings!$B$4<1,Settings!$B$4>20),"ERROR: Invalid MaxLevels",IF(AND(Settings!$B$10<>"DOWN",Settings!$B$10<>"UP"),"ERROR: Invalid Direction",IF(OR(C4<0,E4<0,J4<0,AND(LEN(L4)>0,L4<0)),"ERROR: Negative input",IF(C4<E4,"ERROR: Big BUY must be >= Small SELL",IF(AND(LEN(L4)>0,L4>G4),"ERROR: ManualClose exceeds remaining Start position",IF(OR(N4<0,Q4<0,R4<0),"ERROR: Negative totals",IF(Q4>R4,"ERROR: Rounding broke protection balance",IF(S4>Settings!$B$8,"WARNING: Skew exceeds recommended limit","OK"))))))))))) | U4: =IF(LEFT(T4,5)="ERROR","Check input/risk","") | V4: =Settings!$B$2*C4/100 | W4: =IF(Settings!$B$9,FLOOR(V4,Settings!$B$5),V4) | X4: =Settings!$B$2*E4/100 | Y4: =IF(Settings!$B$9,CEILING(X4,Settings!$B$5),X4) | Z4: =Settings!$B$2*M4/100 | AA4: =IF(Settings!$B$17,MIN(Settings!$B$2*G4/100,IF(Settings!$B$9,CEILING(MAX(0,V4+Settings!$B$2*G4/100-X4-Settings!$B$2*J4/100),Settings!$B$5),MAX(0,V4+Settings!$B$2*G4/100-X4-Settings!$B$2*J4/100))),IF(Settings!$B$9,MROUND(Z4,Settings!$B$5),Z4)) | AB4: =IF(LEFT(T4,5)="ERROR","ERROR",IF(AND(Settings!$B$17,ABS(AA4-Z4)>1E-9),"FIXED",IF(ABS(S4)<=Settings!$B$7,"SAFE","WARNING"))) | AC4: =IF(AB4="FIXED","Close adjusted by SAFE mode",IF(AB4="SAFE","BUY/SELL balance preserved",IF(AB4="WARNING","Near protection boundary","Protection broken")))
A5: 3 | B5: =A5*Settings!$B$3 | C5: =IF(A5<=Settings!$B$4,IFERROR(XLOOKUP(A5,LevelRange,BigPercentRange),0),0) | D5: =W5 | E5: =IF(A5<=Settings!$B$4,IFERROR(XLOOKUP(A5,LevelRange,SmallPercentRange),0),0) | F5: =Y5 | G5: =N4 | H5: =G5+SUM($C$3:C5) | I5: =100+SUM($E$3:E5) | J5: =IF(A5<=Settings!$B$4,IFERROR(XLOOKUP(A5,LevelRange,TargetSkewRange),0),0) | K5: =MIN(G5,MAX(0,H5-I5+J5)) | L5: =IF(A5<=Settings!$B$4,IFERROR(XLOOKUP(A5,LevelRange,ManualCloseRange),""),"") | M5: =MIN(G5,AA5/Settings!$B$2*100) | N5: =G5-M5 | O5: =SUM($C$3:C5) | P5: =SUM($E$3:E5) | Q5: =N5+O5 | R5: =100+P5 | S5: =R5-Q5 | T5: =IF(Settings!$B$18=FALSE,"OK",IF(OR(NOT(ISNUMBER(Settings!$B$2)),Settings!$B$2<=0),"ERROR: Invalid StartLot",IF(OR(NOT(ISNUMBER(Settings!$B$5)),Settings!$B$5<=0),"ERROR: Invalid LotStep",IF(OR(Settings!$B$4<1,Settings!$B$4>20),"ERROR: Invalid MaxLevels",IF(AND(Settings!$B$10<>"DOWN",Settings!$B$10<>"UP"),"ERROR: Invalid Direction",IF(OR(C5<0,E5<0,J5<0,AND(LEN(L5)>0,L5<0)),"ERROR: Negative input",IF(C5<E5,"ERROR: Big BUY must be >= Small SELL",IF(AND(LEN(L5)>0,L5>G5),"ERROR: ManualClose exceeds remaining Start position",IF(OR(N5<0,Q5<0,R5<0),"ERROR: Negative totals",IF(Q5>R5,"ERROR: Rounding broke protection balance",IF(S5>Settings!$B$8,"WARNING: Skew exceeds recommended limit","OK"))))))))))) | U5: =IF(LEFT(T5,5)="ERROR","Check input/risk","") | V5: =Settings!$B$2*C5/100 | W5: =IF(Settings!$B$9,FLOOR(V5,Settings!$B$5),V5) | X5: =Settings!$B$2*E5/100 | Y5: =IF(Settings!$B$9,CEILING(X5,Settings!$B$5),X5) | Z5: =Settings!$B$2*M5/100 | AA5: =IF(Settings!$B$17,MIN(Settings!$B$2*G5/100,IF(Settings!$B$9,CEILING(MAX(0,V5+Settings!$B$2*G5/100-X5-Settings!$B$2*J5/100),Settings!$B$5),MAX(0,V5+Settings!$B$2*G5/100-X5-Settings!$B$2*J5/100))),IF(Settings!$B$9,MROUND(Z5,Settings!$B$5),Z5)) | AB5: =IF(LEFT(T5,5)="ERROR","ERROR",IF(AND(Settings!$B$17,ABS(AA5-Z5)>1E-9),"FIXED",IF(ABS(S5)<=Settings!$B$7,"SAFE","WARNING"))) | AC5: =IF(AB5="FIXED","Close adjusted by SAFE mode",IF(AB5="SAFE","BUY/SELL balance preserved",IF(AB5="WARNING","Near protection boundary","Protection broken")))
A6: 4 | B6: =A6*Settings!$B$3 | C6: =IF(A6<=Settings!$B$4,IFERROR(XLOOKUP(A6,LevelRange,BigPercentRange),0),0) | D6: =W6 | E6: =IF(A6<=Settings!$B$4,IFERROR(XLOOKUP(A6,LevelRange,SmallPercentRange),0),0) | F6: =Y6 | G6: =N5 | H6: =G6+SUM($C$3:C6) | I6: =100+SUM($E$3:E6) | J6: =IF(A6<=Settings!$B$4,IFERROR(XLOOKUP(A6,LevelRange,TargetSkewRange),0),0) | K6: =MIN(G6,MAX(0,H6-I6+J6)) | L6: =IF(A6<=Settings!$B$4,IFERROR(XLOOKUP(A6,LevelRange,ManualCloseRange),""),"") | M6: =MIN(G6,AA6/Settings!$B$2*100) | N6: =G6-M6 | O6: =SUM($C$3:C6) | P6: =SUM($E$3:E6) | Q6: =N6+O6 | R6: =100+P6 | S6: =R6-Q6 | T6: =IF(Settings!$B$18=FALSE,"OK",IF(OR(NOT(ISNUMBER(Settings!$B$2)),Settings!$B$2<=0),"ERROR: Invalid StartLot",IF(OR(NOT(ISNUMBER(Settings!$B$5)),Settings!$B$5<=0),"ERROR: Invalid LotStep",IF(OR(Settings!$B$4<1,Settings!$B$4>20),"ERROR: Invalid MaxLevels",IF(AND(Settings!$B$10<>"DOWN",Settings!$B$10<>"UP"),"ERROR: Invalid Direction",IF(OR(C6<0,E6<0,J6<0,AND(LEN(L6)>0,L6<0)),"ERROR: Negative input",IF(C6<E6,"ERROR: Big BUY must be >= Small SELL",IF(AND(LEN(L6)>0,L6>G6),"ERROR: ManualClose exceeds remaining Start position",IF(OR(N6<0,Q6<0,R6<0),"ERROR: Negative totals",IF(Q6>R6,"ERROR: Rounding broke protection balance",IF(S6>Settings!$B$8,"WARNING: Skew exceeds recommended limit","OK"))))))))))) | U6: =IF(LEFT(T6,5)="ERROR","Check input/risk","") | V6: =Settings!$B$2*C6/100 | W6: =IF(Settings!$B$9,FLOOR(V6,Settings!$B$5),V6) | X6: =Settings!$B$2*E6/100 | Y6: =IF(Settings!$B$9,CEILING(X6,Settings!$B$5),X6) | Z6: =Settings!$B$2*M6/100 | AA6: =IF(Settings!$B$17,MIN(Settings!$B$2*G6/100,IF(Settings!$B$9,CEILING(MAX(0,V6+Settings!$B$2*G6/100-X6-Settings!$B$2*J6/100),Settings!$B$5),MAX(0,V6+Settings!$B$2*G6/100-X6-Settings!$B$2*J6/100))),IF(Settings!$B$9,MROUND(Z6,Settings!$B$5),Z6)) | AB6: =IF(LEFT(T6,5)="ERROR","ERROR",IF(AND(Settings!$B$17,ABS(AA6-Z6)>1E-9),"FIXED",IF(ABS(S6)<=Settings!$B$7,"SAFE","WARNING"))) | AC6: =IF(AB6="FIXED","Close adjusted by SAFE mode",IF(AB6="SAFE","BUY/SELL balance preserved",IF(AB6="WARNING","Near protection boundary","Protection broken")))
A7: 5 | B7: =A7*Settings!$B$3 | C7: =IF(A7<=Settings!$B$4,IFERROR(XLOOKUP(A7,LevelRange,BigPercentRange),0),0) | D7: =W7 | E7: =IF(A7<=Settings!$B$4,IFERROR(XLOOKUP(A7,LevelRange,SmallPercentRange),0),0) | F7: =Y7 | G7: =N6 | H7: =G7+SUM($C$3:C7) | I7: =100+SUM($E$3:E7) | J7: =IF(A7<=Settings!$B$4,IFERROR(XLOOKUP(A7,LevelRange,TargetSkewRange),0),0) | K7: =MIN(G7,MAX(0,H7-I7+J7)) | L7: =IF(A7<=Settings!$B$4,IFERROR(XLOOKUP(A7,LevelRange,ManualCloseRange),""),"") | M7: =MIN(G7,AA7/Settings!$B$2*100) | N7: =G7-M7 | O7: =SUM($C$3:C7) | P7: =SUM($E$3:E7) | Q7: =N7+O7 | R7: =100+P7 | S7: =R7-Q7 | T7: =IF(Settings!$B$18=FALSE,"OK",IF(OR(NOT(ISNUMBER(Settings!$B$2)),Settings!$B$2<=0),"ERROR: Invalid StartLot",IF(OR(NOT(ISNUMBER(Settings!$B$5)),Settings!$B$5<=0),"ERROR: Invalid LotStep",IF(OR(Settings!$B$4<1,Settings!$B$4>20),"ERROR: Invalid MaxLevels",IF(AND(Settings!$B$10<>"DOWN",Settings!$B$10<>"UP"),"ERROR: Invalid Direction",IF(OR(C7<0,E7<0,J7<0,AND(LEN(L7)>0,L7<0)),"ERROR: Negative input",IF(C7<E7,"ERROR: Big BUY must be >= Small SELL",IF(AND(LEN(L7)>0,L7>G7),"ERROR: ManualClose exceeds remaining Start position",IF(OR(N7<0,Q7<0,R7<0),"ERROR: Negative totals",IF(Q7>R7,"ERROR: Rounding broke protection balance",IF(S7>Settings!$B$8,"WARNING: Skew exceeds recommended limit","OK"))))))))))) | U7: =IF(LEFT(T7,5)="ERROR","Check input/risk","") | V7: =Settings!$B$2*C7/100 | W7: =IF(Settings!$B$9,FLOOR(V7,Settings!$B$5),V7) | X7: =Settings!$B$2*E7/100 | Y7: =IF(Settings!$B$9,CEILING(X7,Settings!$B$5),X7) | Z7: =Settings!$B$2*M7/100 | AA7: =IF(Settings!$B$17,MIN(Settings!$B$2*G7/100,IF(Settings!$B$9,CEILING(MAX(0,V7+Settings!$B$2*G7/100-X7-Settings!$B$2*J7/100),Settings!$B$5),MAX(0,V7+Settings!$B$2*G7/100-X7-Settings!$B$2*J7/100))),IF(Settings!$B$9,MROUND(Z7,Settings!$B$5),Z7)) | AB7: =IF(LEFT(T7,5)="ERROR","ERROR",IF(AND(Settings!$B$17,ABS(AA7-Z7)>1E-9),"FIXED",IF(ABS(S7)<=Settings!$B$7,"SAFE","WARNING"))) | AC7: =IF(AB7="FIXED","Close adjusted by SAFE mode",IF(AB7="SAFE","BUY/SELL balance preserved",IF(AB7="WARNING","Near protection boundary","Protection broken")))
A8: 6 | B8: =A8*Settings!$B$3 | C8: =IF(A8<=Settings!$B$4,IFERROR(XLOOKUP(A8,LevelRange,BigPercentRange),0),0) | D8: =W8 | E8: =IF(A8<=Settings!$B$4,IFERROR(XLOOKUP(A8,LevelRange,SmallPercentRange),0),0) | F8: =Y8 | G8: =N7 | H8: =G8+SUM($C$3:C8) | I8: =100+SUM($E$3:E8) | J8: =IF(A8<=Settings!$B$4,IFERROR(XLOOKUP(A8,LevelRange,TargetSkewRange),0),0) | K8: =MIN(G8,MAX(0,H8-I8+J8)) | L8: =IF(A8<=Settings!$B$4,IFERROR(XLOOKUP(A8,LevelRange,ManualCloseRange),""),"") | M8: =MIN(G8,AA8/Settings!$B$2*100) | N8: =G8-M8 | O8: =SUM($C$3:C8) | P8: =SUM($E$3:E8) | Q8: =N8+O8 | R8: =100+P8 | S8: =R8-Q8 | T8: =IF(Settings!$B$18=FALSE,"OK",IF(OR(NOT(ISNUMBER(Settings!$B$2)),Settings!$B$2<=0),"ERROR: Invalid StartLot",IF(OR(NOT(ISNUMBER(Settings!$B$5)),Settings!$B$5<=0),"ERROR: Invalid LotStep",IF(OR(Settings!$B$4<1,Settings!$B$4>20),"ERROR: Invalid MaxLevels",IF(AND(Settings!$B$10<>"DOWN",Settings!$B$10<>"UP"),"ERROR: Invalid Direction",IF(OR(C8<0,E8<0,J8<0,AND(LEN(L8)>0,L8<0)),"ERROR: Negative input",IF(C8<E8,"ERROR: Big BUY must be >= Small SELL",IF(AND(LEN(L8)>0,L8>G8),"ERROR: ManualClose exceeds remaining Start position",IF(OR(N8<0,Q8<0,R8<0),"ERROR: Negative totals",IF(Q8>R8,"ERROR: Rounding broke protection balance",IF(S8>Settings!$B$8,"WARNING: Skew exceeds recommended limit","OK"))))))))))) | U8: =IF(LEFT(T8,5)="ERROR","Check input/risk","") | V8: =Settings!$B$2*C8/100 | W8: =IF(Settings!$B$9,FLOOR(V8,Settings!$B$5),V8) | X8: =Settings!$B$2*E8/100 | Y8: =IF(Settings!$B$9,CEILING(X8,Settings!$B$5),X8) | Z8: =Settings!$B$2*M8/100 | AA8: =IF(Settings!$B$17,MIN(Settings!$B$2*G8/100,IF(Settings!$B$9,CEILING(MAX(0,V8+Settings!$B$2*G8/100-X8-Settings!$B$2*J8/100),Settings!$B$5),MAX(0,V8+Settings!$B$2*G8/100-X8-Settings!$B$2*J8/100))),IF(Settings!$B$9,MROUND(Z8,Settings!$B$5),Z8)) | AB8: =IF(LEFT(T8,5)="ERROR","ERROR",IF(AND(Settings!$B$17,ABS(AA8-Z8)>1E-9),"FIXED",IF(ABS(S8)<=Settings!$B$7,"SAFE","WARNING"))) | AC8: =IF(AB8="FIXED","Close adjusted by SAFE mode",IF(AB8="SAFE","BUY/SELL balance preserved",IF(AB8="WARNING","Near protection boundary","Protection broken")))
A9: 7 | B9: =A9*Settings!$B$3 | C9: =IF(A9<=Settings!$B$4,IFERROR(XLOOKUP(A9,LevelRange,BigPercentRange),0),0) | D9: =W9 | E9: =IF(A9<=Settings!$B$4,IFERROR(XLOOKUP(A9,LevelRange,SmallPercentRange),0),0) | F9: =Y9 | G9: =N8 | H9: =G9+SUM($C$3:C9) | I9: =100+SUM($E$3:E9) | J9: =IF(A9<=Settings!$B$4,IFERROR(XLOOKUP(A9,LevelRange,TargetSkewRange),0),0) | K9: =MIN(G9,MAX(0,H9-I9+J9)) | L9: =IF(A9<=Settings!$B$4,IFERROR(XLOOKUP(A9,LevelRange,ManualCloseRange),""),"") | M9: =MIN(G9,AA9/Settings!$B$2*100) | N9: =G9-M9 | O9: =SUM($C$3:C9) | P9: =SUM($E$3:E9) | Q9: =N9+O9 | R9: =100+P9 | S9: =R9-Q9 | T9: =IF(Settings!$B$18=FALSE,"OK",IF(OR(NOT(ISNUMBER(Settings!$B$2)),Settings!$B$2<=0),"ERROR: Invalid StartLot",IF(OR(NOT(ISNUMBER(Settings!$B$5)),Settings!$B$5<=0),"ERROR: Invalid LotStep",IF(OR(Settings!$B$4<1,Settings!$B$4>20),"ERROR: Invalid MaxLevels",IF(AND(Settings!$B$10<>"DOWN",Settings!$B$10<>"UP"),"ERROR: Invalid Direction",IF(OR(C9<0,E9<0,J9<0,AND(LEN(L9)>0,L9<0)),"ERROR: Negative input",IF(C9<E9,"ERROR: Big BUY must be >= Small SELL",IF(AND(LEN(L9)>0,L9>G9),"ERROR: ManualClose exceeds remaining Start position",IF(OR(N9<0,Q9<0,R9<0),"ERROR: Negative totals",IF(Q9>R9,"ERROR: Rounding broke protection balance",IF(S9>Settings!$B$8,"WARNING: Skew exceeds recommended limit","OK"))))))))))) | U9: =IF(LEFT(T9,5)="ERROR","Check input/risk","") | V9: =Settings!$B$2*C9/100 | W9: =IF(Settings!$B$9,FLOOR(V9,Settings!$B$5),V9) | X9: =Settings!$B$2*E9/100 | Y9: =IF(Settings!$B$9,CEILING(X9,Settings!$B$5),X9) | Z9: =Settings!$B$2*M9/100 | AA9: =IF(Settings!$B$17,MIN(Settings!$B$2*G9/100,IF(Settings!$B$9,CEILING(MAX(0,V9+Settings!$B$2*G9/100-X9-Settings!$B$2*J9/100),Settings!$B$5),MAX(0,V9+Settings!$B$2*G9/100-X9-Settings!$B$2*J9/100))),IF(Settings!$B$9,MROUND(Z9,Settings!$B$5),Z9)) | AB9: =IF(LEFT(T9,5)="ERROR","ERROR",IF(AND(Settings!$B$17,ABS(AA9-Z9)>1E-9),"FIXED",IF(ABS(S9)<=Settings!$B$7,"SAFE","WARNING"))) | AC9: =IF(AB9="FIXED","Close adjusted by SAFE mode",IF(AB9="SAFE","BUY/SELL balance preserved",IF(AB9="WARNING","Near protection boundary","Protection broken")))
A10: 8 | B10: =A10*Settings!$B$3 | C10: =IF(A10<=Settings!$B$4,IFERROR(XLOOKUP(A10,LevelRange,BigPercentRange),0),0) | D10: =W10 | E10: =IF(A10<=Settings!$B$4,IFERROR(XLOOKUP(A10,LevelRange,SmallPercentRange),0),0) | F10: =Y10 | G10: =N9 | H10: =G10+SUM($C$3:C10) | I10: =100+SUM($E$3:E10) | J10: =IF(A10<=Settings!$B$4,IFERROR(XLOOKUP(A10,LevelRange,TargetSkewRange),0),0) | K10: =MIN(G10,MAX(0,H10-I10+J10)) | L10: =IF(A10<=Settings!$B$4,IFERROR(XLOOKUP(A10,LevelRange,ManualCloseRange),""),"") | M10: =MIN(G10,AA10/Settings!$B$2*100) | N10: =G10-M10 | O10: =SUM($C$3:C10) | P10: =SUM($E$3:E10) | Q10: =N10+O10 | R10: =100+P10 | S10: =R10-Q10 | T10: =IF(Settings!$B$18=FALSE,"OK",IF(OR(NOT(ISNUMBER(Settings!$B$2)),Settings!$B$2<=0),"ERROR: Invalid StartLot",IF(OR(NOT(ISNUMBER(Settings!$B$5)),Settings!$B$5<=0),"ERROR: Invalid LotStep",IF(OR(Settings!$B$4<1,Settings!$B$4>20),"ERROR: Invalid MaxLevels",IF(AND(Settings!$B$10<>"DOWN",Settings!$B$10<>"UP"),"ERROR: Invalid Direction",IF(OR(C10<0,E10<0,J10<0,AND(LEN(L10)>0,L10<0)),"ERROR: Negative input",IF(C10<E10,"ERROR: Big BUY must be >= Small SELL",IF(AND(LEN(L10)>0,L10>G10),"ERROR: ManualClose exceeds remaining Start position",IF(OR(N10<0,Q10<0,R10<0),"ERROR: Negative totals",IF(Q10>R10,"ERROR: Rounding broke protection balance",IF(S10>Settings!$B$8,"WARNING: Skew exceeds recommended limit","OK"))))))))))) | U10: =IF(LEFT(T10,5)="ERROR","Check input/risk","") | V10: =Settings!$B$2*C10/100 | W10: =IF(Settings!$B$9,FLOOR(V10,Settings!$B$5),V10) | X10: =Settings!$B$2*E10/100 | Y10: =IF(Settings!$B$9,CEILING(X10,Settings!$B$5),X10) | Z10: =Settings!$B$2*M10/100 | AA10: =IF(Settings!$B$17,MIN(Settings!$B$2*G10/100,IF(Settings!$B$9,CEILING(MAX(0,V10+Settings!$B$2*G10/100-X10-Settings!$B$2*J10/100),Settings!$B$5),MAX(0,V10+Settings!$B$2*G10/100-X10-Settings!$B$2*J10/100))),IF(Settings!$B$9,MROUND(Z10,Settings!$B$5),Z10)) | AB10: =IF(LEFT(T10,5)="ERROR","ERROR",IF(AND(Settings!$B$17,ABS(AA10-Z10)>1E-9),"FIXED",IF(ABS(S10)<=Settings!$B$7,"SAFE","WARNING"))) | AC10: =IF(AB10="FIXED","Close adjusted by SAFE mode",IF(AB10="SAFE","BUY/SELL balance preserved",IF(AB10="WARNING","Near protection boundary","Protection broken")))
A11: 9 | B11: =A11*Settings!$B$3 | C11: =IF(A11<=Settings!$B$4,IFERROR(XLOOKUP(A11,LevelRange,BigPercentRange),0),0) | D11: =W11 | E11: =IF(A11<=Settings!$B$4,IFERROR(XLOOKUP(A11,LevelRange,SmallPercentRange),0),0) | F11: =Y11 | G11: =N10 | H11: =G11+SUM($C$3:C11) | I11: =100+SUM($E$3:E11) | J11: =IF(A11<=Settings!$B$4,IFERROR(XLOOKUP(A11,LevelRange,TargetSkewRange),0),0) | K11: =MIN(G11,MAX(0,H11-I11+J11)) | L11: =IF(A11<=Settings!$B$4,IFERROR(XLOOKUP(A11,LevelRange,ManualCloseRange),""),"") | M11: =MIN(G11,AA11/Settings!$B$2*100) | N11: =G11-M11 | O11: =SUM($C$3:C11) | P11: =SUM($E$3:E11) | Q11: =N11+O11 | R11: =100+P11 | S11: =R11-Q11 | T11: =IF(Settings!$B$18=FALSE,"OK",IF(OR(NOT(ISNUMBER(Settings!$B$2)),Settings!$B$2<=0),"ERROR: Invalid StartLot",IF(OR(NOT(ISNUMBER(Settings!$B$5)),Settings!$B$5<=0),"ERROR: Invalid LotStep",IF(OR(Settings!$B$4<1,Settings!$B$4>20),"ERROR: Invalid MaxLevels",IF(AND(Settings!$B$10<>"DOWN",Settings!$B$10<>"UP"),"ERROR: Invalid Direction",IF(OR(C11<0,E11<0,J11<0,AND(LEN(L11)>0,L11<0)),"ERROR: Negative input",IF(C11<E11,"ERROR: Big BUY must be >= Small SELL",IF(AND(LEN(L11)>0,L11>G11),"ERROR: ManualClose exceeds remaining Start position",IF(OR(N11<0,Q11<0,R11<0),"ERROR: Negative totals",IF(Q11>R11,"ERROR: Rounding broke protection balance",IF(S11>Settings!$B$8,"WARNING: Skew exceeds recommended limit","OK"))))))))))) | U11: =IF(LEFT(T11,5)="ERROR","Check input/risk","") | V11: =Settings!$B$2*C11/100 | W11: =IF(Settings!$B$9,FLOOR(V11,Settings!$B$5),V11) | X11: =Settings!$B$2*E11/100 | Y11: =IF(Settings!$B$9,CEILING(X11,Settings!$B$5),X11) | Z11: =Settings!$B$2*M11/100 | AA11: =IF(Settings!$B$17,MIN(Settings!$B$2*G11/100,IF(Settings!$B$9,CEILING(MAX(0,V11+Settings!$B$2*G11/100-X11-Settings!$B$2*J11/100),Settings!$B$5),MAX(0,V11+Settings!$B$2*G11/100-X11-Settings!$B$2*J11/100))),IF(Settings!$B$9,MROUND(Z11,Settings!$B$5),Z11)) | AB11: =IF(LEFT(T11,5)="ERROR","ERROR",IF(AND(Settings!$B$17,ABS(AA11-Z11)>1E-9),"FIXED",IF(ABS(S11)<=Settings!$B$7,"SAFE","WARNING"))) | AC11: =IF(AB11="FIXED","Close adjusted by SAFE mode",IF(AB11="SAFE","BUY/SELL balance preserved",IF(AB11="WARNING","Near protection boundary","Protection broken")))
A12: 10 | B12: =A12*Settings!$B$3 | C12: =IF(A12<=Settings!$B$4,IFERROR(XLOOKUP(A12,LevelRange,BigPercentRange),0),0) | D12: =W12 | E12: =IF(A12<=Settings!$B$4,IFERROR(XLOOKUP(A12,LevelRange,SmallPercentRange),0),0) | F12: =Y12 | G12: =N11 | H12: =G12+SUM($C$3:C12) | I12: =100+SUM($E$3:E12) | J12: =IF(A12<=Settings!$B$4,IFERROR(XLOOKUP(A12,LevelRange,TargetSkewRange),0),0) | K12: =MIN(G12,MAX(0,H12-I12+J12)) | L12: =IF(A12<=Settings!$B$4,IFERROR(XLOOKUP(A12,LevelRange,ManualCloseRange),""),"") | M12: =MIN(G12,AA12/Settings!$B$2*100) | N12: =G12-M12 | O12: =SUM($C$3:C12) | P12: =SUM($E$3:E12) | Q12: =N12+O12 | R12: =100+P12 | S12: =R12-Q12 | T12: =IF(Settings!$B$18=FALSE,"OK",IF(OR(NOT(ISNUMBER(Settings!$B$2)),Settings!$B$2<=0),"ERROR: Invalid StartLot",IF(OR(NOT(ISNUMBER(Settings!$B$5)),Settings!$B$5<=0),"ERROR: Invalid LotStep",IF(OR(Settings!$B$4<1,Settings!$B$4>20),"ERROR: Invalid MaxLevels",IF(AND(Settings!$B$10<>"DOWN",Settings!$B$10<>"UP"),"ERROR: Invalid Direction",IF(OR(C12<0,E12<0,J12<0,AND(LEN(L12)>0,L12<0)),"ERROR: Negative input",IF(C12<E12,"ERROR: Big BUY must be >= Small SELL",IF(AND(LEN(L12)>0,L12>G12),"ERROR: ManualClose exceeds remaining Start position",IF(OR(N12<0,Q12<0,R12<0),"ERROR: Negative totals",IF(Q12>R12,"ERROR: Rounding broke protection balance",IF(S12>Settings!$B$8,"WARNING: Skew exceeds recommended limit","OK"))))))))))) | U12: =IF(LEFT(T12,5)="ERROR","Check input/risk","") | V12: =Settings!$B$2*C12/100 | W12: =IF(Settings!$B$9,FLOOR(V12,Settings!$B$5),V12) | X12: =Settings!$B$2*E12/100 | Y12: =IF(Settings!$B$9,CEILING(X12,Settings!$B$5),X12) | Z12: =Settings!$B$2*M12/100 | AA12: =IF(Settings!$B$17,MIN(Settings!$B$2*G12/100,IF(Settings!$B$9,CEILING(MAX(0,V12+Settings!$B$2*G12/100-X12-Settings!$B$2*J12/100),Settings!$B$5),MAX(0,V12+Settings!$B$2*G12/100-X12-Settings!$B$2*J12/100))),IF(Settings!$B$9,MROUND(Z12,Settings!$B$5),Z12)) | AB12: =IF(LEFT(T12,5)="ERROR","ERROR",IF(AND(Settings!$B$17,ABS(AA12-Z12)>1E-9),"FIXED",IF(ABS(S12)<=Settings!$B$7,"SAFE","WARNING"))) | AC12: =IF(AB12="FIXED","Close adjusted by SAFE mode",IF(AB12="SAFE","BUY/SELL balance preserved",IF(AB12="WARNING","Near protection boundary","Protection broken")))
A13: 11 | B13: =A13*Settings!$B$3 | C13: =IF(A13<=Settings!$B$4,IFERROR(XLOOKUP(A13,LevelRange,BigPercentRange),0),0) | D13: =W13 | E13: =IF(A13<=Settings!$B$4,IFERROR(XLOOKUP(A13,LevelRange,SmallPercentRange),0),0) | F13: =Y13 | G13: =N12 | H13: =G13+SUM($C$3:C13) | I13: =100+SUM($E$3:E13) | J13: =IF(A13<=Settings!$B$4,IFERROR(XLOOKUP(A13,LevelRange,TargetSkewRange),0),0) | K13: =MIN(G13,MAX(0,H13-I13+J13)) | L13: =IF(A13<=Settings!$B$4,IFERROR(XLOOKUP(A13,LevelRange,ManualCloseRange),""),"") | M13: =MIN(G13,AA13/Settings!$B$2*100) | N13: =G13-M13 | O13: =SUM($C$3:C13) | P13: =SUM($E$3:E13) | Q13: =N13+O13 | R13: =100+P13 | S13: =R13-Q13 | T13: =IF(Settings!$B$18=FALSE,"OK",IF(OR(NOT(ISNUMBER(Settings!$B$2)),Settings!$B$2<=0),"ERROR: Invalid StartLot",IF(OR(NOT(ISNUMBER(Settings!$B$5)),Settings!$B$5<=0),"ERROR: Invalid LotStep",IF(OR(Settings!$B$4<1,Settings!$B$4>20),"ERROR: Invalid MaxLevels",IF(AND(Settings!$B$10<>"DOWN",Settings!$B$10<>"UP"),"ERROR: Invalid Direction",IF(OR(C13<0,E13<0,J13<0,AND(LEN(L13)>0,L13<0)),"ERROR: Negative input",IF(C13<E13,"ERROR: Big BUY must be >= Small SELL",IF(AND(LEN(L13)>0,L13>G13),"ERROR: ManualClose exceeds remaining Start position",IF(OR(N13<0,Q13<0,R13<0),"ERROR: Negative totals",IF(Q13>R13,"ERROR: Rounding broke protection balance",IF(S13>Settings!$B$8,"WARNING: Skew exceeds recommended limit","OK"))))))))))) | U13: =IF(LEFT(T13,5)="ERROR","Check input/risk","") | V13: =Settings!$B$2*C13/100 | W13: =IF(Settings!$B$9,FLOOR(V13,Settings!$B$5),V13) | X13: =Settings!$B$2*E13/100 | Y13: =IF(Settings!$B$9,CEILING(X13,Settings!$B$5),X13) | Z13: =Settings!$B$2*M13/100 | AA13: =IF(Settings!$B$17,MIN(Settings!$B$2*G13/100,IF(Settings!$B$9,CEILING(MAX(0,V13+Settings!$B$2*G13/100-X13-Settings!$B$2*J13/100),Settings!$B$5),MAX(0,V13+Settings!$B$2*G13/100-X13-Settings!$B$2*J13/100))),IF(Settings!$B$9,MROUND(Z13,Settings!$B$5),Z13)) | AB13: =IF(LEFT(T13,5)="ERROR","ERROR",IF(AND(Settings!$B$17,ABS(AA13-Z13)>1E-9),"FIXED",IF(ABS(S13)<=Settings!$B$7,"SAFE","WARNING"))) | AC13: =IF(AB13="FIXED","Close adjusted by SAFE mode",IF(AB13="SAFE","BUY/SELL balance preserved",IF(AB13="WARNING","Near protection boundary","Protection broken")))
A14: 12 | B14: =A14*Settings!$B$3 | C14: =IF(A14<=Settings!$B$4,IFERROR(XLOOKUP(A14,LevelRange,BigPercentRange),0),0) | D14: =W14 | E14: =IF(A14<=Settings!$B$4,IFERROR(XLOOKUP(A14,LevelRange,SmallPercentRange),0),0) | F14: =Y14 | G14: =N13 | H14: =G14+SUM($C$3:C14) | I14: =100+SUM($E$3:E14) | J14: =IF(A14<=Settings!$B$4,IFERROR(XLOOKUP(A14,LevelRange,TargetSkewRange),0),0) | K14: =MIN(G14,MAX(0,H14-I14+J14)) | L14: =IF(A14<=Settings!$B$4,IFERROR(XLOOKUP(A14,LevelRange,ManualCloseRange),""),"") | M14: =MIN(G14,AA14/Settings!$B$2*100) | N14: =G14-M14 | O14: =SUM($C$3:C14) | P14: =SUM($E$3:E14) | Q14: =N14+O14 | R14: =100+P14 | S14: =R14-Q14 | T14: =IF(Settings!$B$18=FALSE,"OK",IF(OR(NOT(ISNUMBER(Settings!$B$2)),Settings!$B$2<=0),"ERROR: Invalid StartLot",IF(OR(NOT(ISNUMBER(Settings!$B$5)),Settings!$B$5<=0),"ERROR: Invalid LotStep",IF(OR(Settings!$B$4<1,Settings!$B$4>20),"ERROR: Invalid MaxLevels",IF(AND(Settings!$B$10<>"DOWN",Settings!$B$10<>"UP"),"ERROR: Invalid Direction",IF(OR(C14<0,E14<0,J14<0,AND(LEN(L14)>0,L14<0)),"ERROR: Negative input",IF(C14<E14,"ERROR: Big BUY must be >= Small SELL",IF(AND(LEN(L14)>0,L14>G14),"ERROR: ManualClose exceeds remaining Start position",IF(OR(N14<0,Q14<0,R14<0),"ERROR: Negative totals",IF(Q14>R14,"ERROR: Rounding broke protection balance",IF(S14>Settings!$B$8,"WARNING: Skew exceeds recommended limit","OK"))))))))))) | U14: =IF(LEFT(T14,5)="ERROR","Check input/risk","") | V14: =Settings!$B$2*C14/100 | W14: =IF(Settings!$B$9,FLOOR(V14,Settings!$B$5),V14) | X14: =Settings!$B$2*E14/100 | Y14: =IF(Settings!$B$9,CEILING(X14,Settings!$B$5),X14) | Z14: =Settings!$B$2*M14/100 | AA14: =IF(Settings!$B$17,MIN(Settings!$B$2*G14/100,IF(Settings!$B$9,CEILING(MAX(0,V14+Settings!$B$2*G14/100-X14-Settings!$B$2*J14/100),Settings!$B$5),MAX(0,V14+Settings!$B$2*G14/100-X14-Settings!$B$2*J14/100))),IF(Settings!$B$9,MROUND(Z14,Settings!$B$5),Z14)) | AB14: =IF(LEFT(T14,5)="ERROR","ERROR",IF(AND(Settings!$B$17,ABS(AA14-Z14)>1E-9),"FIXED",IF(ABS(S14)<=Settings!$B$7,"SAFE","WARNING"))) | AC14: =IF(AB14="FIXED","Close adjusted by SAFE mode",IF(AB14="SAFE","BUY/SELL balance preserved",IF(AB14="WARNING","Near protection boundary","Protection broken")))
A15: 13 | B15: =A15*Settings!$B$3 | C15: =IF(A15<=Settings!$B$4,IFERROR(XLOOKUP(A15,LevelRange,BigPercentRange),0),0) | D15: =W15 | E15: =IF(A15<=Settings!$B$4,IFERROR(XLOOKUP(A15,LevelRange,SmallPercentRange),0),0) | F15: =Y15 | G15: =N14 | H15: =G15+SUM($C$3:C15) | I15: =100+SUM($E$3:E15) | J15: =IF(A15<=Settings!$B$4,IFERROR(XLOOKUP(A15,LevelRange,TargetSkewRange),0),0) | K15: =MIN(G15,MAX(0,H15-I15+J15)) | L15: =IF(A15<=Settings!$B$4,IFERROR(XLOOKUP(A15,LevelRange,ManualCloseRange),""),"") | M15: =MIN(G15,AA15/Settings!$B$2*100) | N15: =G15-M15 | O15: =SUM($C$3:C15) | P15: =SUM($E$3:E15) | Q15: =N15+O15 | R15: =100+P15 | S15: =R15-Q15 | T15: =IF(Settings!$B$18=FALSE,"OK",IF(OR(NOT(ISNUMBER(Settings!$B$2)),Settings!$B$2<=0),"ERROR: Invalid StartLot",IF(OR(NOT(ISNUMBER(Settings!$B$5)),Settings!$B$5<=0),"ERROR: Invalid LotStep",IF(OR(Settings!$B$4<1,Settings!$B$4>20),"ERROR: Invalid MaxLevels",IF(AND(Settings!$B$10<>"DOWN",Settings!$B$10<>"UP"),"ERROR: Invalid Direction",IF(OR(C15<0,E15<0,J15<0,AND(LEN(L15)>0,L15<0)),"ERROR: Negative input",IF(C15<E15,"ERROR: Big BUY must be >= Small SELL",IF(AND(LEN(L15)>0,L15>G15),"ERROR: ManualClose exceeds remaining Start position",IF(OR(N15<0,Q15<0,R15<0),"ERROR: Negative totals",IF(Q15>R15,"ERROR: Rounding broke protection balance",IF(S15>Settings!$B$8,"WARNING: Skew exceeds recommended limit","OK"))))))))))) | U15: =IF(LEFT(T15,5)="ERROR","Check input/risk","") | V15: =Settings!$B$2*C15/100 | W15: =IF(Settings!$B$9,FLOOR(V15,Settings!$B$5),V15) | X15: =Settings!$B$2*E15/100 | Y15: =IF(Settings!$B$9,CEILING(X15,Settings!$B$5),X15) | Z15: =Settings!$B$2*M15/100 | AA15: =IF(Settings!$B$17,MIN(Settings!$B$2*G15/100,IF(Settings!$B$9,CEILING(MAX(0,V15+Settings!$B$2*G15/100-X15-Settings!$B$2*J15/100),Settings!$B$5),MAX(0,V15+Settings!$B$2*G15/100-X15-Settings!$B$2*J15/100))),IF(Settings!$B$9,MROUND(Z15,Settings!$B$5),Z15)) | AB15: =IF(LEFT(T15,5)="ERROR","ERROR",IF(AND(Settings!$B$17,ABS(AA15-Z15)>1E-9),"FIXED",IF(ABS(S15)<=Settings!$B$7,"SAFE","WARNING"))) | AC15: =IF(AB15="FIXED","Close adjusted by SAFE mode",IF(AB15="SAFE","BUY/SELL balance preserved",IF(AB15="WARNING","Near protection boundary","Protection broken")))
... A41: 39 | B41: =A41*Settings!$B$3 | C41: =IF(A41<=Settings!$B$4,IFERROR(XLOOKUP(A41,LevelRange,BigPercentRange),0),0) | D41: =W41 | E41: =IF(A41<=Settings!$B$4,IFERROR(XLOOKUP(A41,LevelRange,SmallPercentRange),0),0) | F41: =Y41 | G41: =N40 | H41: =G41+SUM($C$3:C41) | I41: =100+SUM($E$3:E41) | J41: =IF(A41<=Settings!$B$4,IFERROR(XLOOKUP(A41,LevelRange,TargetSkewRange),0),0) | K41: =MIN(G41,MAX(0,H41-I41+J41)) | L41: =IF(A41<=Settings!$B$4,IFERROR(XLOOKUP(A41,LevelRange,ManualCloseRange),""),"") | M41: =MIN(G41,AA41/Settings!$B$2*100) | N41: =G41-M41 | O41: =SUM($C$3:C41) | P41: =SUM($E$3:E41) | Q41: =N41+O41 | R41: =100+P41 | S41: =R41-Q41 | T41: =IF(Settings!$B$18=FALSE,"OK",IF(OR(NOT(ISNUMBER(Settings!$B$2)),Settings!$B$2<=0),"ERROR: Invalid StartLot",IF(OR(NOT(ISNUMBER(Settings!$B$5)),Settings!$B$5<=0),"ERROR: Invalid LotStep",IF(OR(Settings!$B$4<1,Settings!$B$4>20),"ERROR: Invalid MaxLevels",IF(AND(Settings!$B$10<>"DOWN",Settings!$B$10<>"UP"),"ERROR: Invalid Direction",IF(OR(C41<0,E41<0,J41<0,AND(LEN(L41)>0,L41<0)),"ERROR: Negative input",IF(C41<E41,"ERROR: Big BUY must be >= Small SELL",IF(AND(LEN(L41)>0,L41>G41),"ERROR: ManualClose exceeds remaining Start position",IF(OR(N41<0,Q41<0,R41<0),"ERROR: Negative totals",IF(Q41>R41,"ERROR: Rounding broke protection balance",IF(S41>Settings!$B$8,"WARNING: Skew exceeds recommended limit","OK"))))))))))) | U41: =IF(LEFT(T41,5)="ERROR","Check input/risk","") | V41: =Settings!$B$2*C41/100 | W41: =IF(Settings!$B$9,FLOOR(V41,Settings!$B$5),V41) | X41: =Settings!$B$2*E41/100 | Y41: =IF(Settings!$B$9,CEILING(X41,Settings!$B$5),X41) | Z41: =Settings!$B$2*M41/100 | AA41: =IF(Settings!$B$17,MIN(Settings!$B$2*G41/100,IF(Settings!$B$9,CEILING(MAX(0,V41+Settings!$B$2*G41/100-X41-Settings!$B$2*J41/100),Settings!$B$5),MAX(0,V41+Settings!$B$2*G41/100-X41-Settings!$B$2*J41/100))),IF(Settings!$B$9,MROUND(Z41,Settings!$B$5),Z41)) | AB41: =IF(LEFT(T41,5)="ERROR","ERROR",IF(AND(Settings!$B$17,ABS(AA41-Z41)>1E-9),"FIXED",IF(ABS(S41)<=Settings!$B$7,"SAFE","WARNING"))) | AC41: =IF(AB41="FIXED","Close adjusted by SAFE mode",IF(AB41="SAFE","BUY/SELL balance preserved",IF(AB41="WARNING","Near protection boundary","Protection broken")))

Sheet UpTrend
A1: Level | B1: PriceStep | C1: Big % | D1: Big Lot | E1: Small % | F1: Small Lot | G1: Start Before % | H1: Before Close % | I1: Opposite After Add % | J1: Target Skew % | K1: Auto Close % | L1: Manual Close % | M1: Final Close % | N1: Start After % | O1: Sum Big % | P1: Sum Small % | Q1: Total Main % | R1: Total Opposite % | S1: Skew % | T1: Status | U1: Comment | V1: Big Raw Lot | W1: Big Rounded | X1: Small Raw Lot | Y1: Small Rounded | Z1: Close Raw Lot | AA1: Close Rounded | AB1: Safe Rounding Status | AC1: Rounding Comment
A2: 0 | B2: 0 | C2: 0 | D2: =W2 | E2: 0 | F2: =Y2 | G2: 100 | H2: 100 | I2: 100 | J2: 0 | K2: 0 | M2: 0 | N2: 100 | O2: 0 | P2: 0 | Q2: =N2+O2 | R2: =100+P2 | S2: =R2-Q2 | T2: =IF(Settings!$B$18=FALSE,"OK",IF(OR(NOT(ISNUMBER(Settings!$B$2)),Settings!$B$2<=0),"ERROR: Invalid StartLot",IF(OR(NOT(ISNUMBER(Settings!$B$5)),Settings!$B$5<=0),"ERROR: Invalid LotStep",IF(OR(Settings!$B$4<1,Settings!$B$4>20),"ERROR: Invalid MaxLevels",IF(AND(Settings!$B$10<>"DOWN",Settings!$B$10<>"UP"),"ERROR: Invalid Direction",IF(OR(C2<0,E2<0,J2<0,AND(LEN(L2)>0,L2<0)),"ERROR: Negative input",IF(C2<E2,"ERROR: Big SELL must be >= Small BUY",IF(AND(LEN(L2)>0,L2>G2),"ERROR: ManualClose exceeds remaining Start position",IF(OR(N2<0,Q2<0,R2<0),"ERROR: Negative totals",IF(Q2>R2,"ERROR: Rounding broke protection balance",IF(S2>Settings!$B$8,"WARNING: Skew exceeds recommended limit","OK"))))))))))) | U2: =IF(LEFT(T2,5)="ERROR","Check input/risk","") | V2: 0 | W2: 0 | X2: 0 | Y2: 0 | Z2: 0 | AA2: 0 | AB2: =IF(LEFT(T2,5)="ERROR","ERROR",IF(AND(Settings!$B$17,ABS(AA2-Z2)>1E-9),"FIXED",IF(ABS(S2)<=Settings!$B$7,"SAFE","WARNING"))) | AC2: =IF(AB2="FIXED","Close adjusted by SAFE mode",IF(AB2="SAFE","BUY/SELL balance preserved",IF(AB2="WARNING","Near protection boundary","Protection broken")))
A3: 1 | B3: =A3*Settings!$B$3 | C3: =IF(A3<=Settings!$B$4,IFERROR(XLOOKUP(A3,LevelRange,BigPercentRange),0),0) | D3: =W3 | E3: =IF(A3<=Settings!$B$4,IFERROR(XLOOKUP(A3,LevelRange,SmallPercentRange),0),0) | F3: =Y3 | G3: 100 | H3: =G3+SUM($C$3:C3) | I3: =100+SUM($E$3:E3) | J3: =IF(A3<=Settings!$B$4,IFERROR(XLOOKUP(A3,LevelRange,TargetSkewRange),0),0) | K3: =MIN(G3,MAX(0,H3-I3+J3)) | L3: =IF(A3<=Settings!$B$4,IFERROR(XLOOKUP(A3,LevelRange,ManualCloseRange),""),"") | M3: =MIN(G3,AA3/Settings!$B$2*100) | N3: =G3-M3 | O3: =SUM($C$3:C3) | P3: =SUM($E$3:E3) | Q3: =N3+O3 | R3: =100+P3 | S3: =R3-Q3 | T3: =IF(Settings!$B$18=FALSE,"OK",IF(OR(NOT(ISNUMBER(Settings!$B$2)),Settings!$B$2<=0),"ERROR: Invalid StartLot",IF(OR(NOT(ISNUMBER(Settings!$B$5)),Settings!$B$5<=0),"ERROR: Invalid LotStep",IF(OR(Settings!$B$4<1,Settings!$B$4>20),"ERROR: Invalid MaxLevels",IF(AND(Settings!$B$10<>"DOWN",Settings!$B$10<>"UP"),"ERROR: Invalid Direction",IF(OR(C3<0,E3<0,J3<0,AND(LEN(L3)>0,L3<0)),"ERROR: Negative input",IF(C3<E3,"ERROR: Big SELL must be >= Small BUY",IF(AND(LEN(L3)>0,L3>G3),"ERROR: ManualClose exceeds remaining Start position",IF(OR(N3<0,Q3<0,R3<0),"ERROR: Negative totals",IF(Q3>R3,"ERROR: Rounding broke protection balance",IF(S3>Settings!$B$8,"WARNING: Skew exceeds recommended limit","OK"))))))))))) | U3: =IF(LEFT(T3,5)="ERROR","Check input/risk","") | V3: =Settings!$B$2*C3/100 | W3: =IF(Settings!$B$9,FLOOR(V3,Settings!$B$5),V3) | X3: =Settings!$B$2*E3/100 | Y3: =IF(Settings!$B$9,CEILING(X3,Settings!$B$5),X3) | Z3: =Settings!$B$2*M3/100 | AA3: =IF(Settings!$B$17,MIN(Settings!$B$2*G3/100,IF(Settings!$B$9,CEILING(MAX(0,V3+Settings!$B$2*G3/100-X3-Settings!$B$2*J3/100),Settings!$B$5),MAX(0,V3+Settings!$B$2*G3/100-X3-Settings!$B$2*J3/100))),IF(Settings!$B$9,MROUND(Z3,Settings!$B$5),Z3)) | AB3: =IF(LEFT(T3,5)="ERROR","ERROR",IF(AND(Settings!$B$17,ABS(AA3-Z3)>1E-9),"FIXED",IF(ABS(S3)<=Settings!$B$7,"SAFE","WARNING"))) | AC3: =IF(AB3="FIXED","Close adjusted by SAFE mode",IF(AB3="SAFE","BUY/SELL balance preserved",IF(AB3="WARNING","Near protection boundary","Protection broken")))
A4: 2 | B4: =A4*Settings!$B$3 | C4: =IF(A4<=Settings!$B$4,IFERROR(XLOOKUP(A4,LevelRange,BigPercentRange),0),0) | D4: =W4 | E4: =IF(A4<=Settings!$B$4,IFERROR(XLOOKUP(A4,LevelRange,SmallPercentRange),0),0) | F4: =Y4 | G4: =N3 | H4: =G4+SUM($C$3:C4) | I4: =100+SUM($E$3:E4) | J4: =IF(A4<=Settings!$B$4,IFERROR(XLOOKUP(A4,LevelRange,TargetSkewRange),0),0) | K4: =MIN(G4,MAX(0,H4-I4+J4)) | L4: =IF(A4<=Settings!$B$4,IFERROR(XLOOKUP(A4,LevelRange,ManualCloseRange),""),"") | M4: =MIN(G4,AA4/Settings!$B$2*100) | N4: =G4-M4 | O4: =SUM($C$3:C4) | P4: =SUM($E$3:E4) | Q4: =N4+O4 | R4: =100+P4 | S4: =R4-Q4 | T4: =IF(Settings!$B$18=FALSE,"OK",IF(OR(NOT(ISNUMBER(Settings!$B$2)),Settings!$B$2<=0),"ERROR: Invalid StartLot",IF(OR(NOT(ISNUMBER(Settings!$B$5)),Settings!$B$5<=0),"ERROR: Invalid LotStep",IF(OR(Settings!$B$4<1,Settings!$B$4>20),"ERROR: Invalid MaxLevels",IF(AND(Settings!$B$10<>"DOWN",Settings!$B$10<>"UP"),"ERROR: Invalid Direction",IF(OR(C4<0,E4<0,J4<0,AND(LEN(L4)>0,L4<0)),"ERROR: Negative input",IF(C4<E4,"ERROR: Big SELL must be >= Small BUY",IF(AND(LEN(L4)>0,L4>G4),"ERROR: ManualClose exceeds remaining Start position",IF(OR(N4<0,Q4<0,R4<0),"ERROR: Negative totals",IF(Q4>R4,"ERROR: Rounding broke protection balance",IF(S4>Settings!$B$8,"WARNING: Skew exceeds recommended limit","OK"))))))))))) | U4: =IF(LEFT(T4,5)="ERROR","Check input/risk","") | V4: =Settings!$B$2*C4/100 | W4: =IF(Settings!$B$9,FLOOR(V4,Settings!$B$5),V4) | X4: =Settings!$B$2*E4/100 | Y4: =IF(Settings!$B$9,CEILING(X4,Settings!$B$5),X4) | Z4: =Settings!$B$2*M4/100 | AA4: =IF(Settings!$B$17,MIN(Settings!$B$2*G4/100,IF(Settings!$B$9,CEILING(MAX(0,V4+Settings!$B$2*G4/100-X4-Settings!$B$2*J4/100),Settings!$B$5),MAX(0,V4+Settings!$B$2*G4/100-X4-Settings!$B$2*J4/100))),IF(Settings!$B$9,MROUND(Z4,Settings!$B$5),Z4)) | AB4: =IF(LEFT(T4,5)="ERROR","ERROR",IF(AND(Settings!$B$17,ABS(AA4-Z4)>1E-9),"FIXED",IF(ABS(S4)<=Settings!$B$7,"SAFE","WARNING"))) | AC4: =IF(AB4="FIXED","Close adjusted by SAFE mode",IF(AB4="SAFE","BUY/SELL balance preserved",IF(AB4="WARNING","Near protection boundary","Protection broken")))
A5: 3 | B5: =A5*Settings!$B$3 | C5: =IF(A5<=Settings!$B$4,IFERROR(XLOOKUP(A5,LevelRange,BigPercentRange),0),0) | D5: =W5 | E5: =IF(A5<=Settings!$B$4,IFERROR(XLOOKUP(A5,LevelRange,SmallPercentRange),0),0) | F5: =Y5 | G5: =N4 | H5: =G5+SUM($C$3:C5) | I5: =100+SUM($E$3:E5) | J5: =IF(A5<=Settings!$B$4,IFERROR(XLOOKUP(A5,LevelRange,TargetSkewRange),0),0) | K5: =MIN(G5,MAX(0,H5-I5+J5)) | L5: =IF(A5<=Settings!$B$4,IFERROR(XLOOKUP(A5,LevelRange,ManualCloseRange),""),"") | M5: =MIN(G5,AA5/Settings!$B$2*100) | N5: =G5-M5 | O5: =SUM($C$3:C5) | P5: =SUM($E$3:E5) | Q5: =N5+O5 | R5: =100+P5 | S5: =R5-Q5 | T5: =IF(Settings!$B$18=FALSE,"OK",IF(OR(NOT(ISNUMBER(Settings!$B$2)),Settings!$B$2<=0),"ERROR: Invalid StartLot",IF(OR(NOT(ISNUMBER(Settings!$B$5)),Settings!$B$5<=0),"ERROR: Invalid LotStep",IF(OR(Settings!$B$4<1,Settings!$B$4>20),"ERROR: Invalid MaxLevels",IF(AND(Settings!$B$10<>"DOWN",Settings!$B$10<>"UP"),"ERROR: Invalid Direction",IF(OR(C5<0,E5<0,J5<0,AND(LEN(L5)>0,L5<0)),"ERROR: Negative input",IF(C5<E5,"ERROR: Big SELL must be >= Small BUY",IF(AND(LEN(L5)>0,L5>G5),"ERROR: ManualClose exceeds remaining Start position",IF(OR(N5<0,Q5<0,R5<0),"ERROR: Negative totals",IF(Q5>R5,"ERROR: Rounding broke protection balance",IF(S5>Settings!$B$8,"WARNING: Skew exceeds recommended limit","OK"))))))))))) | U5: =IF(LEFT(T5,5)="ERROR","Check input/risk","") | V5: =Settings!$B$2*C5/100 | W5: =IF(Settings!$B$9,FLOOR(V5,Settings!$B$5),V5) | X5: =Settings!$B$2*E5/100 | Y5: =IF(Settings!$B$9,CEILING(X5,Settings!$B$5),X5) | Z5: =Settings!$B$2*M5/100 | AA5: =IF(Settings!$B$17,MIN(Settings!$B$2*G5/100,IF(Settings!$B$9,CEILING(MAX(0,V5+Settings!$B$2*G5/100-X5-Settings!$B$2*J5/100),Settings!$B$5),MAX(0,V5+Settings!$B$2*G5/100-X5-Settings!$B$2*J5/100))),IF(Settings!$B$9,MROUND(Z5,Settings!$B$5),Z5)) | AB5: =IF(LEFT(T5,5)="ERROR","ERROR",IF(AND(Settings!$B$17,ABS(AA5-Z5)>1E-9),"FIXED",IF(ABS(S5)<=Settings!$B$7,"SAFE","WARNING"))) | AC5: =IF(AB5="FIXED","Close adjusted by SAFE mode",IF(AB5="SAFE","BUY/SELL balance preserved",IF(AB5="WARNING","Near protection boundary","Protection broken")))
A6: 4 | B6: =A6*Settings!$B$3 | C6: =IF(A6<=Settings!$B$4,IFERROR(XLOOKUP(A6,LevelRange,BigPercentRange),0),0) | D6: =W6 | E6: =IF(A6<=Settings!$B$4,IFERROR(XLOOKUP(A6,LevelRange,SmallPercentRange),0),0) | F6: =Y6 | G6: =N5 | H6: =G6+SUM($C$3:C6) | I6: =100+SUM($E$3:E6) | J6: =IF(A6<=Settings!$B$4,IFERROR(XLOOKUP(A6,LevelRange,TargetSkewRange),0),0) | K6: =MIN(G6,MAX(0,H6-I6+J6)) | L6: =IF(A6<=Settings!$B$4,IFERROR(XLOOKUP(A6,LevelRange,ManualCloseRange),""),"") | M6: =MIN(G6,AA6/Settings!$B$2*100) | N6: =G6-M6 | O6: =SUM($C$3:C6) | P6: =SUM($E$3:E6) | Q6: =N6+O6 | R6: =100+P6 | S6: =R6-Q6 | T6: =IF(Settings!$B$18=FALSE,"OK",IF(OR(NOT(ISNUMBER(Settings!$B$2)),Settings!$B$2<=0),"ERROR: Invalid StartLot",IF(OR(NOT(ISNUMBER(Settings!$B$5)),Settings!$B$5<=0),"ERROR: Invalid LotStep",IF(OR(Settings!$B$4<1,Settings!$B$4>20),"ERROR: Invalid MaxLevels",IF(AND(Settings!$B$10<>"DOWN",Settings!$B$10<>"UP"),"ERROR: Invalid Direction",IF(OR(C6<0,E6<0,J6<0,AND(LEN(L6)>0,L6<0)),"ERROR: Negative input",IF(C6<E6,"ERROR: Big SELL must be >= Small BUY",IF(AND(LEN(L6)>0,L6>G6),"ERROR: ManualClose exceeds remaining Start position",IF(OR(N6<0,Q6<0,R6<0),"ERROR: Negative totals",IF(Q6>R6,"ERROR: Rounding broke protection balance",IF(S6>Settings!$B$8,"WARNING: Skew exceeds recommended limit","OK"))))))))))) | U6: =IF(LEFT(T6,5)="ERROR","Check input/risk","") | V6: =Settings!$B$2*C6/100 | W6: =IF(Settings!$B$9,FLOOR(V6,Settings!$B$5),V6) | X6: =Settings!$B$2*E6/100 | Y6: =IF(Settings!$B$9,CEILING(X6,Settings!$B$5),X6) | Z6: =Settings!$B$2*M6/100 | AA6: =IF(Settings!$B$17,MIN(Settings!$B$2*G6/100,IF(Settings!$B$9,CEILING(MAX(0,V6+Settings!$B$2*G6/100-X6-Settings!$B$2*J6/100),Settings!$B$5),MAX(0,V6+Settings!$B$2*G6/100-X6-Settings!$B$2*J6/100))),IF(Settings!$B$9,MROUND(Z6,Settings!$B$5),Z6)) | AB6: =IF(LEFT(T6,5)="ERROR","ERROR",IF(AND(Settings!$B$17,ABS(AA6-Z6)>1E-9),"FIXED",IF(ABS(S6)<=Settings!$B$7,"SAFE","WARNING"))) | AC6: =IF(AB6="FIXED","Close adjusted by SAFE mode",IF(AB6="SAFE","BUY/SELL balance preserved",IF(AB6="WARNING","Near protection boundary","Protection broken")))
A7: 5 | B7: =A7*Settings!$B$3 | C7: =IF(A7<=Settings!$B$4,IFERROR(XLOOKUP(A7,LevelRange,BigPercentRange),0),0) | D7: =W7 | E7: =IF(A7<=Settings!$B$4,IFERROR(XLOOKUP(A7,LevelRange,SmallPercentRange),0),0) | F7: =Y7 | G7: =N6 | H7: =G7+SUM($C$3:C7) | I7: =100+SUM($E$3:E7) | J7: =IF(A7<=Settings!$B$4,IFERROR(XLOOKUP(A7,LevelRange,TargetSkewRange),0),0) | K7: =MIN(G7,MAX(0,H7-I7+J7)) | L7: =IF(A7<=Settings!$B$4,IFERROR(XLOOKUP(A7,LevelRange,ManualCloseRange),""),"") | M7: =MIN(G7,AA7/Settings!$B$2*100) | N7: =G7-M7 | O7: =SUM($C$3:C7) | P7: =SUM($E$3:E7) | Q7: =N7+O7 | R7: =100+P7 | S7: =R7-Q7 | T7: =IF(Settings!$B$18=FALSE,"OK",IF(OR(NOT(ISNUMBER(Settings!$B$2)),Settings!$B$2<=0),"ERROR: Invalid StartLot",IF(OR(NOT(ISNUMBER(Settings!$B$5)),Settings!$B$5<=0),"ERROR: Invalid LotStep",IF(OR(Settings!$B$4<1,Settings!$B$4>20),"ERROR: Invalid MaxLevels",IF(AND(Settings!$B$10<>"DOWN",Settings!$B$10<>"UP"),"ERROR: Invalid Direction",IF(OR(C7<0,E7<0,J7<0,AND(LEN(L7)>0,L7<0)),"ERROR: Negative input",IF(C7<E7,"ERROR: Big SELL must be >= Small BUY",IF(AND(LEN(L7)>0,L7>G7),"ERROR: ManualClose exceeds remaining Start position",IF(OR(N7<0,Q7<0,R7<0),"ERROR: Negative totals",IF(Q7>R7,"ERROR: Rounding broke protection balance",IF(S7>Settings!$B$8,"WARNING: Skew exceeds recommended limit","OK"))))))))))) | U7: =IF(LEFT(T7,5)="ERROR","Check input/risk","") | V7: =Settings!$B$2*C7/100 | W7: =IF(Settings!$B$9,FLOOR(V7,Settings!$B$5),V7) | X7: =Settings!$B$2*E7/100 | Y7: =IF(Settings!$B$9,CEILING(X7,Settings!$B$5),X7) | Z7: =Settings!$B$2*M7/100 | AA7: =IF(Settings!$B$17,MIN(Settings!$B$2*G7/100,IF(Settings!$B$9,CEILING(MAX(0,V7+Settings!$B$2*G7/100-X7-Settings!$B$2*J7/100),Settings!$B$5),MAX(0,V7+Settings!$B$2*G7/100-X7-Settings!$B$2*J7/100))),IF(Settings!$B$9,MROUND(Z7,Settings!$B$5),Z7)) | AB7: =IF(LEFT(T7,5)="ERROR","ERROR",IF(AND(Settings!$B$17,ABS(AA7-Z7)>1E-9),"FIXED",IF(ABS(S7)<=Settings!$B$7,"SAFE","WARNING"))) | AC7: =IF(AB7="FIXED","Close adjusted by SAFE mode",IF(AB7="SAFE","BUY/SELL balance preserved",IF(AB7="WARNING","Near protection boundary","Protection broken")))
A8: 6 | B8: =A8*Settings!$B$3 | C8: =IF(A8<=Settings!$B$4,IFERROR(XLOOKUP(A8,LevelRange,BigPercentRange),0),0) | D8: =W8 | E8: =IF(A8<=Settings!$B$4,IFERROR(XLOOKUP(A8,LevelRange,SmallPercentRange),0),0) | F8: =Y8 | G8: =N7 | H8: =G8+SUM($C$3:C8) | I8: =100+SUM($E$3:E8) | J8: =IF(A8<=Settings!$B$4,IFERROR(XLOOKUP(A8,LevelRange,TargetSkewRange),0),0) | K8: =MIN(G8,MAX(0,H8-I8+J8)) | L8: =IF(A8<=Settings!$B$4,IFERROR(XLOOKUP(A8,LevelRange,ManualCloseRange),""),"") | M8: =MIN(G8,AA8/Settings!$B$2*100) | N8: =G8-M8 | O8: =SUM($C$3:C8) | P8: =SUM($E$3:E8) | Q8: =N8+O8 | R8: =100+P8 | S8: =R8-Q8 | T8: =IF(Settings!$B$18=FALSE,"OK",IF(OR(NOT(ISNUMBER(Settings!$B$2)),Settings!$B$2<=0),"ERROR: Invalid StartLot",IF(OR(NOT(ISNUMBER(Settings!$B$5)),Settings!$B$5<=0),"ERROR: Invalid LotStep",IF(OR(Settings!$B$4<1,Settings!$B$4>20),"ERROR: Invalid MaxLevels",IF(AND(Settings!$B$10<>"DOWN",Settings!$B$10<>"UP"),"ERROR: Invalid Direction",IF(OR(C8<0,E8<0,J8<0,AND(LEN(L8)>0,L8<0)),"ERROR: Negative input",IF(C8<E8,"ERROR: Big SELL must be >= Small BUY",IF(AND(LEN(L8)>0,L8>G8),"ERROR: ManualClose exceeds remaining Start position",IF(OR(N8<0,Q8<0,R8<0),"ERROR: Negative totals",IF(Q8>R8,"ERROR: Rounding broke protection balance",IF(S8>Settings!$B$8,"WARNING: Skew exceeds recommended limit","OK"))))))))))) | U8: =IF(LEFT(T8,5)="ERROR","Check input/risk","") | V8: =Settings!$B$2*C8/100 | W8: =IF(Settings!$B$9,FLOOR(V8,Settings!$B$5),V8) | X8: =Settings!$B$2*E8/100 | Y8: =IF(Settings!$B$9,CEILING(X8,Settings!$B$5),X8) | Z8: =Settings!$B$2*M8/100 | AA8: =IF(Settings!$B$17,MIN(Settings!$B$2*G8/100,IF(Settings!$B$9,CEILING(MAX(0,V8+Settings!$B$2*G8/100-X8-Settings!$B$2*J8/100),Settings!$B$5),MAX(0,V8+Settings!$B$2*G8/100-X8-Settings!$B$2*J8/100))),IF(Settings!$B$9,MROUND(Z8,Settings!$B$5),Z8)) | AB8: =IF(LEFT(T8,5)="ERROR","ERROR",IF(AND(Settings!$B$17,ABS(AA8-Z8)>1E-9),"FIXED",IF(ABS(S8)<=Settings!$B$7,"SAFE","WARNING"))) | AC8: =IF(AB8="FIXED","Close adjusted by SAFE mode",IF(AB8="SAFE","BUY/SELL balance preserved",IF(AB8="WARNING","Near protection boundary","Protection broken")))
A9: 7 | B9: =A9*Settings!$B$3 | C9: =IF(A9<=Settings!$B$4,IFERROR(XLOOKUP(A9,LevelRange,BigPercentRange),0),0) | D9: =W9 | E9: =IF(A9<=Settings!$B$4,IFERROR(XLOOKUP(A9,LevelRange,SmallPercentRange),0),0) | F9: =Y9 | G9: =N8 | H9: =G9+SUM($C$3:C9) | I9: =100+SUM($E$3:E9) | J9: =IF(A9<=Settings!$B$4,IFERROR(XLOOKUP(A9,LevelRange,TargetSkewRange),0),0) | K9: =MIN(G9,MAX(0,H9-I9+J9)) | L9: =IF(A9<=Settings!$B$4,IFERROR(XLOOKUP(A9,LevelRange,ManualCloseRange),""),"") | M9: =MIN(G9,AA9/Settings!$B$2*100) | N9: =G9-M9 | O9: =SUM($C$3:C9) | P9: =SUM($E$3:E9) | Q9: =N9+O9 | R9: =100+P9 | S9: =R9-Q9 | T9: =IF(Settings!$B$18=FALSE,"OK",IF(OR(NOT(ISNUMBER(Settings!$B$2)),Settings!$B$2<=0),"ERROR: Invalid StartLot",IF(OR(NOT(ISNUMBER(Settings!$B$5)),Settings!$B$5<=0),"ERROR: Invalid LotStep",IF(OR(Settings!$B$4<1,Settings!$B$4>20),"ERROR: Invalid MaxLevels",IF(AND(Settings!$B$10<>"DOWN",Settings!$B$10<>"UP"),"ERROR: Invalid Direction",IF(OR(C9<0,E9<0,J9<0,AND(LEN(L9)>0,L9<0)),"ERROR: Negative input",IF(C9<E9,"ERROR: Big SELL must be >= Small BUY",IF(AND(LEN(L9)>0,L9>G9),"ERROR: ManualClose exceeds remaining Start position",IF(OR(N9<0,Q9<0,R9<0),"ERROR: Negative totals",IF(Q9>R9,"ERROR: Rounding broke protection balance",IF(S9>Settings!$B$8,"WARNING: Skew exceeds recommended limit","OK"))))))))))) | U9: =IF(LEFT(T9,5)="ERROR","Check input/risk","") | V9: =Settings!$B$2*C9/100 | W9: =IF(Settings!$B$9,FLOOR(V9,Settings!$B$5),V9) | X9: =Settings!$B$2*E9/100 | Y9: =IF(Settings!$B$9,CEILING(X9,Settings!$B$5),X9) | Z9: =Settings!$B$2*M9/100 | AA9: =IF(Settings!$B$17,MIN(Settings!$B$2*G9/100,IF(Settings!$B$9,CEILING(MAX(0,V9+Settings!$B$2*G9/100-X9-Settings!$B$2*J9/100),Settings!$B$5),MAX(0,V9+Settings!$B$2*G9/100-X9-Settings!$B$2*J9/100))),IF(Settings!$B$9,MROUND(Z9,Settings!$B$5),Z9)) | AB9: =IF(LEFT(T9,5)="ERROR","ERROR",IF(AND(Settings!$B$17,ABS(AA9-Z9)>1E-9),"FIXED",IF(ABS(S9)<=Settings!$B$7,"SAFE","WARNING"))) | AC9: =IF(AB9="FIXED","Close adjusted by SAFE mode",IF(AB9="SAFE","BUY/SELL balance preserved",IF(AB9="WARNING","Near protection boundary","Protection broken")))
A10: 8 | B10: =A10*Settings!$B$3 | C10: =IF(A10<=Settings!$B$4,IFERROR(XLOOKUP(A10,LevelRange,BigPercentRange),0),0) | D10: =W10 | E10: =IF(A10<=Settings!$B$4,IFERROR(XLOOKUP(A10,LevelRange,SmallPercentRange),0),0) | F10: =Y10 | G10: =N9 | H10: =G10+SUM($C$3:C10) | I10: =100+SUM($E$3:E10) | J10: =IF(A10<=Settings!$B$4,IFERROR(XLOOKUP(A10,LevelRange,TargetSkewRange),0),0) | K10: =MIN(G10,MAX(0,H10-I10+J10)) | L10: =IF(A10<=Settings!$B$4,IFERROR(XLOOKUP(A10,LevelRange,ManualCloseRange),""),"") | M10: =MIN(G10,AA10/Settings!$B$2*100) | N10: =G10-M10 | O10: =SUM($C$3:C10) | P10: =SUM($E$3:E10) | Q10: =N10+O10 | R10: =100+P10 | S10: =R10-Q10 | T10: =IF(Settings!$B$18=FALSE,"OK",IF(OR(NOT(ISNUMBER(Settings!$B$2)),Settings!$B$2<=0),"ERROR: Invalid StartLot",IF(OR(NOT(ISNUMBER(Settings!$B$5)),Settings!$B$5<=0),"ERROR: Invalid LotStep",IF(OR(Settings!$B$4<1,Settings!$B$4>20),"ERROR: Invalid MaxLevels",IF(AND(Settings!$B$10<>"DOWN",Settings!$B$10<>"UP"),"ERROR: Invalid Direction",IF(OR(C10<0,E10<0,J10<0,AND(LEN(L10)>0,L10<0)),"ERROR: Negative input",IF(C10<E10,"ERROR: Big SELL must be >= Small BUY",IF(AND(LEN(L10)>0,L10>G10),"ERROR: ManualClose exceeds remaining Start position",IF(OR(N10<0,Q10<0,R10<0),"ERROR: Negative totals",IF(Q10>R10,"ERROR: Rounding broke protection balance",IF(S10>Settings!$B$8,"WARNING: Skew exceeds recommended limit","OK"))))))))))) | U10: =IF(LEFT(T10,5)="ERROR","Check input/risk","") | V10: =Settings!$B$2*C10/100 | W10: =IF(Settings!$B$9,FLOOR(V10,Settings!$B$5),V10) | X10: =Settings!$B$2*E10/100 | Y10: =IF(Settings!$B$9,CEILING(X10,Settings!$B$5),X10) | Z10: =Settings!$B$2*M10/100 | AA10: =IF(Settings!$B$17,MIN(Settings!$B$2*G10/100,IF(Settings!$B$9,CEILING(MAX(0,V10+Settings!$B$2*G10/100-X10-Settings!$B$2*J10/100),Settings!$B$5),MAX(0,V10+Settings!$B$2*G10/100-X10-Settings!$B$2*J10/100))),IF(Settings!$B$9,MROUND(Z10,Settings!$B$5),Z10)) | AB10: =IF(LEFT(T10,5)="ERROR","ERROR",IF(AND(Settings!$B$17,ABS(AA10-Z10)>1E-9),"FIXED",IF(ABS(S10)<=Settings!$B$7,"SAFE","WARNING"))) | AC10: =IF(AB10="FIXED","Close adjusted by SAFE mode",IF(AB10="SAFE","BUY/SELL balance preserved",IF(AB10="WARNING","Near protection boundary","Protection broken")))
A11: 9 | B11: =A11*Settings!$B$3 | C11: =IF(A11<=Settings!$B$4,IFERROR(XLOOKUP(A11,LevelRange,BigPercentRange),0),0) | D11: =W11 | E11: =IF(A11<=Settings!$B$4,IFERROR(XLOOKUP(A11,LevelRange,SmallPercentRange),0),0) | F11: =Y11 | G11: =N10 | H11: =G11+SUM($C$3:C11) | I11: =100+SUM($E$3:E11) | J11: =IF(A11<=Settings!$B$4,IFERROR(XLOOKUP(A11,LevelRange,TargetSkewRange),0),0) | K11: =MIN(G11,MAX(0,H11-I11+J11)) | L11: =IF(A11<=Settings!$B$4,IFERROR(XLOOKUP(A11,LevelRange,ManualCloseRange),""),"") | M11: =MIN(G11,AA11/Settings!$B$2*100) | N11: =G11-M11 | O11: =SUM($C$3:C11) | P11: =SUM($E$3:E11) | Q11: =N11+O11 | R11: =100+P11 | S11: =R11-Q11 | T11: =IF(Settings!$B$18=FALSE,"OK",IF(OR(NOT(ISNUMBER(Settings!$B$2)),Settings!$B$2<=0),"ERROR: Invalid StartLot",IF(OR(NOT(ISNUMBER(Settings!$B$5)),Settings!$B$5<=0),"ERROR: Invalid LotStep",IF(OR(Settings!$B$4<1,Settings!$B$4>20),"ERROR: Invalid MaxLevels",IF(AND(Settings!$B$10<>"DOWN",Settings!$B$10<>"UP"),"ERROR: Invalid Direction",IF(OR(C11<0,E11<0,J11<0,AND(LEN(L11)>0,L11<0)),"ERROR: Negative input",IF(C11<E11,"ERROR: Big SELL must be >= Small BUY",IF(AND(LEN(L11)>0,L11>G11),"ERROR: ManualClose exceeds remaining Start position",IF(OR(N11<0,Q11<0,R11<0),"ERROR: Negative totals",IF(Q11>R11,"ERROR: Rounding broke protection balance",IF(S11>Settings!$B$8,"WARNING: Skew exceeds recommended limit","OK"))))))))))) | U11: =IF(LEFT(T11,5)="ERROR","Check input/risk","") | V11: =Settings!$B$2*C11/100 | W11: =IF(Settings!$B$9,FLOOR(V11,Settings!$B$5),V11) | X11: =Settings!$B$2*E11/100 | Y11: =IF(Settings!$B$9,CEILING(X11,Settings!$B$5),X11) | Z11: =Settings!$B$2*M11/100 | AA11: =IF(Settings!$B$17,MIN(Settings!$B$2*G11/100,IF(Settings!$B$9,CEILING(MAX(0,V11+Settings!$B$2*G11/100-X11-Settings!$B$2*J11/100),Settings!$B$5),MAX(0,V11+Settings!$B$2*G11/100-X11-Settings!$B$2*J11/100))),IF(Settings!$B$9,MROUND(Z11,Settings!$B$5),Z11)) | AB11: =IF(LEFT(T11,5)="ERROR","ERROR",IF(AND(Settings!$B$17,ABS(AA11-Z11)>1E-9),"FIXED",IF(ABS(S11)<=Settings!$B$7,"SAFE","WARNING"))) | AC11: =IF(AB11="FIXED","Close adjusted by SAFE mode",IF(AB11="SAFE","BUY/SELL balance preserved",IF(AB11="WARNING","Near protection boundary","Protection broken")))
A12: 10 | B12: =A12*Settings!$B$3 | C12: =IF(A12<=Settings!$B$4,IFERROR(XLOOKUP(A12,LevelRange,BigPercentRange),0),0) | D12: =W12 | E12: =IF(A12<=Settings!$B$4,IFERROR(XLOOKUP(A12,LevelRange,SmallPercentRange),0),0) | F12: =Y12 | G12: =N11 | H12: =G12+SUM($C$3:C12) | I12: =100+SUM($E$3:E12) | J12: =IF(A12<=Settings!$B$4,IFERROR(XLOOKUP(A12,LevelRange,TargetSkewRange),0),0) | K12: =MIN(G12,MAX(0,H12-I12+J12)) | L12: =IF(A12<=Settings!$B$4,IFERROR(XLOOKUP(A12,LevelRange,ManualCloseRange),""),"") | M12: =MIN(G12,AA12/Settings!$B$2*100) | N12: =G12-M12 | O12: =SUM($C$3:C12) | P12: =SUM($E$3:E12) | Q12: =N12+O12 | R12: =100+P12 | S12: =R12-Q12 | T12: =IF(Settings!$B$18=FALSE,"OK",IF(OR(NOT(ISNUMBER(Settings!$B$2)),Settings!$B$2<=0),"ERROR: Invalid StartLot",IF(OR(NOT(ISNUMBER(Settings!$B$5)),Settings!$B$5<=0),"ERROR: Invalid LotStep",IF(OR(Settings!$B$4<1,Settings!$B$4>20),"ERROR: Invalid MaxLevels",IF(AND(Settings!$B$10<>"DOWN",Settings!$B$10<>"UP"),"ERROR: Invalid Direction",IF(OR(C12<0,E12<0,J12<0,AND(LEN(L12)>0,L12<0)),"ERROR: Negative input",IF(C12<E12,"ERROR: Big SELL must be >= Small BUY",IF(AND(LEN(L12)>0,L12>G12),"ERROR: ManualClose exceeds remaining Start position",IF(OR(N12<0,Q12<0,R12<0),"ERROR: Negative totals",IF(Q12>R12,"ERROR: Rounding broke protection balance",IF(S12>Settings!$B$8,"WARNING: Skew exceeds recommended limit","OK"))))))))))) | U12: =IF(LEFT(T12,5)="ERROR","Check input/risk","") | V12: =Settings!$B$2*C12/100 | W12: =IF(Settings!$B$9,FLOOR(V12,Settings!$B$5),V12) | X12: =Settings!$B$2*E12/100 | Y12: =IF(Settings!$B$9,CEILING(X12,Settings!$B$5),X12) | Z12: =Settings!$B$2*M12/100 | AA12: =IF(Settings!$B$17,MIN(Settings!$B$2*G12/100,IF(Settings!$B$9,CEILING(MAX(0,V12+Settings!$B$2*G12/100-X12-Settings!$B$2*J12/100),Settings!$B$5),MAX(0,V12+Settings!$B$2*G12/100-X12-Settings!$B$2*J12/100))),IF(Settings!$B$9,MROUND(Z12,Settings!$B$5),Z12)) | AB12: =IF(LEFT(T12,5)="ERROR","ERROR",IF(AND(Settings!$B$17,ABS(AA12-Z12)>1E-9),"FIXED",IF(ABS(S12)<=Settings!$B$7,"SAFE","WARNING"))) | AC12: =IF(AB12="FIXED","Close adjusted by SAFE mode",IF(AB12="SAFE","BUY/SELL balance preserved",IF(AB12="WARNING","Near protection boundary","Protection broken")))
A13: 11 | B13: =A13*Settings!$B$3 | C13: =IF(A13<=Settings!$B$4,IFERROR(XLOOKUP(A13,LevelRange,BigPercentRange),0),0) | D13: =W13 | E13: =IF(A13<=Settings!$B$4,IFERROR(XLOOKUP(A13,LevelRange,SmallPercentRange),0),0) | F13: =Y13 | G13: =N12 | H13: =G13+SUM($C$3:C13) | I13: =100+SUM($E$3:E13) | J13: =IF(A13<=Settings!$B$4,IFERROR(XLOOKUP(A13,LevelRange,TargetSkewRange),0),0) | K13: =MIN(G13,MAX(0,H13-I13+J13)) | L13: =IF(A13<=Settings!$B$4,IFERROR(XLOOKUP(A13,LevelRange,ManualCloseRange),""),"") | M13: =MIN(G13,AA13/Settings!$B$2*100) | N13: =G13-M13 | O13: =SUM($C$3:C13) | P13: =SUM($E$3:E13) | Q13: =N13+O13 | R13: =100+P13 | S13: =R13-Q13 | T13: =IF(Settings!$B$18=FALSE,"OK",IF(OR(NOT(ISNUMBER(Settings!$B$2)),Settings!$B$2<=0),"ERROR: Invalid StartLot",IF(OR(NOT(ISNUMBER(Settings!$B$5)),Settings!$B$5<=0),"ERROR: Invalid LotStep",IF(OR(Settings!$B$4<1,Settings!$B$4>20),"ERROR: Invalid MaxLevels",IF(AND(Settings!$B$10<>"DOWN",Settings!$B$10<>"UP"),"ERROR: Invalid Direction",IF(OR(C13<0,E13<0,J13<0,AND(LEN(L13)>0,L13<0)),"ERROR: Negative input",IF(C13<E13,"ERROR: Big SELL must be >= Small BUY",IF(AND(LEN(L13)>0,L13>G13),"ERROR: ManualClose exceeds remaining Start position",IF(OR(N13<0,Q13<0,R13<0),"ERROR: Negative totals",IF(Q13>R13,"ERROR: Rounding broke protection balance",IF(S13>Settings!$B$8,"WARNING: Skew exceeds recommended limit","OK"))))))))))) | U13: =IF(LEFT(T13,5)="ERROR","Check input/risk","") | V13: =Settings!$B$2*C13/100 | W13: =IF(Settings!$B$9,FLOOR(V13,Settings!$B$5),V13) | X13: =Settings!$B$2*E13/100 | Y13: =IF(Settings!$B$9,CEILING(X13,Settings!$B$5),X13) | Z13: =Settings!$B$2*M13/100 | AA13: =IF(Settings!$B$17,MIN(Settings!$B$2*G13/100,IF(Settings!$B$9,CEILING(MAX(0,V13+Settings!$B$2*G13/100-X13-Settings!$B$2*J13/100),Settings!$B$5),MAX(0,V13+Settings!$B$2*G13/100-X13-Settings!$B$2*J13/100))),IF(Settings!$B$9,MROUND(Z13,Settings!$B$5),Z13)) | AB13: =IF(LEFT(T13,5)="ERROR","ERROR",IF(AND(Settings!$B$17,ABS(AA13-Z13)>1E-9),"FIXED",IF(ABS(S13)<=Settings!$B$7,"SAFE","WARNING"))) | AC13: =IF(AB13="FIXED","Close adjusted by SAFE mode",IF(AB13="SAFE","BUY/SELL balance preserved",IF(AB13="WARNING","Near protection boundary","Protection broken")))
