Workbook

Sheet Settings
A1: Параметр | B1: Значение | C1: Описание | E1: Цветовая легенда
A2: StartLot | B2: 1 | C2: стартовый лот замка | E2: Входные параметры
A3: BigRatio | B3: 1.15 | C3: Big = FarStart × 115% | E3: Расчётные поля
A4: SmallRatio | B4: 0.38 | C4: Small = Big × 38% | E4: Прибыль
A5: CloseFarShare | B5: 0.2 | C5: максимум 20% чистой прибыли на хвост | E5: Убыток
A6: ReserveShare | B6: 0.8 | C6: 80% чистой прибыли в резерв | E6: Резерв
A7: CloseBigOnSmall | B7: 0.22 | C7: закрытие Big при Small-сценарии | E7: WARNING
A8: RemainBigOnSmall | B8: 0.78 | C8: остаток Big | E8: DUAL_TAIL
A9: PointValuePerLot | B9: 1 | C9: стоимость пункта на 1 лот | E9: DANGER
A10: MarginPerLot | B10: 1000 | C10: маржа на 1 лот | E10: STOP
A11: LotStep | B11: 0.01 | C11: шаг лота
A12: MaxLevels | B12: 10 | C12: количество уровней
A13: CommissionPerLot | B13: 0 | C13: комиссия
A14: SpreadCostPerLot | B14: 0 | C14: спред
A15: SlippageCostPerLot | B15: 0 | C15: проскальзывание
A16: MaxBigRatio | B16: 1.2 | C16: лимит Big
A17: MaxSmallRatio | B17: 0.45 | C17: лимит Small

Sheet Calculator
A1: Level | B1: Scenario | C1: FarDirection | D1: FarStartLot | E1: BigDirection | F1: BigLotRaw | G1: BigLot | H1: SmallDirection | I1: SmallLotRaw | J1: SmallLot | K1: BigProfitPoints | L1: SmallPoints | M1: FarLossPoints | N1: ProfitBig | O1: ProfitSmall | P1: LossSmall | Q1: LossClosedBig | R1: Costs | S1: NetProfit | T1: CloseFarBudget | U1: LossPerLotToClose | V1: CloseFarLot | W1: FarRemainLot | X1: ReserveAdd | Y1: TotalReserve | Z1: BalanceBefore | AA1: BalanceAfter | AB1: OpenLotsBefore | AC1: OpenLotsAfter | AD1: MarginBefore | AE1: MarginAfter | AF1: NewFarDirection | AG1: NewFarStartLot | AH1: OldFarCanClose | AI1: OldFarClosePL | AJ1: OldFarRemainLot | AK1: DualTailFlag | AL1: CloseBigLot | AM1: RemainBigLot | AN1: BigClosedPercent | AO1: SmallClosedPercent | AP1: NewFullLevelAllowed | AQ1: Status | AR1: Comment | AS1: RealizedFarLoss | AT1: ClosedLotsForCosts | AU1: CostPerLot | AV1: OldFarClosedLot | AW1: BlockedReason | AX1: NetProfitBeforeFar | AY1: CostsBeforeFar | AZ1: CostsFarClose
A2: 1 | B2: BIG_SIDE | C2: SELL | D2: =Settings!$B$2 | E2: =IF($B2="BLOCKED","",IF($C2="SELL","BUY","SELL")) | F2: =IF($B2="BLOCKED",0,MAX(0,$D2*Settings!$B$3)) | G2: =IF($B2="BLOCKED",0,IFERROR(MAX(0,ROUND($F2/Settings!$B$11,0)*Settings!$B$11),0)) | H2: =IF($B2="BLOCKED","",$C2) | I2: =IF($B2="BLOCKED",0,MAX(0,$G2*Settings!$B$4)) | J2: =IF($B2="BLOCKED",0,IFERROR(MAX(0,ROUND($I2/Settings!$B$11,0)*Settings!$B$11),0)) | K2: 100 | L2: -40 | M2: 100 | N2: =IF($B2="BIG_SIDE",$G2*MAX(0,$K2)*Settings!$B$9,0) | O2: =IF($B2="SMALL_SIDE",$J2*ABS($L2)*Settings!$B$9,0) | P2: =IF($B2="BIG_SIDE",$J2*ABS($L2)*Settings!$B$9,0) | Q2: =IF($B2="SMALL_SIDE",$AL2*ABS($K2)*Settings!$B$9,0) | R2: =$AT2*$AU2 | S2: =IF($B2="BIG_SIDE",$N2-$P2-$R2,IF($B2="SMALL_SIDE",$O2-$Q2-$R2,0)) | T2: =IF(AND($B2="BIG_SIDE",$AX2>0),$AX2*Settings!$B$5,0) | U2: =MAX(0,$M2*Settings!$B$9) | V2: =IF($B2="BIG_SIDE",IFERROR(MIN($D2,MAX(0,$T2/$U2)),0),0) | W2: =IF($B2="BIG_SIDE",MAX(0,$D2-$V2),$AJ2) | X2: =IF($B2="BIG_SIDE",IF($AX2>0,$AX2-$AS2,0),IF($S2>0,$S2*0.5,0)) | Y2: =X2 | Z2: 0 | AA2: =IF($B2="BLOCKED",$Z2,IF($B2="BIG_SIDE",$Z2+$AX2-$AS2-$AZ2,IF($B2="SMALL_SIDE",$Z2+$S2+$AI2,$Z2+$S2))) | AB2: =IF($B2="BLOCKED",IF(ROW()=2,0,$AG1+$AJ1),$D2+$G2+$J2) | AC2: =IF($B2="BLOCKED",$AB2,IF($B2="BIG_SIDE",$W2,$AG2+$AJ2)) | AD2: =$AB2*Settings!$B$10 | AE2: =$AC2*Settings!$B$10 | AF2: =IF($B2="BLOCKED",IF(ROW()=2,$C2,$AF1),IF($B2="SMALL_SIDE",$E2,$C2)) | AG2: =IF($B2="BLOCKED",IF(ROW()=2,0,$AG1),IF($B2="SMALL_SIDE",$AM2,$W2)) | AH2: NO | AI2: 0 | AJ2: =IF($B2="SMALL_SIDE",MAX(0,$D2-$AV2),0) | AK2: =IF(AND($AJ2>0,$AG2>0),TRUE,FALSE) | AL2: =IF($B2="SMALL_SIDE",$G2*Settings!$B$7,IF($B2="BIG_SIDE",$G2,0)) | AM2: =IF($B2="SMALL_SIDE",MAX(0,$G2-$AL2),0) | AN2: =IF($B2="BIG_SIDE",1,IF($B2="SMALL_SIDE",Settings!$B$7,0)) | AO2: =IF(OR($B2="BIG_SIDE",$B2="SMALL_SIDE"),1,0) | AP2: =IF(OR($AQ2="DUAL_TAIL",$AQ2="DANGER",$AQ2="STOP"),"NO","YES") | AQ2: =IF($B2="BLOCKED","STOP",IF($AK2=TRUE,"DUAL_TAIL",IF(OR(IFERROR($G2/$D2,0)>Settings!$B$16,IFERROR($J2/$G2,0)>Settings!$B$17,$AE2>$AD2,$Y2<0,$AG2>$D2*1.0001,$S2<-100),"DANGER",IF(OR(AND($B2="BIG_SIDE",$U2<=0),$S2<=0,$X2=0,$AE2>$AD2*0.95),"WARNING","OK")))) | AR2: =IF($B2="BLOCKED","Заблокировано: предыдущий уровень не разрешил новый полноценный уровень",IF($B2="BIG_SIDE","BIG_SIDE: Big и Small закрыты 100%; баланс учитывает RealizedFarLoss",IF($AQ2="DUAL_TAIL","SMALL_SIDE: старый и новый хвост одновременно; новый уровень запрещён","SMALL_SIDE: Small закрыт 100%, Big закрыт 22%, остаток Big = новый хвост"))) | AS2: =IF($B2="BIG_SIDE",$V2*$U2,0) | AT2: =IF($B2="BIG_SIDE",$G2+$J2+$V2,IF($B2="SMALL_SIDE",$J2+$AL2+$AV2,0)) | AU2: =Settings!$B$13+Settings!$B$14+Settings!$B$15 | AV2: =IF($B2="SMALL_SIDE",IF($AH2="YES",$D2,IFERROR(MIN($D2,MAX(0,$AI2/$U2)),0)),0) | AW2: =IF($B2="BLOCKED","Заблокировано: предыдущий уровень не разрешил новый полноценный уровень","") | AX2: =IF($B2="BIG_SIDE",$N2-$P2-$AY2,IF($B2="SMALL_SIDE",$O2-$Q2-$R2,0)) | AY2: =IF($B2="BIG_SIDE",($G2+$J2)*$AU2,0) | AZ2: =IF($B2="BIG_SIDE",$V2*$AU2,0)
A3: 2 | B3: =IF(OR($AP2="NO",$AQ2="DUAL_TAIL",$AQ2="DANGER",$AQ2="STOP"),"BLOCKED","BIG_SIDE") | C3: =IF($B3="BLOCKED",$AF2,IF($AP2="YES",$AF2,$C2)) | D3: =IF($B3="BLOCKED",0,IF($AP2="YES",MAX(0,$AG2),$D2)) | E3: =IF($B3="BLOCKED","",IF($C3="SELL","BUY","SELL")) | F3: =IF($B3="BLOCKED",0,MAX(0,$D3*Settings!$B$3)) | G3: =IF($B3="BLOCKED",0,IFERROR(MAX(0,ROUND($F3/Settings!$B$11,0)*Settings!$B$11),0)) | H3: =IF($B3="BLOCKED","",$C3) | I3: =IF($B3="BLOCKED",0,MAX(0,$G3*Settings!$B$4)) | J3: =IF($B3="BLOCKED",0,IFERROR(MAX(0,ROUND($I3/Settings!$B$11,0)*Settings!$B$11),0)) | K3: 100 | L3: -40 | M3: 100 | N3: =IF($B3="BIG_SIDE",$G3*MAX(0,$K3)*Settings!$B$9,0) | O3: =IF($B3="SMALL_SIDE",$J3*ABS($L3)*Settings!$B$9,0) | P3: =IF($B3="BIG_SIDE",$J3*ABS($L3)*Settings!$B$9,0) | Q3: =IF($B3="SMALL_SIDE",$AL3*ABS($K3)*Settings!$B$9,0) | R3: =$AT3*$AU3 | S3: =IF($B3="BIG_SIDE",$N3-$P3-$R3,IF($B3="SMALL_SIDE",$O3-$Q3-$R3,0)) | T3: =IF(AND($B3="BIG_SIDE",$AX3>0),$AX3*Settings!$B$5,0) | U3: =MAX(0,$M3*Settings!$B$9) | V3: =IF($B3="BIG_SIDE",IFERROR(MIN($D3,MAX(0,$T3/$U3)),0),0) | W3: =IF($B3="BIG_SIDE",MAX(0,$D3-$V3),$AJ3) | X3: =IF($B3="BIG_SIDE",IF($AX3>0,$AX3-$AS3,0),IF($S3>0,$S3*0.5,0)) | Y3: =$Y2+$X3 | Z3: =$AA2 | AA3: =IF($B3="BLOCKED",$Z3,IF($B3="BIG_SIDE",$Z3+$AX3-$AS3-$AZ3,IF($B3="SMALL_SIDE",$Z3+$S3+$AI3,$Z3+$S3))) | AB3: =IF($B3="BLOCKED",IF(ROW()=2,0,$AG2+$AJ2),$D3+$G3+$J3) | AC3: =IF($B3="BLOCKED",$AB3,IF($B3="BIG_SIDE",$W3,$AG3+$AJ3)) | AD3: =$AB3*Settings!$B$10 | AE3: =$AC3*Settings!$B$10 | AF3: =IF($B3="BLOCKED",IF(ROW()=2,$C3,$AF2),IF($B3="SMALL_SIDE",$E3,$C3)) | AG3: =IF($B3="BLOCKED",IF(ROW()=2,0,$AG2),IF($B3="SMALL_SIDE",$AM3,$W3)) | AH3: NO | AI3: 0 | AJ3: =IF($B3="SMALL_SIDE",MAX(0,$D3-$AV3),0) | AK3: =IF(AND($AJ3>0,$AG3>0),TRUE,FALSE) | AL3: =IF($B3="SMALL_SIDE",$G3*Settings!$B$7,IF($B3="BIG_SIDE",$G3,0)) | AM3: =IF($B3="SMALL_SIDE",MAX(0,$G3-$AL3),0) | AN3: =IF($B3="BIG_SIDE",1,IF($B3="SMALL_SIDE",Settings!$B$7,0)) | AO3: =IF(OR($B3="BIG_SIDE",$B3="SMALL_SIDE"),1,0) | AP3: =IF(OR($AQ3="DUAL_TAIL",$AQ3="DANGER",$AQ3="STOP"),"NO","YES") | AQ3: =IF($B3="BLOCKED","STOP",IF($AK3=TRUE,"DUAL_TAIL",IF(OR(IFERROR($G3/$D3,0)>Settings!$B$16,IFERROR($J3/$G3,0)>Settings!$B$17,$AE3>$AD3,$Y3<0,$AG3>$D3*1.0001,$S3<-100),"DANGER",IF(OR(AND($B3="BIG_SIDE",$U3<=0),$S3<=0,$X3=0,$AE3>$AD3*0.95),"WARNING","OK")))) | AR3: =IF($B3="BLOCKED","Заблокировано: предыдущий уровень не разрешил новый полноценный уровень",IF($B3="BIG_SIDE","BIG_SIDE: Big и Small закрыты 100%; баланс учитывает RealizedFarLoss",IF($AQ3="DUAL_TAIL","SMALL_SIDE: старый и новый хвост одновременно; новый уровень запрещён","SMALL_SIDE: Small закрыт 100%, Big закрыт 22%, остаток Big = новый хвост"))) | AS3: =IF($B3="BIG_SIDE",$V3*$U3,0) | AT3: =IF($B3="BIG_SIDE",$G3+$J3+$V3,IF($B3="SMALL_SIDE",$J3+$AL3+$AV3,0)) | AU3: =Settings!$B$13+Settings!$B$14+Settings!$B$15 | AV3: =IF($B3="SMALL_SIDE",IF($AH3="YES",$D3,IFERROR(MIN($D3,MAX(0,$AI3/$U3)),0)),0) | AW3: =IF($B3="BLOCKED","Заблокировано: предыдущий уровень не разрешил новый полноценный уровень","") | AX3: =IF($B3="BIG_SIDE",$N3-$P3-$AY3,IF($B3="SMALL_SIDE",$O3-$Q3-$R3,0)) | AY3: =IF($B3="BIG_SIDE",($G3+$J3)*$AU3,0) | AZ3: =IF($B3="BIG_SIDE",$V3*$AU3,0)
A4: 3 | B4: =IF(OR($AP3="NO",$AQ3="DUAL_TAIL",$AQ3="DANGER",$AQ3="STOP"),"BLOCKED","SMALL_SIDE") | C4: =IF($B4="BLOCKED",$AF3,IF($AP3="YES",$AF3,$C3)) | D4: =IF($B4="BLOCKED",0,IF($AP3="YES",MAX(0,$AG3),$D3)) | E4: =IF($B4="BLOCKED","",IF($C4="SELL","BUY","SELL")) | F4: =IF($B4="BLOCKED",0,MAX(0,$D4*Settings!$B$3)) | G4: =IF($B4="BLOCKED",0,IFERROR(MAX(0,ROUND($F4/Settings!$B$11,0)*Settings!$B$11),0)) | H4: =IF($B4="BLOCKED","",$C4) | I4: =IF($B4="BLOCKED",0,MAX(0,$G4*Settings!$B$4)) | J4: =IF($B4="BLOCKED",0,IFERROR(MAX(0,ROUND($I4/Settings!$B$11,0)*Settings!$B$11),0)) | K4: 80 | L4: 60 | M4: 100 | N4: =IF($B4="BIG_SIDE",$G4*MAX(0,$K4)*Settings!$B$9,0) | O4: =IF($B4="SMALL_SIDE",$J4*ABS($L4)*Settings!$B$9,0) | P4: =IF($B4="BIG_SIDE",$J4*ABS($L4)*Settings!$B$9,0) | Q4: =IF($B4="SMALL_SIDE",$AL4*ABS($K4)*Settings!$B$9,0) | R4: =$AT4*$AU4 | S4: =IF($B4="BIG_SIDE",$N4-$P4-$R4,IF($B4="SMALL_SIDE",$O4-$Q4-$R4,0)) | T4: =IF(AND($B4="BIG_SIDE",$AX4>0),$AX4*Settings!$B$5,0) | U4: =MAX(0,$M4*Settings!$B$9) | V4: =IF($B4="BIG_SIDE",IFERROR(MIN($D4,MAX(0,$T4/$U4)),0),0) | W4: =IF($B4="BIG_SIDE",MAX(0,$D4-$V4),$AJ4) | X4: =IF($B4="BIG_SIDE",IF($AX4>0,$AX4-$AS4,0),IF($S4>0,$S4*0.5,0)) | Y4: =$Y3+$X4 | Z4: =$AA3 | AA4: =IF($B4="BLOCKED",$Z4,IF($B4="BIG_SIDE",$Z4+$AX4-$AS4-$AZ4,IF($B4="SMALL_SIDE",$Z4+$S4+$AI4,$Z4+$S4))) | AB4: =IF($B4="BLOCKED",IF(ROW()=2,0,$AG3+$AJ3),$D4+$G4+$J4) | AC4: =IF($B4="BLOCKED",$AB4,IF($B4="BIG_SIDE",$W4,$AG4+$AJ4)) | AD4: =$AB4*Settings!$B$10 | AE4: =$AC4*Settings!$B$10 | AF4: =IF($B4="BLOCKED",IF(ROW()=2,$C4,$AF3),IF($B4="SMALL_SIDE",$E4,$C4)) | AG4: =IF($B4="BLOCKED",IF(ROW()=2,0,$AG3),IF($B4="SMALL_SIDE",$AM4,$W4)) | AH4: YES | AI4: 0 | AJ4: =IF($B4="SMALL_SIDE",MAX(0,$D4-$AV4),0) | AK4: =IF(AND($AJ4>0,$AG4>0),TRUE,FALSE) | AL4: =IF($B4="SMALL_SIDE",$G4*Settings!$B$7,IF($B4="BIG_SIDE",$G4,0)) | AM4: =IF($B4="SMALL_SIDE",MAX(0,$G4-$AL4),0) | AN4: =IF($B4="BIG_SIDE",1,IF($B4="SMALL_SIDE",Settings!$B$7,0)) | AO4: =IF(OR($B4="BIG_SIDE",$B4="SMALL_SIDE"),1,0) | AP4: =IF(OR($AQ4="DUAL_TAIL",$AQ4="DANGER",$AQ4="STOP"),"NO","YES") | AQ4: =IF($B4="BLOCKED","STOP",IF($AK4=TRUE,"DUAL_TAIL",IF(OR(IFERROR($G4/$D4,0)>Settings!$B$16,IFERROR($J4/$G4,0)>Settings!$B$17,$AE4>$AD4,$Y4<0,$AG4>$D4*1.0001,$S4<-100),"DANGER",IF(OR(AND($B4="BIG_SIDE",$U4<=0),$S4<=0,$X4=0,$AE4>$AD4*0.95),"WARNING","OK")))) | AR4: =IF($B4="BLOCKED","Заблокировано: предыдущий уровень не разрешил новый полноценный уровень",IF($B4="BIG_SIDE","BIG_SIDE: Big и Small закрыты 100%; баланс учитывает RealizedFarLoss",IF($AQ4="DUAL_TAIL","SMALL_SIDE: старый и новый хвост одновременно; новый уровень запрещён","SMALL_SIDE: Small закрыт 100%, Big закрыт 22%, остаток Big = новый хвост"))) | AS4: =IF($B4="BIG_SIDE",$V4*$U4,0) | AT4: =IF($B4="BIG_SIDE",$G4+$J4+$V4,IF($B4="SMALL_SIDE",$J4+$AL4+$AV4,0)) | AU4: =Settings!$B$13+Settings!$B$14+Settings!$B$15 | AV4: =IF($B4="SMALL_SIDE",IF($AH4="YES",$D4,IFERROR(MIN($D4,MAX(0,$AI4/$U4)),0)),0) | AW4: =IF($B4="BLOCKED","Заблокировано: предыдущий уровень не разрешил новый полноценный уровень","") | AX4: =IF($B4="BIG_SIDE",$N4-$P4-$AY4,IF($B4="SMALL_SIDE",$O4-$Q4-$R4,0)) | AY4: =IF($B4="BIG_SIDE",($G4+$J4)*$AU4,0) | AZ4: =IF($B4="BIG_SIDE",$V4*$AU4,0)
A5: 4 | B5: =IF(OR($AP4="NO",$AQ4="DUAL_TAIL",$AQ4="DANGER",$AQ4="STOP"),"BLOCKED","BIG_SIDE") | C5: =IF($B5="BLOCKED",$AF4,IF($AP4="YES",$AF4,$C4)) | D5: =IF($B5="BLOCKED",0,IF($AP4="YES",MAX(0,$AG4),$D4)) | E5: =IF($B5="BLOCKED","",IF($C5="SELL","BUY","SELL")) | F5: =IF($B5="BLOCKED",0,MAX(0,$D5*Settings!$B$3)) | G5: =IF($B5="BLOCKED",0,IFERROR(MAX(0,ROUND($F5/Settings!$B$11,0)*Settings!$B$11),0)) | H5: =IF($B5="BLOCKED","",$C5) | I5: =IF($B5="BLOCKED",0,MAX(0,$G5*Settings!$B$4)) | J5: =IF($B5="BLOCKED",0,IFERROR(MAX(0,ROUND($I5/Settings!$B$11,0)*Settings!$B$11),0)) | K5: 100 | L5: -40 | M5: 100 | N5: =IF($B5="BIG_SIDE",$G5*MAX(0,$K5)*Settings!$B$9,0) | O5: =IF($B5="SMALL_SIDE",$J5*ABS($L5)*Settings!$B$9,0) | P5: =IF($B5="BIG_SIDE",$J5*ABS($L5)*Settings!$B$9,0) | Q5: =IF($B5="SMALL_SIDE",$AL5*ABS($K5)*Settings!$B$9,0) | R5: =$AT5*$AU5 | S5: =IF($B5="BIG_SIDE",$N5-$P5-$R5,IF($B5="SMALL_SIDE",$O5-$Q5-$R5,0)) | T5: =IF(AND($B5="BIG_SIDE",$AX5>0),$AX5*Settings!$B$5,0) | U5: =MAX(0,$M5*Settings!$B$9) | V5: =IF($B5="BIG_SIDE",IFERROR(MIN($D5,MAX(0,$T5/$U5)),0),0) | W5: =IF($B5="BIG_SIDE",MAX(0,$D5-$V5),$AJ5) | X5: =IF($B5="BIG_SIDE",IF($AX5>0,$AX5-$AS5,0),IF($S5>0,$S5*0.5,0)) | Y5: =$Y4+$X5 | Z5: =$AA4 | AA5: =IF($B5="BLOCKED",$Z5,IF($B5="BIG_SIDE",$Z5+$AX5-$AS5-$AZ5,IF($B5="SMALL_SIDE",$Z5+$S5+$AI5,$Z5+$S5))) | AB5: =IF($B5="BLOCKED",IF(ROW()=2,0,$AG4+$AJ4),$D5+$G5+$J5) | AC5: =IF($B5="BLOCKED",$AB5,IF($B5="BIG_SIDE",$W5,$AG5+$AJ5)) | AD5: =$AB5*Settings!$B$10 | AE5: =$AC5*Settings!$B$10 | AF5: =IF($B5="BLOCKED",IF(ROW()=2,$C5,$AF4),IF($B5="SMALL_SIDE",$E5,$C5)) | AG5: =IF($B5="BLOCKED",IF(ROW()=2,0,$AG4),IF($B5="SMALL_SIDE",$AM5,$W5)) | AH5: NO | AI5: 0 | AJ5: =IF($B5="SMALL_SIDE",MAX(0,$D5-$AV5),0) | AK5: =IF(AND($AJ5>0,$AG5>0),TRUE,FALSE) | AL5: =IF($B5="SMALL_SIDE",$G5*Settings!$B$7,IF($B5="BIG_SIDE",$G5,0)) | AM5: =IF($B5="SMALL_SIDE",MAX(0,$G5-$AL5),0) | AN5: =IF($B5="BIG_SIDE",1,IF($B5="SMALL_SIDE",Settings!$B$7,0)) | AO5: =IF(OR($B5="BIG_SIDE",$B5="SMALL_SIDE"),1,0) | AP5: =IF(OR($AQ5="DUAL_TAIL",$AQ5="DANGER",$AQ5="STOP"),"NO","YES") | AQ5: =IF($B5="BLOCKED","STOP",IF($AK5=TRUE,"DUAL_TAIL",IF(OR(IFERROR($G5/$D5,0)>Settings!$B$16,IFERROR($J5/$G5,0)>Settings!$B$17,$AE5>$AD5,$Y5<0,$AG5>$D5*1.0001,$S5<-100),"DANGER",IF(OR(AND($B5="BIG_SIDE",$U5<=0),$S5<=0,$X5=0,$AE5>$AD5*0.95),"WARNING","OK")))) | AR5: =IF($B5="BLOCKED","Заблокировано: предыдущий уровень не разрешил новый полноценный уровень",IF($B5="BIG_SIDE","BIG_SIDE: Big и Small закрыты 100%; баланс учитывает RealizedFarLoss",IF($AQ5="DUAL_TAIL","SMALL_SIDE: старый и новый хвост одновременно; новый уровень запрещён","SMALL_SIDE: Small закрыт 100%, Big закрыт 22%, остаток Big = новый хвост"))) | AS5: =IF($B5="BIG_SIDE",$V5*$U5,0) | AT5: =IF($B5="BIG_SIDE",$G5+$J5+$V5,IF($B5="SMALL_SIDE",$J5+$AL5+$AV5,0)) | AU5: =Settings!$B$13+Settings!$B$14+Settings!$B$15 | AV5: =IF($B5="SMALL_SIDE",IF($AH5="YES",$D5,IFERROR(MIN($D5,MAX(0,$AI5/$U5)),0)),0) | AW5: =IF($B5="BLOCKED","Заблокировано: предыдущий уровень не разрешил новый полноценный уровень","") | AX5: =IF($B5="BIG_SIDE",$N5-$P5-$AY5,IF($B5="SMALL_SIDE",$O5-$Q5-$R5,0)) | AY5: =IF($B5="BIG_SIDE",($G5+$J5)*$AU5,0) | AZ5: =IF($B5="BIG_SIDE",$V5*$AU5,0)
A6: 5 | B6: =IF(OR($AP5="NO",$AQ5="DUAL_TAIL",$AQ5="DANGER",$AQ5="STOP"),"BLOCKED","BIG_SIDE") | C6: =IF($B6="BLOCKED",$AF5,IF($AP5="YES",$AF5,$C5)) | D6: =IF($B6="BLOCKED",0,IF($AP5="YES",MAX(0,$AG5),$D5)) | E6: =IF($B6="BLOCKED","",IF($C6="SELL","BUY","SELL")) | F6: =IF($B6="BLOCKED",0,MAX(0,$D6*Settings!$B$3)) | G6: =IF($B6="BLOCKED",0,IFERROR(MAX(0,ROUND($F6/Settings!$B$11,0)*Settings!$B$11),0)) | H6: =IF($B6="BLOCKED","",$C6) | I6: =IF($B6="BLOCKED",0,MAX(0,$G6*Settings!$B$4)) | J6: =IF($B6="BLOCKED",0,IFERROR(MAX(0,ROUND($I6/Settings!$B$11,0)*Settings!$B$11),0)) | K6: 100 | L6: -40 | M6: 100 | N6: =IF($B6="BIG_SIDE",$G6*MAX(0,$K6)*Settings!$B$9,0) | O6: =IF($B6="SMALL_SIDE",$J6*ABS($L6)*Settings!$B$9,0) | P6: =IF($B6="BIG_SIDE",$J6*ABS($L6)*Settings!$B$9,0) | Q6: =IF($B6="SMALL_SIDE",$AL6*ABS($K6)*Settings!$B$9,0) | R6: =$AT6*$AU6 | S6: =IF($B6="BIG_SIDE",$N6-$P6-$R6,IF($B6="SMALL_SIDE",$O6-$Q6-$R6,0)) | T6: =IF(AND($B6="BIG_SIDE",$AX6>0),$AX6*Settings!$B$5,0) | U6: =MAX(0,$M6*Settings!$B$9) | V6: =IF($B6="BIG_SIDE",IFERROR(MIN($D6,MAX(0,$T6/$U6)),0),0) | W6: =IF($B6="BIG_SIDE",MAX(0,$D6-$V6),$AJ6) | X6: =IF($B6="BIG_SIDE",IF($AX6>0,$AX6-$AS6,0),IF($S6>0,$S6*0.5,0)) | Y6: =$Y5+$X6 | Z6: =$AA5 | AA6: =IF($B6="BLOCKED",$Z6,IF($B6="BIG_SIDE",$Z6+$AX6-$AS6-$AZ6,IF($B6="SMALL_SIDE",$Z6+$S6+$AI6,$Z6+$S6))) | AB6: =IF($B6="BLOCKED",IF(ROW()=2,0,$AG5+$AJ5),$D6+$G6+$J6) | AC6: =IF($B6="BLOCKED",$AB6,IF($B6="BIG_SIDE",$W6,$AG6+$AJ6)) | AD6: =$AB6*Settings!$B$10 | AE6: =$AC6*Settings!$B$10 | AF6: =IF($B6="BLOCKED",IF(ROW()=2,$C6,$AF5),IF($B6="SMALL_SIDE",$E6,$C6)) | AG6: =IF($B6="BLOCKED",IF(ROW()=2,0,$AG5),IF($B6="SMALL_SIDE",$AM6,$W6)) | AH6: NO | AI6: 0 | AJ6: =IF($B6="SMALL_SIDE",MAX(0,$D6-$AV6),0) | AK6: =IF(AND($AJ6>0,$AG6>0),TRUE,FALSE) | AL6: =IF($B6="SMALL_SIDE",$G6*Settings!$B$7,IF($B6="BIG_SIDE",$G6,0)) | AM6: =IF($B6="SMALL_SIDE",MAX(0,$G6-$AL6),0) | AN6: =IF($B6="BIG_SIDE",1,IF($B6="SMALL_SIDE",Settings!$B$7,0)) | AO6: =IF(OR($B6="BIG_SIDE",$B6="SMALL_SIDE"),1,0) | AP6: =IF(OR($AQ6="DUAL_TAIL",$AQ6="DANGER",$AQ6="STOP"),"NO","YES") | AQ6: =IF($B6="BLOCKED","STOP",IF($AK6=TRUE,"DUAL_TAIL",IF(OR(IFERROR($G6/$D6,0)>Settings!$B$16,IFERROR($J6/$G6,0)>Settings!$B$17,$AE6>$AD6,$Y6<0,$AG6>$D6*1.0001,$S6<-100),"DANGER",IF(OR(AND($B6="BIG_SIDE",$U6<=0),$S6<=0,$X6=0,$AE6>$AD6*0.95),"WARNING","OK")))) | AR6: =IF($B6="BLOCKED","Заблокировано: предыдущий уровень не разрешил новый полноценный уровень",IF($B6="BIG_SIDE","BIG_SIDE: Big и Small закрыты 100%; баланс учитывает RealizedFarLoss",IF($AQ6="DUAL_TAIL","SMALL_SIDE: старый и новый хвост одновременно; новый уровень запрещён","SMALL_SIDE: Small закрыт 100%, Big закрыт 22%, остаток Big = новый хвост"))) | AS6: =IF($B6="BIG_SIDE",$V6*$U6,0) | AT6: =IF($B6="BIG_SIDE",$G6+$J6+$V6,IF($B6="SMALL_SIDE",$J6+$AL6+$AV6,0)) | AU6: =Settings!$B$13+Settings!$B$14+Settings!$B$15 | AV6: =IF($B6="SMALL_SIDE",IF($AH6="YES",$D6,IFERROR(MIN($D6,MAX(0,$AI6/$U6)),0)),0) | AW6: =IF($B6="BLOCKED","Заблокировано: предыдущий уровень не разрешил новый полноценный уровень","") | AX6: =IF($B6="BIG_SIDE",$N6-$P6-$AY6,IF($B6="SMALL_SIDE",$O6-$Q6-$R6,0)) | AY6: =IF($B6="BIG_SIDE",($G6+$J6)*$AU6,0) | AZ6: =IF($B6="BIG_SIDE",$V6*$AU6,0)
A7: 6 | B7: =IF(OR($AP6="NO",$AQ6="DUAL_TAIL",$AQ6="DANGER",$AQ6="STOP"),"BLOCKED","SMALL_SIDE") | C7: =IF($B7="BLOCKED",$AF6,IF($AP6="YES",$AF6,$C6)) | D7: =IF($B7="BLOCKED",0,IF($AP6="YES",MAX(0,$AG6),$D6)) | E7: =IF($B7="BLOCKED","",IF($C7="SELL","BUY","SELL")) | F7: =IF($B7="BLOCKED",0,MAX(0,$D7*Settings!$B$3)) | G7: =IF($B7="BLOCKED",0,IFERROR(MAX(0,ROUND($F7/Settings!$B$11,0)*Settings!$B$11),0)) | H7: =IF($B7="BLOCKED","",$C7) | I7: =IF($B7="BLOCKED",0,MAX(0,$G7*Settings!$B$4)) | J7: =IF($B7="BLOCKED",0,IFERROR(MAX(0,ROUND($I7/Settings!$B$11,0)*Settings!$B$11),0)) | K7: 80 | L7: 60 | M7: 100 | N7: =IF($B7="BIG_SIDE",$G7*MAX(0,$K7)*Settings!$B$9,0) | O7: =IF($B7="SMALL_SIDE",$J7*ABS($L7)*Settings!$B$9,0) | P7: =IF($B7="BIG_SIDE",$J7*ABS($L7)*Settings!$B$9,0) | Q7: =IF($B7="SMALL_SIDE",$AL7*ABS($K7)*Settings!$B$9,0) | R7: =$AT7*$AU7 | S7: =IF($B7="BIG_SIDE",$N7-$P7-$R7,IF($B7="SMALL_SIDE",$O7-$Q7-$R7,0)) | T7: =IF(AND($B7="BIG_SIDE",$AX7>0),$AX7*Settings!$B$5,0) | U7: =MAX(0,$M7*Settings!$B$9) | V7: =IF($B7="BIG_SIDE",IFERROR(MIN($D7,MAX(0,$T7/$U7)),0),0) | W7: =IF($B7="BIG_SIDE",MAX(0,$D7-$V7),$AJ7) | X7: =IF($B7="BIG_SIDE",IF($AX7>0,$AX7-$AS7,0),IF($S7>0,$S7*0.5,0)) | Y7: =$Y6+$X7 | Z7: =$AA6 | AA7: =IF($B7="BLOCKED",$Z7,IF($B7="BIG_SIDE",$Z7+$AX7-$AS7-$AZ7,IF($B7="SMALL_SIDE",$Z7+$S7+$AI7,$Z7+$S7))) | AB7: =IF($B7="BLOCKED",IF(ROW()=2,0,$AG6+$AJ6),$D7+$G7+$J7) | AC7: =IF($B7="BLOCKED",$AB7,IF($B7="BIG_SIDE",$W7,$AG7+$AJ7)) | AD7: =$AB7*Settings!$B$10 | AE7: =$AC7*Settings!$B$10 | AF7: =IF($B7="BLOCKED",IF(ROW()=2,$C7,$AF6),IF($B7="SMALL_SIDE",$E7,$C7)) | AG7: =IF($B7="BLOCKED",IF(ROW()=2,0,$AG6),IF($B7="SMALL_SIDE",$AM7,$W7)) | AH7: YES | AI7: 0 | AJ7: =IF($B7="SMALL_SIDE",MAX(0,$D7-$AV7),0) | AK7: =IF(AND($AJ7>0,$AG7>0),TRUE,FALSE) | AL7: =IF($B7="SMALL_SIDE",$G7*Settings!$B$7,IF($B7="BIG_SIDE",$G7,0)) | AM7: =IF($B7="SMALL_SIDE",MAX(0,$G7-$AL7),0) | AN7: =IF($B7="BIG_SIDE",1,IF($B7="SMALL_SIDE",Settings!$B$7,0)) | AO7: =IF(OR($B7="BIG_SIDE",$B7="SMALL_SIDE"),1,0) | AP7: =IF(OR($AQ7="DUAL_TAIL",$AQ7="DANGER",$AQ7="STOP"),"NO","YES") | AQ7: =IF($B7="BLOCKED","STOP",IF($AK7=TRUE,"DUAL_TAIL",IF(OR(IFERROR($G7/$D7,0)>Settings!$B$16,IFERROR($J7/$G7,0)>Settings!$B$17,$AE7>$AD7,$Y7<0,$AG7>$D7*1.0001,$S7<-100),"DANGER",IF(OR(AND($B7="BIG_SIDE",$U7<=0),$S7<=0,$X7=0,$AE7>$AD7*0.95),"WARNING","OK")))) | AR7: =IF($B7="BLOCKED","Заблокировано: предыдущий уровень не разрешил новый полноценный уровень",IF($B7="BIG_SIDE","BIG_SIDE: Big и Small закрыты 100%; баланс учитывает RealizedFarLoss",IF($AQ7="DUAL_TAIL","SMALL_SIDE: старый и новый хвост одновременно; новый уровень запрещён","SMALL_SIDE: Small закрыт 100%, Big закрыт 22%, остаток Big = новый хвост"))) | AS7: =IF($B7="BIG_SIDE",$V7*$U7,0) | AT7: =IF($B7="BIG_SIDE",$G7+$J7+$V7,IF($B7="SMALL_SIDE",$J7+$AL7+$AV7,0)) | AU7: =Settings!$B$13+Settings!$B$14+Settings!$B$15 | AV7: =IF($B7="SMALL_SIDE",IF($AH7="YES",$D7,IFERROR(MIN($D7,MAX(0,$AI7/$U7)),0)),0) | AW7: =IF($B7="BLOCKED","Заблокировано: предыдущий уровень не разрешил новый полноценный уровень","") | AX7: =IF($B7="BIG_SIDE",$N7-$P7-$AY7,IF($B7="SMALL_SIDE",$O7-$Q7-$R7,0)) | AY7: =IF($B7="BIG_SIDE",($G7+$J7)*$AU7,0) | AZ7: =IF($B7="BIG_SIDE",$V7*$AU7,0)
A8: 7 | B8: =IF(OR($AP7="NO",$AQ7="DUAL_TAIL",$AQ7="DANGER",$AQ7="STOP"),"BLOCKED","BIG_SIDE") | C8: =IF($B8="BLOCKED",$AF7,IF($AP7="YES",$AF7,$C7)) | D8: =IF($B8="BLOCKED",0,IF($AP7="YES",MAX(0,$AG7),$D7)) | E8: =IF($B8="BLOCKED","",IF($C8="SELL","BUY","SELL")) | F8: =IF($B8="BLOCKED",0,MAX(0,$D8*Settings!$B$3)) | G8: =IF($B8="BLOCKED",0,IFERROR(MAX(0,ROUND($F8/Settings!$B$11,0)*Settings!$B$11),0)) | H8: =IF($B8="BLOCKED","",$C8) | I8: =IF($B8="BLOCKED",0,MAX(0,$G8*Settings!$B$4)) | J8: =IF($B8="BLOCKED",0,IFERROR(MAX(0,ROUND($I8/Settings!$B$11,0)*Settings!$B$11),0)) | K8: 100 | L8: -40 | M8: 100 | N8: =IF($B8="BIG_SIDE",$G8*MAX(0,$K8)*Settings!$B$9,0) | O8: =IF($B8="SMALL_SIDE",$J8*ABS($L8)*Settings!$B$9,0) | P8: =IF($B8="BIG_SIDE",$J8*ABS($L8)*Settings!$B$9,0) | Q8: =IF($B8="SMALL_SIDE",$AL8*ABS($K8)*Settings!$B$9,0) | R8: =$AT8*$AU8 | S8: =IF($B8="BIG_SIDE",$N8-$P8-$R8,IF($B8="SMALL_SIDE",$O8-$Q8-$R8,0)) | T8: =IF(AND($B8="BIG_SIDE",$AX8>0),$AX8*Settings!$B$5,0) | U8: =MAX(0,$M8*Settings!$B$9) | V8: =IF($B8="BIG_SIDE",IFERROR(MIN($D8,MAX(0,$T8/$U8)),0),0) | W8: =IF($B8="BIG_SIDE",MAX(0,$D8-$V8),$AJ8) | X8: =IF($B8="BIG_SIDE",IF($AX8>0,$AX8-$AS8,0),IF($S8>0,$S8*0.5,0)) | Y8: =$Y7+$X8 | Z8: =$AA7 | AA8: =IF($B8="BLOCKED",$Z8,IF($B8="BIG_SIDE",$Z8+$AX8-$AS8-$AZ8,IF($B8="SMALL_SIDE",$Z8+$S8+$AI8,$Z8+$S8))) | AB8: =IF($B8="BLOCKED",IF(ROW()=2,0,$AG7+$AJ7),$D8+$G8+$J8) | AC8: =IF($B8="BLOCKED",$AB8,IF($B8="BIG_SIDE",$W8,$AG8+$AJ8)) | AD8: =$AB8*Settings!$B$10 | AE8: =$AC8*Settings!$B$10 | AF8: =IF($B8="BLOCKED",IF(ROW()=2,$C8,$AF7),IF($B8="SMALL_SIDE",$E8,$C8)) | AG8: =IF($B8="BLOCKED",IF(ROW()=2,0,$AG7),IF($B8="SMALL_SIDE",$AM8,$W8)) | AH8: NO | AI8: 0 | AJ8: =IF($B8="SMALL_SIDE",MAX(0,$D8-$AV8),0) | AK8: =IF(AND($AJ8>0,$AG8>0),TRUE,FALSE) | AL8: =IF($B8="SMALL_SIDE",$G8*Settings!$B$7,IF($B8="BIG_SIDE",$G8,0)) | AM8: =IF($B8="SMALL_SIDE",MAX(0,$G8-$AL8),0) | AN8: =IF($B8="BIG_SIDE",1,IF($B8="SMALL_SIDE",Settings!$B$7,0)) | AO8: =IF(OR($B8="BIG_SIDE",$B8="SMALL_SIDE"),1,0) | AP8: =IF(OR($AQ8="DUAL_TAIL",$AQ8="DANGER",$AQ8="STOP"),"NO","YES") | AQ8: =IF($B8="BLOCKED","STOP",IF($AK8=TRUE,"DUAL_TAIL",IF(OR(IFERROR($G8/$D8,0)>Settings!$B$16,IFERROR($J8/$G8,0)>Settings!$B$17,$AE8>$AD8,$Y8<0,$AG8>$D8*1.0001,$S8<-100),"DANGER",IF(OR(AND($B8="BIG_SIDE",$U8<=0),$S8<=0,$X8=0,$AE8>$AD8*0.95),"WARNING","OK")))) | AR8: =IF($B8="BLOCKED","Заблокировано: предыдущий уровень не разрешил новый полноценный уровень",IF($B8="BIG_SIDE","BIG_SIDE: Big и Small закрыты 100%; баланс учитывает RealizedFarLoss",IF($AQ8="DUAL_TAIL","SMALL_SIDE: старый и новый хвост одновременно; новый уровень запрещён","SMALL_SIDE: Small закрыт 100%, Big закрыт 22%, остаток Big = новый хвост"))) | AS8: =IF($B8="BIG_SIDE",$V8*$U8,0) | AT8: =IF($B8="BIG_SIDE",$G8+$J8+$V8,IF($B8="SMALL_SIDE",$J8+$AL8+$AV8,0)) | AU8: =Settings!$B$13+Settings!$B$14+Settings!$B$15 | AV8: =IF($B8="SMALL_SIDE",IF($AH8="YES",$D8,IFERROR(MIN($D8,MAX(0,$AI8/$U8)),0)),0) | AW8: =IF($B8="BLOCKED","Заблокировано: предыдущий уровень не разрешил новый полноценный уровень","") | AX8: =IF($B8="BIG_SIDE",$N8-$P8-$AY8,IF($B8="SMALL_SIDE",$O8-$Q8-$R8,0)) | AY8: =IF($B8="BIG_SIDE",($G8+$J8)*$AU8,0) | AZ8: =IF($B8="BIG_SIDE",$V8*$AU8,0)
A9: 8 | B9: =IF(OR($AP8="NO",$AQ8="DUAL_TAIL",$AQ8="DANGER",$AQ8="STOP"),"BLOCKED","BIG_SIDE") | C9: =IF($B9="BLOCKED",$AF8,IF($AP8="YES",$AF8,$C8)) | D9: =IF($B9="BLOCKED",0,IF($AP8="YES",MAX(0,$AG8),$D8)) | E9: =IF($B9="BLOCKED","",IF($C9="SELL","BUY","SELL")) | F9: =IF($B9="BLOCKED",0,MAX(0,$D9*Settings!$B$3)) | G9: =IF($B9="BLOCKED",0,IFERROR(MAX(0,ROUND($F9/Settings!$B$11,0)*Settings!$B$11),0)) | H9: =IF($B9="BLOCKED","",$C9) | I9: =IF($B9="BLOCKED",0,MAX(0,$G9*Settings!$B$4)) | J9: =IF($B9="BLOCKED",0,IFERROR(MAX(0,ROUND($I9/Settings!$B$11,0)*Settings!$B$11),0)) | K9: 100 | L9: -40 | M9: 100 | N9: =IF($B9="BIG_SIDE",$G9*MAX(0,$K9)*Settings!$B$9,0) | O9: =IF($B9="SMALL_SIDE",$J9*ABS($L9)*Settings!$B$9,0) | P9: =IF($B9="BIG_SIDE",$J9*ABS($L9)*Settings!$B$9,0) | Q9: =IF($B9="SMALL_SIDE",$AL9*ABS($K9)*Settings!$B$9,0) | R9: =$AT9*$AU9 | S9: =IF($B9="BIG_SIDE",$N9-$P9-$R9,IF($B9="SMALL_SIDE",$O9-$Q9-$R9,0)) | T9: =IF(AND($B9="BIG_SIDE",$AX9>0),$AX9*Settings!$B$5,0) | U9: =MAX(0,$M9*Settings!$B$9) | V9: =IF($B9="BIG_SIDE",IFERROR(MIN($D9,MAX(0,$T9/$U9)),0),0) | W9: =IF($B9="BIG_SIDE",MAX(0,$D9-$V9),$AJ9) | X9: =IF($B9="BIG_SIDE",IF($AX9>0,$AX9-$AS9,0),IF($S9>0,$S9*0.5,0)) | Y9: =$Y8+$X9 | Z9: =$AA8 | AA9: =IF($B9="BLOCKED",$Z9,IF($B9="BIG_SIDE",$Z9+$AX9-$AS9-$AZ9,IF($B9="SMALL_SIDE",$Z9+$S9+$AI9,$Z9+$S9))) | AB9: =IF($B9="BLOCKED",IF(ROW()=2,0,$AG8+$AJ8),$D9+$G9+$J9) | AC9: =IF($B9="BLOCKED",$AB9,IF($B9="BIG_SIDE",$W9,$AG9+$AJ9)) | AD9: =$AB9*Settings!$B$10 | AE9: =$AC9*Settings!$B$10 | AF9: =IF($B9="BLOCKED",IF(ROW()=2,$C9,$AF8),IF($B9="SMALL_SIDE",$E9,$C9)) | AG9: =IF($B9="BLOCKED",IF(ROW()=2,0,$AG8),IF($B9="SMALL_SIDE",$AM9,$W9)) | AH9: NO | AI9: 0 | AJ9: =IF($B9="SMALL_SIDE",MAX(0,$D9-$AV9),0) | AK9: =IF(AND($AJ9>0,$AG9>0),TRUE,FALSE) | AL9: =IF($B9="SMALL_SIDE",$G9*Settings!$B$7,IF($B9="BIG_SIDE",$G9,0)) | AM9: =IF($B9="SMALL_SIDE",MAX(0,$G9-$AL9),0) | AN9: =IF($B9="BIG_SIDE",1,IF($B9="SMALL_SIDE",Settings!$B$7,0)) | AO9: =IF(OR($B9="BIG_SIDE",$B9="SMALL_SIDE"),1,0) | AP9: =IF(OR($AQ9="DUAL_TAIL",$AQ9="DANGER",$AQ9="STOP"),"NO","YES") | AQ9: =IF($B9="BLOCKED","STOP",IF($AK9=TRUE,"DUAL_TAIL",IF(OR(IFERROR($G9/$D9,0)>Settings!$B$16,IFERROR($J9/$G9,0)>Settings!$B$17,$AE9>$AD9,$Y9<0,$AG9>$D9*1.0001,$S9<-100),"DANGER",IF(OR(AND($B9="BIG_SIDE",$U9<=0),$S9<=0,$X9=0,$AE9>$AD9*0.95),"WARNING","OK")))) | AR9: =IF($B9="BLOCKED","Заблокировано: предыдущий уровень не разрешил новый полноценный уровень",IF($B9="BIG_SIDE","BIG_SIDE: Big и Small закрыты 100%; баланс учитывает RealizedFarLoss",IF($AQ9="DUAL_TAIL","SMALL_SIDE: старый и новый хвост одновременно; новый уровень запрещён","SMALL_SIDE: Small закрыт 100%, Big закрыт 22%, остаток Big = новый хвост"))) | AS9: =IF($B9="BIG_SIDE",$V9*$U9,0) | AT9: =IF($B9="BIG_SIDE",$G9+$J9+$V9,IF($B9="SMALL_SIDE",$J9+$AL9+$AV9,0)) | AU9: =Settings!$B$13+Settings!$B$14+Settings!$B$15 | AV9: =IF($B9="SMALL_SIDE",IF($AH9="YES",$D9,IFERROR(MIN($D9,MAX(0,$AI9/$U9)),0)),0) | AW9: =IF($B9="BLOCKED","Заблокировано: предыдущий уровень не разрешил новый полноценный уровень","") | AX9: =IF($B9="BIG_SIDE",$N9-$P9-$AY9,IF($B9="SMALL_SIDE",$O9-$Q9-$R9,0)) | AY9: =IF($B9="BIG_SIDE",($G9+$J9)*$AU9,0) | AZ9: =IF($B9="BIG_SIDE",$V9*$AU9,0)
A10: 9 | B10: =IF(OR($AP9="NO",$AQ9="DUAL_TAIL",$AQ9="DANGER",$AQ9="STOP"),"BLOCKED","BIG_SIDE") | C10: =IF($B10="BLOCKED",$AF9,IF($AP9="YES",$AF9,$C9)) | D10: =IF($B10="BLOCKED",0,IF($AP9="YES",MAX(0,$AG9),$D9)) | E10: =IF($B10="BLOCKED","",IF($C10="SELL","BUY","SELL")) | F10: =IF($B10="BLOCKED",0,MAX(0,$D10*Settings!$B$3)) | G10: =IF($B10="BLOCKED",0,IFERROR(MAX(0,ROUND($F10/Settings!$B$11,0)*Settings!$B$11),0)) | H10: =IF($B10="BLOCKED","",$C10) | I10: =IF($B10="BLOCKED",0,MAX(0,$G10*Settings!$B$4)) | J10: =IF($B10="BLOCKED",0,IFERROR(MAX(0,ROUND($I10/Settings!$B$11,0)*Settings!$B$11),0)) | K10: 100 | L10: -40 | M10: 100 | N10: =IF($B10="BIG_SIDE",$G10*MAX(0,$K10)*Settings!$B$9,0) | O10: =IF($B10="SMALL_SIDE",$J10*ABS($L10)*Settings!$B$9,0) | P10: =IF($B10="BIG_SIDE",$J10*ABS($L10)*Settings!$B$9,0) | Q10: =IF($B10="SMALL_SIDE",$AL10*ABS($K10)*Settings!$B$9,0) | R10: =$AT10*$AU10 | S10: =IF($B10="BIG_SIDE",$N10-$P10-$R10,IF($B10="SMALL_SIDE",$O10-$Q10-$R10,0)) | T10: =IF(AND($B10="BIG_SIDE",$AX10>0),$AX10*Settings!$B$5,0) | U10: =MAX(0,$M10*Settings!$B$9) | V10: =IF($B10="BIG_SIDE",IFERROR(MIN($D10,MAX(0,$T10/$U10)),0),0) | W10: =IF($B10="BIG_SIDE",MAX(0,$D10-$V10),$AJ10) | X10: =IF($B10="BIG_SIDE",IF($AX10>0,$AX10-$AS10,0),IF($S10>0,$S10*0.5,0)) | Y10: =$Y9+$X10 | Z10: =$AA9 | AA10: =IF($B10="BLOCKED",$Z10,IF($B10="BIG_SIDE",$Z10+$AX10-$AS10-$AZ10,IF($B10="SMALL_SIDE",$Z10+$S10+$AI10,$Z10+$S10))) | AB10: =IF($B10="BLOCKED",IF(ROW()=2,0,$AG9+$AJ9),$D10+$G10+$J10) | AC10: =IF($B10="BLOCKED",$AB10,IF($B10="BIG_SIDE",$W10,$AG10+$AJ10)) | AD10: =$AB10*Settings!$B$10 | AE10: =$AC10*Settings!$B$10 | AF10: =IF($B10="BLOCKED",IF(ROW()=2,$C10,$AF9),IF($B10="SMALL_SIDE",$E10,$C10)) | AG10: =IF($B10="BLOCKED",IF(ROW()=2,0,$AG9),IF($B10="SMALL_SIDE",$AM10,$W10)) | AH10: NO | AI10: 0 | AJ10: =IF($B10="SMALL_SIDE",MAX(0,$D10-$AV10),0) | AK10: =IF(AND($AJ10>0,$AG10>0),TRUE,FALSE) | AL10: =IF($B10="SMALL_SIDE",$G10*Settings!$B$7,IF($B10="BIG_SIDE",$G10,0)) | AM10: =IF($B10="SMALL_SIDE",MAX(0,$G10-$AL10),0) | AN10: =IF($B10="BIG_SIDE",1,IF($B10="SMALL_SIDE",Settings!$B$7,0)) | AO10: =IF(OR($B10="BIG_SIDE",$B10="SMALL_SIDE"),1,0) | AP10: =IF(OR($AQ10="DUAL_TAIL",$AQ10="DANGER",$AQ10="STOP"),"NO","YES") | AQ10: =IF($B10="BLOCKED","STOP",IF($AK10=TRUE,"DUAL_TAIL",IF(OR(IFERROR($G10/$D10,0)>Settings!$B$16,IFERROR($J10/$G10,0)>Settings!$B$17,$AE10>$AD10,$Y10<0,$AG10>$D10*1.0001,$S10<-100),"DANGER",IF(OR(AND($B10="BIG_SIDE",$U10<=0),$S10<=0,$X10=0,$AE10>$AD10*0.95),"WARNING","OK")))) | AR10: =IF($B10="BLOCKED","Заблокировано: предыдущий уровень не разрешил новый полноценный уровень",IF($B10="BIG_SIDE","BIG_SIDE: Big и Small закрыты 100%; баланс учитывает RealizedFarLoss",IF($AQ10="DUAL_TAIL","SMALL_SIDE: старый и новый хвост одновременно; новый уровень запрещён","SMALL_SIDE: Small закрыт 100%, Big закрыт 22%, остаток Big = новый хвост"))) | AS10: =IF($B10="BIG_SIDE",$V10*$U10,0) | AT10: =IF($B10="BIG_SIDE",$G10+$J10+$V10,IF($B10="SMALL_SIDE",$J10+$AL10+$AV10,0)) | AU10: =Settings!$B$13+Settings!$B$14+Settings!$B$15 | AV10: =IF($B10="SMALL_SIDE",IF($AH10="YES",$D10,IFERROR(MIN($D10,MAX(0,$AI10/$U10)),0)),0) | AW10: =IF($B10="BLOCKED","Заблокировано: предыдущий уровень не разрешил новый полноценный уровень","") | AX10: =IF($B10="BIG_SIDE",$N10-$P10-$AY10,IF($B10="SMALL_SIDE",$O10-$Q10-$R10,0)) | AY10: =IF($B10="BIG_SIDE",($G10+$J10)*$AU10,0) | AZ10: =IF($B10="BIG_SIDE",$V10*$AU10,0)
A11: 10 | B11: =IF(OR($AP10="NO",$AQ10="DUAL_TAIL",$AQ10="DANGER",$AQ10="STOP"),"BLOCKED","BIG_SIDE") | C11: =IF($B11="BLOCKED",$AF10,IF($AP10="YES",$AF10,$C10)) | D11: =IF($B11="BLOCKED",0,IF($AP10="YES",MAX(0,$AG10),$D10)) | E11: =IF($B11="BLOCKED","",IF($C11="SELL","BUY","SELL")) | F11: =IF($B11="BLOCKED",0,MAX(0,$D11*Settings!$B$3)) | G11: =IF($B11="BLOCKED",0,IFERROR(MAX(0,ROUND($F11/Settings!$B$11,0)*Settings!$B$11),0)) | H11: =IF($B11="BLOCKED","",$C11) | I11: =IF($B11="BLOCKED",0,MAX(0,$G11*Settings!$B$4)) | J11: =IF($B11="BLOCKED",0,IFERROR(MAX(0,ROUND($I11/Settings!$B$11,0)*Settings!$B$11),0)) | K11: 100 | L11: -40 | M11: 100 | N11: =IF($B11="BIG_SIDE",$G11*MAX(0,$K11)*Settings!$B$9,0) | O11: =IF($B11="SMALL_SIDE",$J11*ABS($L11)*Settings!$B$9,0) | P11: =IF($B11="BIG_SIDE",$J11*ABS($L11)*Settings!$B$9,0) | Q11: =IF($B11="SMALL_SIDE",$AL11*ABS($K11)*Settings!$B$9,0) | R11: =$AT11*$AU11 | S11: =IF($B11="BIG_SIDE",$N11-$P11-$R11,IF($B11="SMALL_SIDE",$O11-$Q11-$R11,0)) | T11: =IF(AND($B11="BIG_SIDE",$AX11>0),$AX11*Settings!$B$5,0) | U11: =MAX(0,$M11*Settings!$B$9) | V11: =IF($B11="BIG_SIDE",IFERROR(MIN($D11,MAX(0,$T11/$U11)),0),0) | W11: =IF($B11="BIG_SIDE",MAX(0,$D11-$V11),$AJ11) | X11: =IF($B11="BIG_SIDE",IF($AX11>0,$AX11-$AS11,0),IF($S11>0,$S11*0.5,0)) | Y11: =$Y10+$X11 | Z11: =$AA10 | AA11: =IF($B11="BLOCKED",$Z11,IF($B11="BIG_SIDE",$Z11+$AX11-$AS11-$AZ11,IF($B11="SMALL_SIDE",$Z11+$S11+$AI11,$Z11+$S11))) | AB11: =IF($B11="BLOCKED",IF(ROW()=2,0,$AG10+$AJ10),$D11+$G11+$J11) | AC11: =IF($B11="BLOCKED",$AB11,IF($B11="BIG_SIDE",$W11,$AG11+$AJ11)) | AD11: =$AB11*Settings!$B$10 | AE11: =$AC11*Settings!$B$10 | AF11: =IF($B11="BLOCKED",IF(ROW()=2,$C11,$AF10),IF($B11="SMALL_SIDE",$E11,$C11)) | AG11: =IF($B11="BLOCKED",IF(ROW()=2,0,$AG10),IF($B11="SMALL_SIDE",$AM11,$W11)) | AH11: NO | AI11: 0 | AJ11: =IF($B11="SMALL_SIDE",MAX(0,$D11-$AV11),0) | AK11: =IF(AND($AJ11>0,$AG11>0),TRUE,FALSE) | AL11: =IF($B11="SMALL_SIDE",$G11*Settings!$B$7,IF($B11="BIG_SIDE",$G11,0)) | AM11: =IF($B11="SMALL_SIDE",MAX(0,$G11-$AL11),0) | AN11: =IF($B11="BIG_SIDE",1,IF($B11="SMALL_SIDE",Settings!$B$7,0)) | AO11: =IF(OR($B11="BIG_SIDE",$B11="SMALL_SIDE"),1,0) | AP11: =IF(OR($AQ11="DUAL_TAIL",$AQ11="DANGER",$AQ11="STOP"),"NO","YES") | AQ11: =IF($B11="BLOCKED","STOP",IF($AK11=TRUE,"DUAL_TAIL",IF(OR(IFERROR($G11/$D11,0)>Settings!$B$16,IFERROR($J11/$G11,0)>Settings!$B$17,$AE11>$AD11,$Y11<0,$AG11>$D11*1.0001,$S11<-100),"DANGER",IF(OR(AND($B11="BIG_SIDE",$U11<=0),$S11<=0,$X11=0,$AE11>$AD11*0.95),"WARNING","OK")))) | AR11: =IF($B11="BLOCKED","Заблокировано: предыдущий уровень не разрешил новый полноценный уровень",IF($B11="BIG_SIDE","BIG_SIDE: Big и Small закрыты 100%; баланс учитывает RealizedFarLoss",IF($AQ11="DUAL_TAIL","SMALL_SIDE: старый и новый хвост одновременно; новый уровень запрещён","SMALL_SIDE: Small закрыт 100%, Big закрыт 22%, остаток Big = новый хвост"))) | AS11: =IF($B11="BIG_SIDE",$V11*$U11,0) | AT11: =IF($B11="BIG_SIDE",$G11+$J11+$V11,IF($B11="SMALL_SIDE",$J11+$AL11+$AV11,0)) | AU11: =Settings!$B$13+Settings!$B$14+Settings!$B$15 | AV11: =IF($B11="SMALL_SIDE",IF($AH11="YES",$D11,IFERROR(MIN($D11,MAX(0,$AI11/$U11)),0)),0) | AW11: =IF($B11="BLOCKED","Заблокировано: предыдущий уровень не разрешил новый полноценный уровень","") | AX11: =IF($B11="BIG_SIDE",$N11-$P11-$AY11,IF($B11="SMALL_SIDE",$O11-$Q11-$R11,0)) | AY11: =IF($B11="BIG_SIDE",($G11+$J11)*$AU11,0) | AZ11: =IF($B11="BIG_SIDE",$V11*$AU11,0)

Sheet Trend_UP
A1: Level | B1: Scenario | C1: FarDirection | D1: FarStartLot | E1: BigDirection | F1: BigLotRaw | G1: BigLot | H1: SmallDirection | I1: SmallLotRaw | J1: SmallLot | K1: BigProfitPoints | L1: SmallPoints | M1: FarLossPoints | N1: ProfitBig | O1: ProfitSmall | P1: LossSmall | Q1: LossClosedBig | R1: Costs | S1: NetProfit | T1: CloseFarBudget | U1: LossPerLotToClose | V1: CloseFarLot | W1: FarRemainLot | X1: ReserveAdd | Y1: TotalReserve | Z1: BalanceBefore | AA1: BalanceAfter | AB1: OpenLotsBefore | AC1: OpenLotsAfter | AD1: MarginBefore | AE1: MarginAfter | AF1: NewFarDirection | AG1: NewFarStartLot | AH1: OldFarCanClose | AI1: OldFarClosePL | AJ1: OldFarRemainLot | AK1: DualTailFlag | AL1: CloseBigLot | AM1: RemainBigLot | AN1: BigClosedPercent | AO1: SmallClosedPercent | AP1: NewFullLevelAllowed | AQ1: Status | AR1: Comment | AS1: RealizedFarLoss | AT1: ClosedLotsForCosts | AU1: CostPerLot | AV1: OldFarClosedLot | AW1: BlockedReason | AX1: NetProfitBeforeFar | AY1: CostsBeforeFar | AZ1: CostsFarClose
A2: 1 | B2: BIG_SIDE | C2: SELL | D2: =Settings!$B$2 | E2: =IF($B2="BLOCKED","",IF($C2="SELL","BUY","SELL")) | F2: =IF($B2="BLOCKED",0,MAX(0,$D2*Settings!$B$3)) | G2: =IF($B2="BLOCKED",0,IFERROR(MAX(0,ROUND($F2/Settings!$B$11,0)*Settings!$B$11),0)) | H2: =IF($B2="BLOCKED","",$C2) | I2: =IF($B2="BLOCKED",0,MAX(0,$G2*Settings!$B$4)) | J2: =IF($B2="BLOCKED",0,IFERROR(MAX(0,ROUND($I2/Settings!$B$11,0)*Settings!$B$11),0)) | K2: 100 | L2: -40 | M2: 100 | N2: =IF($B2="BIG_SIDE",$G2*MAX(0,$K2)*Settings!$B$9,0) | O2: =IF($B2="SMALL_SIDE",$J2*ABS($L2)*Settings!$B$9,0) | P2: =IF($B2="BIG_SIDE",$J2*ABS($L2)*Settings!$B$9,0) | Q2: =IF($B2="SMALL_SIDE",$AL2*ABS($K2)*Settings!$B$9,0) | R2: =$AT2*$AU2 | S2: =IF($B2="BIG_SIDE",$N2-$P2-$R2,IF($B2="SMALL_SIDE",$O2-$Q2-$R2,0)) | T2: =IF(AND($B2="BIG_SIDE",$AX2>0),$AX2*Settings!$B$5,0) | U2: =MAX(0,$M2*Settings!$B$9) | V2: =IF($B2="BIG_SIDE",IFERROR(MIN($D2,MAX(0,$T2/$U2)),0),0) | W2: =IF($B2="BIG_SIDE",MAX(0,$D2-$V2),$AJ2) | X2: =IF($B2="BIG_SIDE",IF($AX2>0,$AX2-$AS2,0),IF($S2>0,$S2*0.5,0)) | Y2: =X2 | Z2: 0 | AA2: =IF($B2="BLOCKED",$Z2,IF($B2="BIG_SIDE",$Z2+$AX2-$AS2-$AZ2,IF($B2="SMALL_SIDE",$Z2+$S2+$AI2,$Z2+$S2))) | AB2: =IF($B2="BLOCKED",IF(ROW()=2,0,$AG1+$AJ1),$D2+$G2+$J2) | AC2: =IF($B2="BLOCKED",$AB2,IF($B2="BIG_SIDE",$W2,$AG2+$AJ2)) | AD2: =$AB2*Settings!$B$10 | AE2: =$AC2*Settings!$B$10 | AF2: =IF($B2="BLOCKED",IF(ROW()=2,$C2,$AF1),IF($B2="SMALL_SIDE",$E2,$C2)) | AG2: =IF($B2="BLOCKED",IF(ROW()=2,0,$AG1),IF($B2="SMALL_SIDE",$AM2,$W2)) | AH2: NO | AI2: 0 | AJ2: =IF($B2="SMALL_SIDE",MAX(0,$D2-$AV2),0) | AK2: =IF(AND($AJ2>0,$AG2>0),TRUE,FALSE) | AL2: =IF($B2="SMALL_SIDE",$G2*Settings!$B$7,IF($B2="BIG_SIDE",$G2,0)) | AM2: =IF($B2="SMALL_SIDE",MAX(0,$G2-$AL2),0) | AN2: =IF($B2="BIG_SIDE",1,IF($B2="SMALL_SIDE",Settings!$B$7,0)) | AO2: =IF(OR($B2="BIG_SIDE",$B2="SMALL_SIDE"),1,0) | AP2: =IF(OR($AQ2="DUAL_TAIL",$AQ2="DANGER",$AQ2="STOP"),"NO","YES") | AQ2: =IF($B2="BLOCKED","STOP",IF($AK2=TRUE,"DUAL_TAIL",IF(OR(IFERROR($G2/$D2,0)>Settings!$B$16,IFERROR($J2/$G2,0)>Settings!$B$17,$AE2>$AD2,$Y2<0,$AG2>$D2*1.0001,$S2<-100),"DANGER",IF(OR(AND($B2="BIG_SIDE",$U2<=0),$S2<=0,$X2=0,$AE2>$AD2*0.95),"WARNING","OK")))) | AR2: =IF($B2="BLOCKED","Заблокировано: предыдущий уровень не разрешил новый полноценный уровень",IF($B2="BIG_SIDE","BIG_SIDE: Big и Small закрыты 100%; баланс учитывает RealizedFarLoss",IF($AQ2="DUAL_TAIL","SMALL_SIDE: старый и новый хвост одновременно; новый уровень запрещён","SMALL_SIDE: Small закрыт 100%, Big закрыт 22%, остаток Big = новый хвост"))) | AS2: =IF($B2="BIG_SIDE",$V2*$U2,0) | AT2: =IF($B2="BIG_SIDE",$G2+$J2+$V2,IF($B2="SMALL_SIDE",$J2+$AL2+$AV2,0)) | AU2: =Settings!$B$13+Settings!$B$14+Settings!$B$15 | AV2: =IF($B2="SMALL_SIDE",IF($AH2="YES",$D2,IFERROR(MIN($D2,MAX(0,$AI2/$U2)),0)),0) | AW2: =IF($B2="BLOCKED","Заблокировано: предыдущий уровень не разрешил новый полноценный уровень","") | AX2: =IF($B2="BIG_SIDE",$N2-$P2-$AY2,IF($B2="SMALL_SIDE",$O2-$Q2-$R2,0)) | AY2: =IF($B2="BIG_SIDE",($G2+$J2)*$AU2,0) | AZ2: =IF($B2="BIG_SIDE",$V2*$AU2,0)
A3: 2 | B3: =IF(OR($AP2="NO",$AQ2="DUAL_TAIL",$AQ2="DANGER",$AQ2="STOP"),"BLOCKED","BIG_SIDE") | C3: =IF($B3="BLOCKED",$AF2,IF($AP2="YES",$AF2,$C2)) | D3: =IF($B3="BLOCKED",0,IF($AP2="YES",MAX(0,$AG2),$D2)) | E3: =IF($B3="BLOCKED","",IF($C3="SELL","BUY","SELL")) | F3: =IF($B3="BLOCKED",0,MAX(0,$D3*Settings!$B$3)) | G3: =IF($B3="BLOCKED",0,IFERROR(MAX(0,ROUND($F3/Settings!$B$11,0)*Settings!$B$11),0)) | H3: =IF($B3="BLOCKED","",$C3) | I3: =IF($B3="BLOCKED",0,MAX(0,$G3*Settings!$B$4)) | J3: =IF($B3="BLOCKED",0,IFERROR(MAX(0,ROUND($I3/Settings!$B$11,0)*Settings!$B$11),0)) | K3: 100 | L3: -40 | M3: 100 | N3: =IF($B3="BIG_SIDE",$G3*MAX(0,$K3)*Settings!$B$9,0) | O3: =IF($B3="SMALL_SIDE",$J3*ABS($L3)*Settings!$B$9,0) | P3: =IF($B3="BIG_SIDE",$J3*ABS($L3)*Settings!$B$9,0) | Q3: =IF($B3="SMALL_SIDE",$AL3*ABS($K3)*Settings!$B$9,0) | R3: =$AT3*$AU3 | S3: =IF($B3="BIG_SIDE",$N3-$P3-$R3,IF($B3="SMALL_SIDE",$O3-$Q3-$R3,0)) | T3: =IF(AND($B3="BIG_SIDE",$AX3>0),$AX3*Settings!$B$5,0) | U3: =MAX(0,$M3*Settings!$B$9) | V3: =IF($B3="BIG_SIDE",IFERROR(MIN($D3,MAX(0,$T3/$U3)),0),0) | W3: =IF($B3="BIG_SIDE",MAX(0,$D3-$V3),$AJ3) | X3: =IF($B3="BIG_SIDE",IF($AX3>0,$AX3-$AS3,0),IF($S3>0,$S3*0.5,0)) | Y3: =$Y2+$X3 | Z3: =$AA2 | AA3: =IF($B3="BLOCKED",$Z3,IF($B3="BIG_SIDE",$Z3+$AX3-$AS3-$AZ3,IF($B3="SMALL_SIDE",$Z3+$S3+$AI3,$Z3+$S3))) | AB3: =IF($B3="BLOCKED",IF(ROW()=2,0,$AG2+$AJ2),$D3+$G3+$J3) | AC3: =IF($B3="BLOCKED",$AB3,IF($B3="BIG_SIDE",$W3,$AG3+$AJ3)) | AD3: =$AB3*Settings!$B$10 | AE3: =$AC3*Settings!$B$10 | AF3: =IF($B3="BLOCKED",IF(ROW()=2,$C3,$AF2),IF($B3="SMALL_SIDE",$E3,$C3)) | AG3: =IF($B3="BLOCKED",IF(ROW()=2,0,$AG2),IF($B3="SMALL_SIDE",$AM3,$W3)) | AH3: NO | AI3: 0 | AJ3: =IF($B3="SMALL_SIDE",MAX(0,$D3-$AV3),0) | AK3: =IF(AND($AJ3>0,$AG3>0),TRUE,FALSE) | AL3: =IF($B3="SMALL_SIDE",$G3*Settings!$B$7,IF($B3="BIG_SIDE",$G3,0)) | AM3: =IF($B3="SMALL_SIDE",MAX(0,$G3-$AL3),0) | AN3: =IF($B3="BIG_SIDE",1,IF($B3="SMALL_SIDE",Settings!$B$7,0)) | AO3: =IF(OR($B3="BIG_SIDE",$B3="SMALL_SIDE"),1,0) | AP3: =IF(OR($AQ3="DUAL_TAIL",$AQ3="DANGER",$AQ3="STOP"),"NO","YES") | AQ3: =IF($B3="BLOCKED","STOP",IF($AK3=TRUE,"DUAL_TAIL",IF(OR(IFERROR($G3/$D3,0)>Settings!$B$16,IFERROR($J3/$G3,0)>Settings!$B$17,$AE3>$AD3,$Y3<0,$AG3>$D3*1.0001,$S3<-100),"DANGER",IF(OR(AND($B3="BIG_SIDE",$U3<=0),$S3<=0,$X3=0,$AE3>$AD3*0.95),"WARNING","OK")))) | AR3: =IF($B3="BLOCKED","Заблокировано: предыдущий уровень не разрешил новый полноценный уровень",IF($B3="BIG_SIDE","BIG_SIDE: Big и Small закрыты 100%; баланс учитывает RealizedFarLoss",IF($AQ3="DUAL_TAIL","SMALL_SIDE: старый и новый хвост одновременно; новый уровень запрещён","SMALL_SIDE: Small закрыт 100%, Big закрыт 22%, остаток Big = новый хвост"))) | AS3: =IF($B3="BIG_SIDE",$V3*$U3,0) | AT3: =IF($B3="BIG_SIDE",$G3+$J3+$V3,IF($B3="SMALL_SIDE",$J3+$AL3+$AV3,0)) | AU3: =Settings!$B$13+Settings!$B$14+Settings!$B$15 | AV3: =IF($B3="SMALL_SIDE",IF($AH3="YES",$D3,IFERROR(MIN($D3,MAX(0,$AI3/$U3)),0)),0) | AW3: =IF($B3="BLOCKED","Заблокировано: предыдущий уровень не разрешил новый полноценный уровень","") | AX3: =IF($B3="BIG_SIDE",$N3-$P3-$AY3,IF($B3="SMALL_SIDE",$O3-$Q3-$R3,0)) | AY3: =IF($B3="BIG_SIDE",($G3+$J3)*$AU3,0) | AZ3: =IF($B3="BIG_SIDE",$V3*$AU3,0)
A4: 3 | B4: =IF(OR($AP3="NO",$AQ3="DUAL_TAIL",$AQ3="DANGER",$AQ3="STOP"),"BLOCKED","BIG_SIDE") | C4: =IF($B4="BLOCKED",$AF3,IF($AP3="YES",$AF3,$C3)) | D4: =IF($B4="BLOCKED",0,IF($AP3="YES",MAX(0,$AG3),$D3)) | E4: =IF($B4="BLOCKED","",IF($C4="SELL","BUY","SELL")) | F4: =IF($B4="BLOCKED",0,MAX(0,$D4*Settings!$B$3)) | G4: =IF($B4="BLOCKED",0,IFERROR(MAX(0,ROUND($F4/Settings!$B$11,0)*Settings!$B$11),0)) | H4: =IF($B4="BLOCKED","",$C4) | I4: =IF($B4="BLOCKED",0,MAX(0,$G4*Settings!$B$4)) | J4: =IF($B4="BLOCKED",0,IFERROR(MAX(0,ROUND($I4/Settings!$B$11,0)*Settings!$B$11),0)) | K4: 100 | L4: -40 | M4: 100 | N4: =IF($B4="BIG_SIDE",$G4*MAX(0,$K4)*Settings!$B$9,0) | O4: =IF($B4="SMALL_SIDE",$J4*ABS($L4)*Settings!$B$9,0) | P4: =IF($B4="BIG_SIDE",$J4*ABS($L4)*Settings!$B$9,0) | Q4: =IF($B4="SMALL_SIDE",$AL4*ABS($K4)*Settings!$B$9,0) | R4: =$AT4*$AU4 | S4: =IF($B4="BIG_SIDE",$N4-$P4-$R4,IF($B4="SMALL_SIDE",$O4-$Q4-$R4,0)) | T4: =IF(AND($B4="BIG_SIDE",$AX4>0),$AX4*Settings!$B$5,0) | U4: =MAX(0,$M4*Settings!$B$9) | V4: =IF($B4="BIG_SIDE",IFERROR(MIN($D4,MAX(0,$T4/$U4)),0),0) | W4: =IF($B4="BIG_SIDE",MAX(0,$D4-$V4),$AJ4) | X4: =IF($B4="BIG_SIDE",IF($AX4>0,$AX4-$AS4,0),IF($S4>0,$S4*0.5,0)) | Y4: =$Y3+$X4 | Z4: =$AA3 | AA4: =IF($B4="BLOCKED",$Z4,IF($B4="BIG_SIDE",$Z4+$AX4-$AS4-$AZ4,IF($B4="SMALL_SIDE",$Z4+$S4+$AI4,$Z4+$S4))) | AB4: =IF($B4="BLOCKED",IF(ROW()=2,0,$AG3+$AJ3),$D4+$G4+$J4) | AC4: =IF($B4="BLOCKED",$AB4,IF($B4="BIG_SIDE",$W4,$AG4+$AJ4)) | AD4: =$AB4*Settings!$B$10 | AE4: =$AC4*Settings!$B$10 | AF4: =IF($B4="BLOCKED",IF(ROW()=2,$C4,$AF3),IF($B4="SMALL_SIDE",$E4,$C4)) | AG4: =IF($B4="BLOCKED",IF(ROW()=2,0,$AG3),IF($B4="SMALL_SIDE",$AM4,$W4)) | AH4: NO | AI4: 0 | AJ4: =IF($B4="SMALL_SIDE",MAX(0,$D4-$AV4),0) | AK4: =IF(AND($AJ4>0,$AG4>0),TRUE,FALSE) | AL4: =IF($B4="SMALL_SIDE",$G4*Settings!$B$7,IF($B4="BIG_SIDE",$G4,0)) | AM4: =IF($B4="SMALL_SIDE",MAX(0,$G4-$AL4),0) | AN4: =IF($B4="BIG_SIDE",1,IF($B4="SMALL_SIDE",Settings!$B$7,0)) | AO4: =IF(OR($B4="BIG_SIDE",$B4="SMALL_SIDE"),1,0) | AP4: =IF(OR($AQ4="DUAL_TAIL",$AQ4="DANGER",$AQ4="STOP"),"NO","YES") | AQ4: =IF($B4="BLOCKED","STOP",IF($AK4=TRUE,"DUAL_TAIL",IF(OR(IFERROR($G4/$D4,0)>Settings!$B$16,IFERROR($J4/$G4,0)>Settings!$B$17,$AE4>$AD4,$Y4<0,$AG4>$D4*1.0001,$S4<-100),"DANGER",IF(OR(AND($B4="BIG_SIDE",$U4<=0),$S4<=0,$X4=0,$AE4>$AD4*0.95),"WARNING","OK")))) | AR4: =IF($B4="BLOCKED","Заблокировано: предыдущий уровень не разрешил новый полноценный уровень",IF($B4="BIG_SIDE","BIG_SIDE: Big и Small закрыты 100%; баланс учитывает RealizedFarLoss",IF($AQ4="DUAL_TAIL","SMALL_SIDE: старый и новый хвост одновременно; новый уровень запрещён","SMALL_SIDE: Small закрыт 100%, Big закрыт 22%, остаток Big = новый хвост"))) | AS4: =IF($B4="BIG_SIDE",$V4*$U4,0) | AT4: =IF($B4="BIG_SIDE",$G4+$J4+$V4,IF($B4="SMALL_SIDE",$J4+$AL4+$AV4,0)) | AU4: =Settings!$B$13+Settings!$B$14+Settings!$B$15 | AV4: =IF($B4="SMALL_SIDE",IF($AH4="YES",$D4,IFERROR(MIN($D4,MAX(0,$AI4/$U4)),0)),0) | AW4: =IF($B4="BLOCKED","Заблокировано: предыдущий уровень не разрешил новый полноценный уровень","") | AX4: =IF($B4="BIG_SIDE",$N4-$P4-$AY4,IF($B4="SMALL_SIDE",$O4-$Q4-$R4,0)) | AY4: =IF($B4="BIG_SIDE",($G4+$J4)*$AU4,0) | AZ4: =IF($B4="BIG_SIDE",$V4*$AU4,0)
A5: 4 | B5: =IF(OR($AP4="NO",$AQ4="DUAL_TAIL",$AQ4="DANGER",$AQ4="STOP"),"BLOCKED","SMALL_SIDE") | C5: =IF($B5="BLOCKED",$AF4,IF($AP4="YES",$AF4,$C4)) | D5: =IF($B5="BLOCKED",0,IF($AP4="YES",MAX(0,$AG4),$D4)) | E5: =IF($B5="BLOCKED","",IF($C5="SELL","BUY","SELL")) | F5: =IF($B5="BLOCKED",0,MAX(0,$D5*Settings!$B$3)) | G5: =IF($B5="BLOCKED",0,IFERROR(MAX(0,ROUND($F5/Settings!$B$11,0)*Settings!$B$11),0)) | H5: =IF($B5="BLOCKED","",$C5) | I5: =IF($B5="BLOCKED",0,MAX(0,$G5*Settings!$B$4)) | J5: =IF($B5="BLOCKED",0,IFERROR(MAX(0,ROUND($I5/Settings!$B$11,0)*Settings!$B$11),0)) | K5: 80 | L5: 60 | M5: 100 | N5: =IF($B5="BIG_SIDE",$G5*MAX(0,$K5)*Settings!$B$9,0) | O5: =IF($B5="SMALL_SIDE",$J5*ABS($L5)*Settings!$B$9,0) | P5: =IF($B5="BIG_SIDE",$J5*ABS($L5)*Settings!$B$9,0) | Q5: =IF($B5="SMALL_SIDE",$AL5*ABS($K5)*Settings!$B$9,0) | R5: =$AT5*$AU5 | S5: =IF($B5="BIG_SIDE",$N5-$P5-$R5,IF($B5="SMALL_SIDE",$O5-$Q5-$R5,0)) | T5: =IF(AND($B5="BIG_SIDE",$AX5>0),$AX5*Settings!$B$5,0) | U5: =MAX(0,$M5*Settings!$B$9) | V5: =IF($B5="BIG_SIDE",IFERROR(MIN($D5,MAX(0,$T5/$U5)),0),0) | W5: =IF($B5="BIG_SIDE",MAX(0,$D5-$V5),$AJ5) | X5: =IF($B5="BIG_SIDE",IF($AX5>0,$AX5-$AS5,0),IF($S5>0,$S5*0.5,0)) | Y5: =$Y4+$X5 | Z5: =$AA4 | AA5: =IF($B5="BLOCKED",$Z5,IF($B5="BIG_SIDE",$Z5+$AX5-$AS5-$AZ5,IF($B5="SMALL_SIDE",$Z5+$S5+$AI5,$Z5+$S5))) | AB5: =IF($B5="BLOCKED",IF(ROW()=2,0,$AG4+$AJ4),$D5+$G5+$J5) | AC5: =IF($B5="BLOCKED",$AB5,IF($B5="BIG_SIDE",$W5,$AG5+$AJ5)) | AD5: =$AB5*Settings!$B$10 | AE5: =$AC5*Settings!$B$10 | AF5: =IF($B5="BLOCKED",IF(ROW()=2,$C5,$AF4),IF($B5="SMALL_SIDE",$E5,$C5)) | AG5: =IF($B5="BLOCKED",IF(ROW()=2,0,$AG4),IF($B5="SMALL_SIDE",$AM5,$W5)) | AH5: NO | AI5: 0 | AJ5: =IF($B5="SMALL_SIDE",MAX(0,$D5-$AV5),0) | AK5: =IF(AND($AJ5>0,$AG5>0),TRUE,FALSE) | AL5: =IF($B5="SMALL_SIDE",$G5*Settings!$B$7,IF($B5="BIG_SIDE",$G5,0)) | AM5: =IF($B5="SMALL_SIDE",MAX(0,$G5-$AL5),0) | AN5: =IF($B5="BIG_SIDE",1,IF($B5="SMALL_SIDE",Settings!$B$7,0)) | AO5: =IF(OR($B5="BIG_SIDE",$B5="SMALL_SIDE"),1,0) | AP5: =IF(OR($AQ5="DUAL_TAIL",$AQ5="DANGER",$AQ5="STOP"),"NO","YES") | AQ5: =IF($B5="BLOCKED","STOP",IF($AK5=TRUE,"DUAL_TAIL",IF(OR(IFERROR($G5/$D5,0)>Settings!$B$16,IFERROR($J5/$G5,0)>Settings!$B$17,$AE5>$AD5,$Y5<0,$AG5>$D5*1.0001,$S5<-100),"DANGER",IF(OR(AND($B5="BIG_SIDE",$U5<=0),$S5<=0,$X5=0,$AE5>$AD5*0.95),"WARNING","OK")))) | AR5: =IF($B5="BLOCKED","Заблокировано: предыдущий уровень не разрешил новый полноценный уровень",IF($B5="BIG_SIDE","BIG_SIDE: Big и Small закрыты 100%; баланс учитывает RealizedFarLoss",IF($AQ5="DUAL_TAIL","SMALL_SIDE: старый и новый хвост одновременно; новый уровень запрещён","SMALL_SIDE: Small закрыт 100%, Big закрыт 22%, остаток Big = новый хвост"))) | AS5: =IF($B5="BIG_SIDE",$V5*$U5,0) | AT5: =IF($B5="BIG_SIDE",$G5+$J5+$V5,IF($B5="SMALL_SIDE",$J5+$AL5+$AV5,0)) | AU5: =Settings!$B$13+Settings!$B$14+Settings!$B$15 | AV5: =IF($B5="SMALL_SIDE",IF($AH5="YES",$D5,IFERROR(MIN($D5,MAX(0,$AI5/$U5)),0)),0) | AW5: =IF($B5="BLOCKED","Заблокировано: предыдущий уровень не разрешил новый полноценный уровень","") | AX5: =IF($B5="BIG_SIDE",$N5-$P5-$AY5,IF($B5="SMALL_SIDE",$O5-$Q5-$R5,0)) | AY5: =IF($B5="BIG_SIDE",($G5+$J5)*$AU5,0) | AZ5: =IF($B5="BIG_SIDE",$V5*$AU5,0)
A6: 5 | B6: =IF(OR($AP5="NO",$AQ5="DUAL_TAIL",$AQ5="DANGER",$AQ5="STOP"),"BLOCKED","BIG_SIDE") | C6: =IF($B6="BLOCKED",$AF5,IF($AP5="YES",$AF5,$C5)) | D6: =IF($B6="BLOCKED",0,IF($AP5="YES",MAX(0,$AG5),$D5)) | E6: =IF($B6="BLOCKED","",IF($C6="SELL","BUY","SELL")) | F6: =IF($B6="BLOCKED",0,MAX(0,$D6*Settings!$B$3)) | G6: =IF($B6="BLOCKED",0,IFERROR(MAX(0,ROUND($F6/Settings!$B$11,0)*Settings!$B$11),0)) | H6: =IF($B6="BLOCKED","",$C6) | I6: =IF($B6="BLOCKED",0,MAX(0,$G6*Settings!$B$4)) | J6: =IF($B6="BLOCKED",0,IFERROR(MAX(0,ROUND($I6/Settings!$B$11,0)*Settings!$B$11),0)) | K6: 100 | L6: -40 | M6: 100 | N6: =IF($B6="BIG_SIDE",$G6*MAX(0,$K6)*Settings!$B$9,0) | O6: =IF($B6="SMALL_SIDE",$J6*ABS($L6)*Settings!$B$9,0) | P6: =IF($B6="BIG_SIDE",$J6*ABS($L6)*Settings!$B$9,0) | Q6: =IF($B6="SMALL_SIDE",$AL6*ABS($K6)*Settings!$B$9,0) | R6: =$AT6*$AU6 | S6: =IF($B6="BIG_SIDE",$N6-$P6-$R6,IF($B6="SMALL_SIDE",$O6-$Q6-$R6,0)) | T6: =IF(AND($B6="BIG_SIDE",$AX6>0),$AX6*Settings!$B$5,0) | U6: =MAX(0,$M6*Settings!$B$9) | V6: =IF($B6="BIG_SIDE",IFERROR(MIN($D6,MAX(0,$T6/$U6)),0),0) | W6: =IF($B6="BIG_SIDE",MAX(0,$D6-$V6),$AJ6) | X6: =IF($B6="BIG_SIDE",IF($AX6>0,$AX6-$AS6,0),IF($S6>0,$S6*0.5,0)) | Y6: =$Y5+$X6 | Z6: =$AA5 | AA6: =IF($B6="BLOCKED",$Z6,IF($B6="BIG_SIDE",$Z6+$AX6-$AS6-$AZ6,IF($B6="SMALL_SIDE",$Z6+$S6+$AI6,$Z6+$S6))) | AB6: =IF($B6="BLOCKED",IF(ROW()=2,0,$AG5+$AJ5),$D6+$G6+$J6) | AC6: =IF($B6="BLOCKED",$AB6,IF($B6="BIG_SIDE",$W6,$AG6+$AJ6)) | AD6: =$AB6*Settings!$B$10 | AE6: =$AC6*Settings!$B$10 | AF6: =IF($B6="BLOCKED",IF(ROW()=2,$C6,$AF5),IF($B6="SMALL_SIDE",$E6,$C6)) | AG6: =IF($B6="BLOCKED",IF(ROW()=2,0,$AG5),IF($B6="SMALL_SIDE",$AM6,$W6)) | AH6: NO | AI6: 0 | AJ6: =IF($B6="SMALL_SIDE",MAX(0,$D6-$AV6),0) | AK6: =IF(AND($AJ6>0,$AG6>0),TRUE,FALSE) | AL6: =IF($B6="SMALL_SIDE",$G6*Settings!$B$7,IF($B6="BIG_SIDE",$G6,0)) | AM6: =IF($B6="SMALL_SIDE",MAX(0,$G6-$AL6),0) | AN6: =IF($B6="BIG_SIDE",1,IF($B6="SMALL_SIDE",Settings!$B$7,0)) | AO6: =IF(OR($B6="BIG_SIDE",$B6="SMALL_SIDE"),1,0) | AP6: =IF(OR($AQ6="DUAL_TAIL",$AQ6="DANGER",$AQ6="STOP"),"NO","YES") | AQ6: =IF($B6="BLOCKED","STOP",IF($AK6=TRUE,"DUAL_TAIL",IF(OR(IFERROR($G6/$D6,0)>Settings!$B$16,IFERROR($J6/$G6,0)>Settings!$B$17,$AE6>$AD6,$Y6<0,$AG6>$D6*1.0001,$S6<-100),"DANGER",IF(OR(AND($B6="BIG_SIDE",$U6<=0),$S6<=0,$X6=0,$AE6>$AD6*0.95),"WARNING","OK")))) | AR6: =IF($B6="BLOCKED","Заблокировано: предыдущий уровень не разрешил новый полноценный уровень",IF($B6="BIG_SIDE","BIG_SIDE: Big и Small закрыты 100%; баланс учитывает RealizedFarLoss",IF($AQ6="DUAL_TAIL","SMALL_SIDE: старый и новый хвост одновременно; новый уровень запрещён","SMALL_SIDE: Small закрыт 100%, Big закрыт 22%, остаток Big = новый хвост"))) | AS6: =IF($B6="BIG_SIDE",$V6*$U6,0) | AT6: =IF($B6="BIG_SIDE",$G6+$J6+$V6,IF($B6="SMALL_SIDE",$J6+$AL6+$AV6,0)) | AU6: =Settings!$B$13+Settings!$B$14+Settings!$B$15 | AV6: =IF($B6="SMALL_SIDE",IF($AH6="YES",$D6,IFERROR(MIN($D6,MAX(0,$AI6/$U6)),0)),0) | AW6: =IF($B6="BLOCKED","Заблокировано: предыдущий уровень не разрешил новый полноценный уровень","") | AX6: =IF($B6="BIG_SIDE",$N6-$P6-$AY6,IF($B6="SMALL_SIDE",$O6-$Q6-$R6,0)) | AY6: =IF($B6="BIG_SIDE",($G6+$J6)*$AU6,0) | AZ6: =IF($B6="BIG_SIDE",$V6*$AU6,0)
A7: 6 | B7: =IF(OR($AP6="NO",$AQ6="DUAL_TAIL",$AQ6="DANGER",$AQ6="STOP"),"BLOCKED","BIG_SIDE") | C7: =IF($B7="BLOCKED",$AF6,IF($AP6="YES",$AF6,$C6)) | D7: =IF($B7="BLOCKED",0,IF($AP6="YES",MAX(0,$AG6),$D6)) | E7: =IF($B7="BLOCKED","",IF($C7="SELL","BUY","SELL")) | F7: =IF($B7="BLOCKED",0,MAX(0,$D7*Settings!$B$3)) | G7: =IF($B7="BLOCKED",0,IFERROR(MAX(0,ROUND($F7/Settings!$B$11,0)*Settings!$B$11),0)) | H7: =IF($B7="BLOCKED","",$C7) | I7: =IF($B7="BLOCKED",0,MAX(0,$G7*Settings!$B$4)) | J7: =IF($B7="BLOCKED",0,IFERROR(MAX(0,ROUND($I7/Settings!$B$11,0)*Settings!$B$11),0)) | K7: 100 | L7: -40 | M7: 100 | N7: =IF($B7="BIG_SIDE",$G7*MAX(0,$K7)*Settings!$B$9,0) | O7: =IF($B7="SMALL_SIDE",$J7*ABS($L7)*Settings!$B$9,0) | P7: =IF($B7="BIG_SIDE",$J7*ABS($L7)*Settings!$B$9,0) | Q7: =IF($B7="SMALL_SIDE",$AL7*ABS($K7)*Settings!$B$9,0) | R7: =$AT7*$AU7 | S7: =IF($B7="BIG_SIDE",$N7-$P7-$R7,IF($B7="SMALL_SIDE",$O7-$Q7-$R7,0)) | T7: =IF(AND($B7="BIG_SIDE",$AX7>0),$AX7*Settings!$B$5,0) | U7: =MAX(0,$M7*Settings!$B$9) | V7: =IF($B7="BIG_SIDE",IFERROR(MIN($D7,MAX(0,$T7/$U7)),0),0) | W7: =IF($B7="BIG_SIDE",MAX(0,$D7-$V7),$AJ7) | X7: =IF($B7="BIG_SIDE",IF($AX7>0,$AX7-$AS7,0),IF($S7>0,$S7*0.5,0)) | Y7: =$Y6+$X7 | Z7: =$AA6 | AA7: =IF($B7="BLOCKED",$Z7,IF($B7="BIG_SIDE",$Z7+$AX7-$AS7-$AZ7,IF($B7="SMALL_SIDE",$Z7+$S7+$AI7,$Z7+$S7))) | AB7: =IF($B7="BLOCKED",IF(ROW()=2,0,$AG6+$AJ6),$D7+$G7+$J7) | AC7: =IF($B7="BLOCKED",$AB7,IF($B7="BIG_SIDE",$W7,$AG7+$AJ7)) | AD7: =$AB7*Settings!$B$10 | AE7: =$AC7*Settings!$B$10 | AF7: =IF($B7="BLOCKED",IF(ROW()=2,$C7,$AF6),IF($B7="SMALL_SIDE",$E7,$C7)) | AG7: =IF($B7="BLOCKED",IF(ROW()=2,0,$AG6),IF($B7="SMALL_SIDE",$AM7,$W7)) | AH7: NO | AI7: 0 | AJ7: =IF($B7="SMALL_SIDE",MAX(0,$D7-$AV7),0) | AK7: =IF(AND($AJ7>0,$AG7>0),TRUE,FALSE) | AL7: =IF($B7="SMALL_SIDE",$G7*Settings!$B$7,IF($B7="BIG_SIDE",$G7,0)) | AM7: =IF($B7="SMALL_SIDE",MAX(0,$G7-$AL7),0) | AN7: =IF($B7="BIG_SIDE",1,IF($B7="SMALL_SIDE",Settings!$B$7,0)) | AO7: =IF(OR($B7="BIG_SIDE",$B7="SMALL_SIDE"),1,0) | AP7: =IF(OR($AQ7="DUAL_TAIL",$AQ7="DANGER",$AQ7="STOP"),"NO","YES") | AQ7: =IF($B7="BLOCKED","STOP",IF($AK7=TRUE,"DUAL_TAIL",IF(OR(IFERROR($G7/$D7,0)>Settings!$B$16,IFERROR($J7/$G7,0)>Settings!$B$17,$AE7>$AD7,$Y7<0,$AG7>$D7*1.0001,$S7<-100),"DANGER",IF(OR(AND($B7="BIG_SIDE",$U7<=0),$S7<=0,$X7=0,$AE7>$AD7*0.95),"WARNING","OK")))) | AR7: =IF($B7="BLOCKED","Заблокировано: предыдущий уровень не разрешил новый полноценный уровень",IF($B7="BIG_SIDE","BIG_SIDE: Big и Small закрыты 100%; баланс учитывает RealizedFarLoss",IF($AQ7="DUAL_TAIL","SMALL_SIDE: старый и новый хвост одновременно; новый уровень запрещён","SMALL_SIDE: Small закрыт 100%, Big закрыт 22%, остаток Big = новый хвост"))) | AS7: =IF($B7="BIG_SIDE",$V7*$U7,0) | AT7: =IF($B7="BIG_SIDE",$G7+$J7+$V7,IF($B7="SMALL_SIDE",$J7+$AL7+$AV7,0)) | AU7: =Settings!$B$13+Settings!$B$14+Settings!$B$15 | AV7: =IF($B7="SMALL_SIDE",IF($AH7="YES",$D7,IFERROR(MIN($D7,MAX(0,$AI7/$U7)),0)),0) | AW7: =IF($B7="BLOCKED","Заблокировано: предыдущий уровень не разрешил новый полноценный уровень","") | AX7: =IF($B7="BIG_SIDE",$N7-$P7-$AY7,IF($B7="SMALL_SIDE",$O7-$Q7-$R7,0)) | AY7: =IF($B7="BIG_SIDE",($G7+$J7)*$AU7,0) | AZ7: =IF($B7="BIG_SIDE",$V7*$AU7,0)
A8: 7 | B8: =IF(OR($AP7="NO",$AQ7="DUAL_TAIL",$AQ7="DANGER",$AQ7="STOP"),"BLOCKED","BIG_SIDE") | C8: =IF($B8="BLOCKED",$AF7,IF($AP7="YES",$AF7,$C7)) | D8: =IF($B8="BLOCKED",0,IF($AP7="YES",MAX(0,$AG7),$D7)) | E8: =IF($B8="BLOCKED","",IF($C8="SELL","BUY","SELL")) | F8: =IF($B8="BLOCKED",0,MAX(0,$D8*Settings!$B$3)) | G8: =IF($B8="BLOCKED",0,IFERROR(MAX(0,ROUND($F8/Settings!$B$11,0)*Settings!$B$11),0)) | H8: =IF($B8="BLOCKED","",$C8) | I8: =IF($B8="BLOCKED",0,MAX(0,$G8*Settings!$B$4)) | J8: =IF($B8="BLOCKED",0,IFERROR(MAX(0,ROUND($I8/Settings!$B$11,0)*Settings!$B$11),0)) | K8: 100 | L8: -40 | M8: 100 | N8: =IF($B8="BIG_SIDE",$G8*MAX(0,$K8)*Settings!$B$9,0) | O8: =IF($B8="SMALL_SIDE",$J8*ABS($L8)*Settings!$B$9,0) | P8: =IF($B8="BIG_SIDE",$J8*ABS($L8)*Settings!$B$9,0) | Q8: =IF($B8="SMALL_SIDE",$AL8*ABS($K8)*Settings!$B$9,0) | R8: =$AT8*$AU8 | S8: =IF($B8="BIG_SIDE",$N8-$P8-$R8,IF($B8="SMALL_SIDE",$O8-$Q8-$R8,0)) | T8: =IF(AND($B8="BIG_SIDE",$AX8>0),$AX8*Settings!$B$5,0) | U8: =MAX(0,$M8*Settings!$B$9) | V8: =IF($B8="BIG_SIDE",IFERROR(MIN($D8,MAX(0,$T8/$U8)),0),0) | W8: =IF($B8="BIG_SIDE",MAX(0,$D8-$V8),$AJ8) | X8: =IF($B8="BIG_SIDE",IF($AX8>0,$AX8-$AS8,0),IF($S8>0,$S8*0.5,0)) | Y8: =$Y7+$X8 | Z8: =$AA7 | AA8: =IF($B8="BLOCKED",$Z8,IF($B8="BIG_SIDE",$Z8+$AX8-$AS8-$AZ8,IF($B8="SMALL_SIDE",$Z8+$S8+$AI8,$Z8+$S8))) | AB8: =IF($B8="BLOCKED",IF(ROW()=2,0,$AG7+$AJ7),$D8+$G8+$J8) | AC8: =IF($B8="BLOCKED",$AB8,IF($B8="BIG_SIDE",$W8,$AG8+$AJ8)) | AD8: =$AB8*Settings!$B$10 | AE8: =$AC8*Settings!$B$10 | AF8: =IF($B8="BLOCKED",IF(ROW()=2,$C8,$AF7),IF($B8="SMALL_SIDE",$E8,$C8)) | AG8: =IF($B8="BLOCKED",IF(ROW()=2,0,$AG7),IF($B8="SMALL_SIDE",$AM8,$W8)) | AH8: NO | AI8: 0 | AJ8: =IF($B8="SMALL_SIDE",MAX(0,$D8-$AV8),0) | AK8: =IF(AND($AJ8>0,$AG8>0),TRUE,FALSE) | AL8: =IF($B8="SMALL_SIDE",$G8*Settings!$B$7,IF($B8="BIG_SIDE",$G8,0)) | AM8: =IF($B8="SMALL_SIDE",MAX(0,$G8-$AL8),0) | AN8: =IF($B8="BIG_SIDE",1,IF($B8="SMALL_SIDE",Settings!$B$7,0)) | AO8: =IF(OR($B8="BIG_SIDE",$B8="SMALL_SIDE"),1,0) | AP8: =IF(OR($AQ8="DUAL_TAIL",$AQ8="DANGER",$AQ8="STOP"),"NO","YES") | AQ8: =IF($B8="BLOCKED","STOP",IF($AK8=TRUE,"DUAL_TAIL",IF(OR(IFERROR($G8/$D8,0)>Settings!$B$16,IFERROR($J8/$G8,0)>Settings!$B$17,$AE8>$AD8,$Y8<0,$AG8>$D8*1.0001,$S8<-100),"DANGER",IF(OR(AND($B8="BIG_SIDE",$U8<=0),$S8<=0,$X8=0,$AE8>$AD8*0.95),"WARNING","OK")))) | AR8: =IF($B8="BLOCKED","Заблокировано: предыдущий уровень не разрешил новый полноценный уровень",IF($B8="BIG_SIDE","BIG_SIDE: Big и Small закрыты 100%; баланс учитывает RealizedFarLoss",IF($AQ8="DUAL_TAIL","SMALL_SIDE: старый и новый хвост одновременно; новый уровень запрещён","SMALL_SIDE: Small закрыт 100%, Big закрыт 22%, остаток Big = новый хвост"))) | AS8: =IF($B8="BIG_SIDE",$V8*$U8,0) | AT8: =IF($B8="BIG_SIDE",$G8+$J8+$V8,IF($B8="SMALL_SIDE",$J8+$AL8+$AV8,0)) | AU8: =Settings!$B$13+Settings!$B$14+Settings!$B$15 | AV8: =IF($B8="SMALL_SIDE",IF($AH8="YES",$D8,IFERROR(MIN($D8,MAX(0,$AI8/$U8)),0)),0) | AW8: =IF($B8="BLOCKED","Заблокировано: предыдущий уровень не разрешил новый полноценный уровень","") | AX8: =IF($B8="BIG_SIDE",$N8-$P8-$AY8,IF($B8="SMALL_SIDE",$O8-$Q8-$R8,0)) | AY8: =IF($B8="BIG_SIDE",($G8+$J8)*$AU8,0) | AZ8: =IF($B8="BIG_SIDE",$V8*$AU8,0)
