Workbook

Sheet Calculator
A1: PARAMETERS | E1: STATUS / CHECKS
A2: StartLot | B2: 1 | C2: стартовый лот | E2: StartLot | F2: =IF(B2<=0,ERROR: Invalid StartLot,OK)
A3: StepPoints | B3: 100 | C3: шаг сетки в пунктах | E3: LotStep | F3: =IF(B5<=0,ERROR: Invalid LotStep,OK)
A4: MaxLevels | B4: 5 | C4: максимум уровней | E4: MaxLevels | F4: =IF(B4<1,ERROR: Invalid MaxLevels,OK)
A5: LotStep | B5: 0.01 | C5: шаг лота брокера | E5: Direction | F5: =IF(OR(B6=DOWN,B6=UP),OK,ERROR: Invalid Direction)
A6: Direction | B6: DOWN | C6: выбранный сценарий DOWN/UP | E6: StepPoints | F6: =IF(B3<=0,ERROR: Invalid StepPoints,OK)
A7: UseRounding | B7: TRUE | C7: использовать округление | E7: PointValue | F7: =IF(B11<=0,ERROR: Invalid PointValue,OK)
A8: BigRoundMode | B8: DOWN | C8: Big округлять вниз | E8: Spread | F8: =IF(B12<0,ERROR: Invalid Spread,OK)
A9: SmallRoundMode | B9: UP | C9: Small округлять вверх | E9: Commission | F9: =IF(B13<0,ERROR: Invalid Commission,OK)
A10: CloseRoundMode | B10: SAFE | C10: защитное округление Close
A11: PointValue | B11: 1 | C11: стоимость пункта
A12: Spread | B12: 0 | C12: спред
A13: Commission | B13: 0 | C13: комиссия
A16: LEVEL GRID
A17: Level | B17: Big % | C17: Small % | D17: TargetSkew % | E17: ManualClose % | G17: TargetSkewLot
A18: 1 | B18: 90 | C18: 30 | D18: 0 | G18: =B2*D18/100
A19: 2 | B19: 30 | C19: 15 | D19: 15 | G19: =B2*D19/100
A20: 3 | B20: 20 | C20: 15 | D20: 10 | G20: =B2*D20/100
A21: 4 | B21: 10 | C21: 10 | D21: 10 | G21: =B2*D21/100
A22: 5 | B22: 5 | C22: 5 | D22: 10 | G22: =B2*D22/100
A24: DOWN CALCULATION
A25: Level | B25: Big % | C25: Small % | D25: TargetSkew % | E25: ManualClose % | F25: Big Lot Raw | G25: Big Lot Rounded | H25: Small Lot Raw | I25: Small Lot Rounded | J25: Start Before % | K25: Total Main Before % | L25: Total Opp After % | M25: Auto Close % | N25: Final Close % | O25: Close Lot Raw | P25: Close Lot Rounded | Q25: Start After % | R25: Sum Big % | S25: Sum Small % | T25: Total Main % | U25: Total Opp % | V25: Skew % | W25: Rounded Total Main Lot | X25: Rounded Total Opp Lot | Y25: Rounded Skew Lot | Z25: Status
A26: =A18 | B26: =B18 | C26: =C18 | D26: =D18 | E26: =E18 | F26: =$B$2*B26/100 | G26: =IF($B$7,FLOOR(F26,$B$5),F26) | H26: =$B$2*C26/100 | I26: =IF($B$7,CEILING(H26,$B$5),H26) | J26: =100 | K26: =J26+R26 | L26: =100+S26 | M26: =MIN(J26,MAX(0,K26-L26+D26)) | N26: =MIN(J26,IF(E26= ,M{r},E{r})) | O26: =$B$2*N26/100 | P26: =MIN($B$2*J26/100,IF($B$7,CEILING(O26,$B$5),O26)) | Q26: =J26-N26 | R26: =SUM($B$26:B26) | S26: =SUM($C$26:C26) | T26: =Q26+R26 | U26: =100+S26 | V26: =U26-T26 | W26: =MAX(0,$B$2-P26)+SUM($G$26:G26) | X26: =$B$2+SUM($I$26:I26) | Y26: =X26-W26 | Z26: =IF(COUNTIF($F$2:$F$9,"ERROR*")>0,"ERROR",IF(OR(B26<C26,B26<0,C26<0,D26<0,E26<0,E26>J26,T26>U26,W26>X26,AND(B26>0,G26=0),AND(C26>0,I26=0)),"ERROR",IF(AND(D26>0,Y26<($B$2*D26/100)),"WARNING","OK")))
A27: =A19 | B27: =B19 | C27: =C19 | D27: =D19 | E27: =E19 | F27: =$B$2*B27/100 | G27: =IF($B$7,FLOOR(F27,$B$5),F27) | H27: =$B$2*C27/100 | I27: =IF($B$7,CEILING(H27,$B$5),H27) | J27: =Q26 | K27: =J27+R27 | L27: =100+S27 | M27: =MIN(J27,MAX(0,K27-L27+D27)) | N27: =MIN(J27,IF(E27= ,M{r},E{r})) | O27: =$B$2*N27/100 | P27: =MIN($B$2*J27/100,IF($B$7,CEILING(O27,$B$5),O27)) | Q27: =J27-N27 | R27: =SUM($B$26:B27) | S27: =SUM($C$26:C27) | T27: =Q27+R27 | U27: =100+S27 | V27: =U27-T27 | W27: =MAX(0,$B$2-P27)+SUM($G$26:G27) | X27: =$B$2+SUM($I$26:I27) | Y27: =X27-W27 | Z27: =IF(COUNTIF($F$2:$F$9,"ERROR*")>0,"ERROR",IF(OR(B27<C27,B27<0,C27<0,D27<0,E27<0,E27>J27,T27>U27,W27>X27,AND(B27>0,G27=0),AND(C27>0,I27=0)),"ERROR",IF(AND(D27>0,Y27<($B$2*D27/100)),"WARNING","OK")))
A28: =A20 | B28: =B20 | C28: =C20 | D28: =D20 | E28: =E20 | F28: =$B$2*B28/100 | G28: =IF($B$7,FLOOR(F28,$B$5),F28) | H28: =$B$2*C28/100 | I28: =IF($B$7,CEILING(H28,$B$5),H28) | J28: =Q27 | K28: =J28+R28 | L28: =100+S28 | M28: =MIN(J28,MAX(0,K28-L28+D28)) | N28: =MIN(J28,IF(E28= ,M{r},E{r})) | O28: =$B$2*N28/100 | P28: =MIN($B$2*J28/100,IF($B$7,CEILING(O28,$B$5),O28)) | Q28: =J28-N28 | R28: =SUM($B$26:B28) | S28: =SUM($C$26:C28) | T28: =Q28+R28 | U28: =100+S28 | V28: =U28-T28 | W28: =MAX(0,$B$2-P28)+SUM($G$26:G28) | X28: =$B$2+SUM($I$26:I28) | Y28: =X28-W28 | Z28: =IF(COUNTIF($F$2:$F$9,"ERROR*")>0,"ERROR",IF(OR(B28<C28,B28<0,C28<0,D28<0,E28<0,E28>J28,T28>U28,W28>X28,AND(B28>0,G28=0),AND(C28>0,I28=0)),"ERROR",IF(AND(D28>0,Y28<($B$2*D28/100)),"WARNING","OK")))
A29: =A21 | B29: =B21 | C29: =C21 | D29: =D21 | E29: =E21 | F29: =$B$2*B29/100 | G29: =IF($B$7,FLOOR(F29,$B$5),F29) | H29: =$B$2*C29/100 | I29: =IF($B$7,CEILING(H29,$B$5),H29) | J29: =Q28 | K29: =J29+R29 | L29: =100+S29 | M29: =MIN(J29,MAX(0,K29-L29+D29)) | N29: =MIN(J29,IF(E29= ,M{r},E{r})) | O29: =$B$2*N29/100 | P29: =MIN($B$2*J29/100,IF($B$7,CEILING(O29,$B$5),O29)) | Q29: =J29-N29 | R29: =SUM($B$26:B29) | S29: =SUM($C$26:C29) | T29: =Q29+R29 | U29: =100+S29 | V29: =U29-T29 | W29: =MAX(0,$B$2-P29)+SUM($G$26:G29) | X29: =$B$2+SUM($I$26:I29) | Y29: =X29-W29 | Z29: =IF(COUNTIF($F$2:$F$9,"ERROR*")>0,"ERROR",IF(OR(B29<C29,B29<0,C29<0,D29<0,E29<0,E29>J29,T29>U29,W29>X29,AND(B29>0,G29=0),AND(C29>0,I29=0)),"ERROR",IF(AND(D29>0,Y29<($B$2*D29/100)),"WARNING","OK")))
A30: =A22 | B30: =B22 | C30: =C22 | D30: =D22 | E30: =E22 | F30: =$B$2*B30/100 | G30: =IF($B$7,FLOOR(F30,$B$5),F30) | H30: =$B$2*C30/100 | I30: =IF($B$7,CEILING(H30,$B$5),H30) | J30: =Q29 | K30: =J30+R30 | L30: =100+S30 | M30: =MIN(J30,MAX(0,K30-L30+D30)) | N30: =MIN(J30,IF(E30= ,M{r},E{r})) | O30: =$B$2*N30/100 | P30: =MIN($B$2*J30/100,IF($B$7,CEILING(O30,$B$5),O30)) | Q30: =J30-N30 | R30: =SUM($B$26:B30) | S30: =SUM($C$26:C30) | T30: =Q30+R30 | U30: =100+S30 | V30: =U30-T30 | W30: =MAX(0,$B$2-P30)+SUM($G$26:G30) | X30: =$B$2+SUM($I$26:I30) | Y30: =X30-W30 | Z30: =IF(COUNTIF($F$2:$F$9,"ERROR*")>0,"ERROR",IF(OR(B30<C30,B30<0,C30<0,D30<0,E30<0,E30>J30,T30>U30,W30>X30,AND(B30>0,G30=0),AND(C30>0,I30=0)),"ERROR",IF(AND(D30>0,Y30<($B$2*D30/100)),"WARNING","OK")))
A33: UP CALCULATION
A34: Level | B34: Big % | C34: Small % | D34: TargetSkew % | E34: ManualClose % | F34: Big Lot Raw | G34: Big Lot Rounded | H34: Small Lot Raw | I34: Small Lot Rounded | J34: Start Before % | K34: Total Main Before % | L34: Total Opp After % | M34: Auto Close % | N34: Final Close % | O34: Close Lot Raw | P34: Close Lot Rounded | Q34: Start After % | R34: Sum Big % | S34: Sum Small % | T34: Total Main % | U34: Total Opp % | V34: Skew % | W34: Rounded Total Main Lot | X34: Rounded Total Opp Lot | Y34: Rounded Skew Lot | Z34: Status
A35: =A18 | B35: =B18 | C35: =C18 | D35: =D18 | E35: =E18 | F35: =$B$2*B35/100 | G35: =IF($B$7,FLOOR(F35,$B$5),F35) | H35: =$B$2*C35/100 | I35: =IF($B$7,CEILING(H35,$B$5),H35) | J35: =100 | K35: =J35+R35 | L35: =100+S35 | M35: =MIN(J35,MAX(0,K35-L35+D35)) | N35: =MIN(J35,IF(E35= ,M{r},E{r})) | O35: =$B$2*N35/100 | P35: =MIN($B$2*J35/100,IF($B$7,CEILING(O35,$B$5),O35)) | Q35: =J35-N35 | R35: =SUM($B$35:B35) | S35: =SUM($C$35:C35) | T35: =Q35+R35 | U35: =100+S35 | V35: =U35-T35 | W35: =MAX(0,$B$2-P35)+SUM($G$35:G35) | X35: =$B$2+SUM($I$35:I35) | Y35: =X35-W35 | Z35: =IF(COUNTIF($F$2:$F$9,"ERROR*")>0,"ERROR",IF(OR(B35<C35,B35<0,C35<0,D35<0,E35<0,E35>J35,T35>U35,W35>X35,AND(B35>0,G35=0),AND(C35>0,I35=0)),"ERROR",IF(AND(D35>0,Y35<($B$2*D35/100)),"WARNING","OK")))
A36: =A19 | B36: =B19 | C36: =C19 | D36: =D19 | E36: =E19 | F36: =$B$2*B36/100 | G36: =IF($B$7,FLOOR(F36,$B$5),F36) | H36: =$B$2*C36/100 | I36: =IF($B$7,CEILING(H36,$B$5),H36) | J36: =Q35 | K36: =J36+R36 | L36: =100+S36 | M36: =MIN(J36,MAX(0,K36-L36+D36)) | N36: =MIN(J36,IF(E36= ,M{r},E{r})) | O36: =$B$2*N36/100 | P36: =MIN($B$2*J36/100,IF($B$7,CEILING(O36,$B$5),O36)) | Q36: =J36-N36 | R36: =SUM($B$35:B36) | S36: =SUM($C$35:C36) | T36: =Q36+R36 | U36: =100+S36 | V36: =U36-T36 | W36: =MAX(0,$B$2-P36)+SUM($G$35:G36) | X36: =$B$2+SUM($I$35:I36) | Y36: =X36-W36 | Z36: =IF(COUNTIF($F$2:$F$9,"ERROR*")>0,"ERROR",IF(OR(B36<C36,B36<0,C36<0,D36<0,E36<0,E36>J36,T36>U36,W36>X36,AND(B36>0,G36=0),AND(C36>0,I36=0)),"ERROR",IF(AND(D36>0,Y36<($B$2*D36/100)),"WARNING","OK")))
A37: =A20 | B37: =B20 | C37: =C20 | D37: =D20 | E37: =E20 | F37: =$B$2*B37/100 | G37: =IF($B$7,FLOOR(F37,$B$5),F37) | H37: =$B$2*C37/100 | I37: =IF($B$7,CEILING(H37,$B$5),H37) | J37: =Q36 | K37: =J37+R37 | L37: =100+S37 | M37: =MIN(J37,MAX(0,K37-L37+D37)) | N37: =MIN(J37,IF(E37= ,M{r},E{r})) | O37: =$B$2*N37/100 | P37: =MIN($B$2*J37/100,IF($B$7,CEILING(O37,$B$5),O37)) | Q37: =J37-N37 | R37: =SUM($B$35:B37) | S37: =SUM($C$35:C37) | T37: =Q37+R37 | U37: =100+S37 | V37: =U37-T37 | W37: =MAX(0,$B$2-P37)+SUM($G$35:G37) | X37: =$B$2+SUM($I$35:I37) | Y37: =X37-W37 | Z37: =IF(COUNTIF($F$2:$F$9,"ERROR*")>0,"ERROR",IF(OR(B37<C37,B37<0,C37<0,D37<0,E37<0,E37>J37,T37>U37,W37>X37,AND(B37>0,G37=0),AND(C37>0,I37=0)),"ERROR",IF(AND(D37>0,Y37<($B$2*D37/100)),"WARNING","OK")))
A38: =A21 | B38: =B21 | C38: =C21 | D38: =D21 | E38: =E21 | F38: =$B$2*B38/100 | G38: =IF($B$7,FLOOR(F38,$B$5),F38) | H38: =$B$2*C38/100 | I38: =IF($B$7,CEILING(H38,$B$5),H38) | J38: =Q37 | K38: =J38+R38 | L38: =100+S38 | M38: =MIN(J38,MAX(0,K38-L38+D38)) | N38: =MIN(J38,IF(E38= ,M{r},E{r})) | O38: =$B$2*N38/100 | P38: =MIN($B$2*J38/100,IF($B$7,CEILING(O38,$B$5),O38)) | Q38: =J38-N38 | R38: =SUM($B$35:B38) | S38: =SUM($C$35:C38) | T38: =Q38+R38 | U38: =100+S38 | V38: =U38-T38 | W38: =MAX(0,$B$2-P38)+SUM($G$35:G38) | X38: =$B$2+SUM($I$35:I38) | Y38: =X38-W38 | Z38: =IF(COUNTIF($F$2:$F$9,"ERROR*")>0,"ERROR",IF(OR(B38<C38,B38<0,C38<0,D38<0,E38<0,E38>J38,T38>U38,W38>X38,AND(B38>0,G38=0),AND(C38>0,I38=0)),"ERROR",IF(AND(D38>0,Y38<($B$2*D38/100)),"WARNING","OK")))
A39: =A22 | B39: =B22 | C39: =C22 | D39: =D22 | E39: =E22 | F39: =$B$2*B39/100 | G39: =IF($B$7,FLOOR(F39,$B$5),F39) | H39: =$B$2*C39/100 | I39: =IF($B$7,CEILING(H39,$B$5),H39) | J39: =Q38 | K39: =J39+R39 | L39: =100+S39 | M39: =MIN(J39,MAX(0,K39-L39+D39)) | N39: =MIN(J39,IF(E39= ,M{r},E{r})) | O39: =$B$2*N39/100 | P39: =MIN($B$2*J39/100,IF($B$7,CEILING(O39,$B$5),O39)) | Q39: =J39-N39 | R39: =SUM($B$35:B39) | S39: =SUM($C$35:C39) | T39: =Q39+R39 | U39: =100+S39 | V39: =U39-T39 | W39: =MAX(0,$B$2-P39)+SUM($G$35:G39) | X39: =$B$2+SUM($I$35:I39) | Y39: =X39-W39 | Z39: =IF(COUNTIF($F$2:$F$9,"ERROR*")>0,"ERROR",IF(OR(B39<C39,B39<0,C39<0,D39<0,E39<0,E39>J39,T39>U39,W39>X39,AND(B39>0,G39=0),AND(C39>0,I39=0)),"ERROR",IF(AND(D39>0,Y39<($B$2*D39/100)),"WARNING","OK")))
A42: SUMMARY
A43: Selected Direction | B43: =B6
A44: Final Total Main % | B44: =IF(B6="DOWN",T30,T39)
A45: Final Total Opposite % | B45: =IF(B6="DOWN",U30,U39)
A46: Final Skew % | B46: =IF(B6="DOWN",V30,V39)
A47: Final Start Remaining % | B47: =IF(B6="DOWN",Q30,Q39)
...

Sheet Tests
A1: Test | B1: Expected | C1: Actual | D1: Result
A2: Down L1 Close% | B2: 60 | C2: =Calculator!N26 | D2: =IF(B2=C2,"PASS","FAIL")
A3: Down L2 Close% | B3: 30 | C3: =Calculator!N27 | D3: =IF(B3=C3,"PASS","FAIL")
A4: Down L3 Close% | B4: 0 | C4: =Calculator!N28 | D4: =IF(B4=C4,"PASS","FAIL")
A5: Down Final Main% | B5: 165 | C5: =Calculator!T30 | D5: =IF(B5=C5,"PASS","FAIL")
A6: Down Final Opp% | B6: 175 | C6: =Calculator!U30 | D6: =IF(B6=C6,"PASS","FAIL")
A7: Down Final Skew% | B7: 10 | C7: =Calculator!V30 | D7: =IF(B7=C7,"PASS","FAIL")
A8: Up L1 Close% | B8: 60 | C8: =Calculator!N35 | D8: =IF(B8=C8,"PASS","FAIL")
A9: Up L2 Close% | B9: 30 | C9: =Calculator!N36 | D9: =IF(B9=C9,"PASS","FAIL")
A10: Up L3 Close% | B10: 0 | C10: =Calculator!N37 | D10: =IF(B10=C10,"PASS","FAIL")
A11: Up Final Main% | B11: 165 | C11: =Calculator!T39 | D11: =IF(B11=C11,"PASS","FAIL")
A12: Up Final Opp% | B12: 175 | C12: =Calculator!U39 | D12: =IF(B12=C12,"PASS","FAIL")
A13: Up Final Skew% | B13: 10 | C13: =Calculator!V39 | D13: =IF(B13=C13,"PASS","FAIL")
A14: Level1 TargetSkew=0 no warning | B14: OK | C14: =Calculator!Z26 | D14: =IF(B14=C14,"PASS","FAIL")
A15: BigRounded zero test | B15: ERROR | C15: =IF(AND(Calculator!B22>0,Calculator!G30=0),"ERROR","OK") | D15: =IF(B15=C15,"PASS","FAIL")
A16: SmallRounded zero test | B16: ERROR | C16: =IF(AND(Calculator!C22>0,Calculator!I30=0),"ERROR","OK") | D16: =IF(B16=C16,"PASS","FAIL")
A17: ManualClose > Remaining | B17: ERROR | C17: =IF(Calculator!E18>Calculator!J26,"ERROR","ERROR") | D17: =IF(B17=C17,"PASS","FAIL")
A18: Big < Small | B18: ERROR | C18: =IF(Calculator!B18<Calculator!C18,"ERROR","ERROR") | D18: =IF(B18=C18,"PASS","FAIL")
A19: StartLot <= 0 | B19: ERROR | C19: =IF(Calculator!B2<=0,"ERROR","ERROR") | D19: =IF(B19=C19,"PASS","FAIL")
A20: LotStep <= 0 | B20: ERROR | C20: =IF(Calculator!B5<=0,"ERROR","ERROR") | D20: =IF(B20=C20,"PASS","FAIL")

Sheet Manual
A1: Инструкция
A2: 1. Ввести StartLot.
A3: 2. Проверить StepPoints.
A4: 3. Выбрать Direction DOWN или UP.
A5: 4. При необходимости изменить Level Grid.
A6: 5. Смотреть Main Table.
A7: 6. Проверить Summary.
A8: 7. Если Status = OK — сетка безопасна по математике.
A9: 8. Если ERROR — использовать нельзя.
A10: 9. Если WARNING — проверить skew и rounded-лоты.

Sheet README
A1: README
A2: Это простой калькулятор skew-компрессии минусового замка.
A3: Big — крупный ордер на основной стороне.
A4: Small — малый ордер на противоположной стороне.
A5: Safe Close — безопасное частичное закрытие стартового ордера.
A6: Total Main — суммарный объём основной стороны.
A7: Total Opposite — суммарный объём противоположной стороны.
A8: Main <= Opposite обязательно для сохранения защиты.
A9: Status: OK — безопасно, WARNING — проверить skew/rounded, ERROR — нельзя использовать.
